[2019-11-22 13:25:01,505][21924][autotest][tMiddleware.py 71 ERROR]: 
request  : /v1/monkey/package  GET [handler: 0]
token    : eyJ0eXAiOiJKV1QiLCJhbGciOiJIUzI1NiJ9.eyJ1c2VyaWQiOjExNTIsInVzZXJuYW1lIjoiYWRtaW4iLCJuaWNrbmFtZSI6ImFkbWluIiwicGljdHVyZSI6IiIsInVzZXJ3ZWlnaHQiOjEsInJvbGUiOlt7ImlkIjoxLCJuYW1lIjoiYWRtaW4iLCJjb21tZW50IjoiXHU4ZDg1XHU3ZWE3XHU3YmExXHU3NDA2XHU1NDU4In0seyJpZCI6MywibmFtZSI6InRlc3QiLCJjb21tZW50IjoiXHU2ZDRiXHU4YmQ1In1dLCJwcm9qZWN0aWQiOlsyXSwiZXhwIjoxNTc1MDMzODgxfQ.QRpqtIUc1lcf7boYzrm8XadcMs-APbWJTyX98VMSxTY
projectid: 
query    : {'page_index': '1', 'page_size': '10'}

Traceback (most recent call last):
  File "D:\Programs\python37\lib\site-packages\sqlalchemy\engine\base.py", line 1246, in _execute_context
    cursor, statement, parameters, context
  File "D:\Programs\python37\lib\site-packages\sqlalchemy\engine\default.py", line 581, in do_execute
    cursor.execute(statement, parameters)
  File "D:\Programs\python37\lib\site-packages\MySQLdb\cursors.py", line 209, in execute
    res = self._query(query)
  File "D:\Programs\python37\lib\site-packages\MySQLdb\cursors.py", line 315, in _query
    db.query(q)
  File "D:\Programs\python37\lib\site-packages\MySQLdb\connections.py", line 231, in query
    _mysql.connection.query(self, query)
MySQLdb._exceptions.OperationalError: (1054, "Unknown column 'monkey_package.test_type' in 'field list'")

The above exception was the direct cause of the following exception:

Traceback (most recent call last):
  File "D:\Programs\python37\lib\site-packages\flask\app.py", line 1949, in full_dispatch_request
    rv = self.dispatch_request()
  File "D:\Programs\python37\lib\site-packages\flask\app.py", line 1935, in dispatch_request
    return self.view_functions[rule.endpoint](**req.view_args)
  File "G:\gitworkspace\TcloudServer\apps\autotest\views\monkey.py", line 479, in monkey_package_index_handler
    all, count = MonkeyPackageBusiness.get_monkey_packages_by_user_id(user_id, page_size, page_index, test_type)
  File "G:\gitworkspace\TcloudServer\apps\autotest\business\monkey.py", line 702, in get_monkey_packages_by_user_id
    all = cls.query_all_json(page_size, page_index, test_type)
  File "G:\gitworkspace\TcloudServer\library\api\transfer.py", line 129, in _
    result = func(*args, **kwargs)
  File "G:\gitworkspace\TcloudServer\apps\autotest\business\monkey.py", line 648, in query_all_json
    int(page_index - 1) * int(page_size)).all()
  File "D:\Programs\python37\lib\site-packages\sqlalchemy\orm\query.py", line 3211, in all
    return list(self)
  File "D:\Programs\python37\lib\site-packages\sqlalchemy\orm\query.py", line 3367, in __iter__
    return self._execute_and_instances(context)
  File "D:\Programs\python37\lib\site-packages\sqlalchemy\orm\query.py", line 3392, in _execute_and_instances
    result = conn.execute(querycontext.statement, self._params)
  File "D:\Programs\python37\lib\site-packages\sqlalchemy\engine\base.py", line 982, in execute
    return meth(self, multiparams, params)
  File "D:\Programs\python37\lib\site-packages\sqlalchemy\sql\elements.py", line 287, in _execute_on_connection
    return connection._execute_clauseelement(self, multiparams, params)
  File "D:\Programs\python37\lib\site-packages\sqlalchemy\engine\base.py", line 1101, in _execute_clauseelement
    distilled_params,
  File "D:\Programs\python37\lib\site-packages\sqlalchemy\engine\base.py", line 1250, in _execute_context
    e, statement, parameters, cursor, context
  File "D:\Programs\python37\lib\site-packages\sqlalchemy\engine\base.py", line 1476, in _handle_dbapi_exception
    util.raise_from_cause(sqlalchemy_exception, exc_info)
  File "D:\Programs\python37\lib\site-packages\sqlalchemy\util\compat.py", line 398, in raise_from_cause
    reraise(type(exception), exception, tb=exc_tb, cause=cause)
  File "D:\Programs\python37\lib\site-packages\sqlalchemy\util\compat.py", line 152, in reraise
    raise value.with_traceback(tb)
  File "D:\Programs\python37\lib\site-packages\sqlalchemy\engine\base.py", line 1246, in _execute_context
    cursor, statement, parameters, context
  File "D:\Programs\python37\lib\site-packages\sqlalchemy\engine\default.py", line 581, in do_execute
    cursor.execute(statement, parameters)
  File "D:\Programs\python37\lib\site-packages\MySQLdb\cursors.py", line 209, in execute
    res = self._query(query)
  File "D:\Programs\python37\lib\site-packages\MySQLdb\cursors.py", line 315, in _query
    db.query(q)
  File "D:\Programs\python37\lib\site-packages\MySQLdb\connections.py", line 231, in query
    _mysql.connection.query(self, query)
sqlalchemy.exc.OperationalError: (MySQLdb._exceptions.OperationalError) (1054, "Unknown column 'monkey_package.test_type' in 'field list'")
[SQL: SELECT monkey_package.id AS monkey_package_id, monkey_package.creation_time AS monkey_package_creation_time, monkey_package.modified_time AS monkey_package_modified_time, monkey_package.name AS monkey_package_name, monkey_package.package_name AS monkey_package_package_name, monkey_package.oss_url AS monkey_package_oss_url, monkey_package.picture AS monkey_package_picture, monkey_package.version AS monkey_package_version, monkey_package.default_activity AS monkey_package_default_activity, monkey_package.user_id AS monkey_package_user_id, monkey_package.status AS monkey_package_status, monkey_package.size AS monkey_package_size, monkey_package.test_type AS monkey_package_test_type, monkey_package.id AS id, monkey_package.name AS name, monkey_package.package_name AS package_name, monkey_package.oss_url AS oss_url, monkey_package.picture AS picture, monkey_package.version AS version, monkey_package.default_activity AS default_activity, monkey_package.user_id AS user_id, monkey_package.status AS status, monkey_package.size AS size, date_format(monkey_package.creation_time, %s) AS upload_time, monkey_package.test_type AS test_type 
FROM monkey_package 
WHERE monkey_package.status = %s AND monkey_package.test_type = %s ORDER BY monkey_package.id DESC 
 LIMIT %s, %s]
[parameters: ('%Y-%m-%d %H:%i:%s', 0, 1, 0, 10)]
(Background on this error at: http://sqlalche.me/e/e3q8)

[2019-11-22 13:25:01,511][21924][autotest][tMiddleware.py 71 ERROR]: 
request  : /v1/monkey/package  GET [handler: 0]
token    : eyJ0eXAiOiJKV1QiLCJhbGciOiJIUzI1NiJ9.eyJ1c2VyaWQiOjExNTIsInVzZXJuYW1lIjoiYWRtaW4iLCJuaWNrbmFtZSI6ImFkbWluIiwicGljdHVyZSI6IiIsInVzZXJ3ZWlnaHQiOjEsInJvbGUiOlt7ImlkIjoxLCJuYW1lIjoiYWRtaW4iLCJjb21tZW50IjoiXHU4ZDg1XHU3ZWE3XHU3YmExXHU3NDA2XHU1NDU4In0seyJpZCI6MywibmFtZSI6InRlc3QiLCJjb21tZW50IjoiXHU2ZDRiXHU4YmQ1In1dLCJwcm9qZWN0aWQiOlsyXSwiZXhwIjoxNTc1MDMzODgxfQ.QRpqtIUc1lcf7boYzrm8XadcMs-APbWJTyX98VMSxTY
projectid: 
query    : {'page_index': '1', 'page_size': '10', 'user_id': '1152'}

Traceback (most recent call last):
  File "D:\Programs\python37\lib\site-packages\sqlalchemy\engine\base.py", line 1246, in _execute_context
    cursor, statement, parameters, context
  File "D:\Programs\python37\lib\site-packages\sqlalchemy\engine\default.py", line 581, in do_execute
    cursor.execute(statement, parameters)
  File "D:\Programs\python37\lib\site-packages\MySQLdb\cursors.py", line 209, in execute
    res = self._query(query)
  File "D:\Programs\python37\lib\site-packages\MySQLdb\cursors.py", line 315, in _query
    db.query(q)
  File "D:\Programs\python37\lib\site-packages\MySQLdb\connections.py", line 231, in query
    _mysql.connection.query(self, query)
MySQLdb._exceptions.OperationalError: (1054, "Unknown column 'monkey_package.test_type' in 'field list'")

The above exception was the direct cause of the following exception:

Traceback (most recent call last):
  File "D:\Programs\python37\lib\site-packages\flask\app.py", line 1949, in full_dispatch_request
    rv = self.dispatch_request()
  File "D:\Programs\python37\lib\site-packages\flask\app.py", line 1935, in dispatch_request
    return self.view_functions[rule.endpoint](**req.view_args)
  File "G:\gitworkspace\TcloudServer\apps\autotest\views\monkey.py", line 479, in monkey_package_index_handler
    all, count = MonkeyPackageBusiness.get_monkey_packages_by_user_id(user_id, page_size, page_index, test_type)
  File "G:\gitworkspace\TcloudServer\apps\autotest\business\monkey.py", line 699, in get_monkey_packages_by_user_id
    all = cls.query_json_by_user_id(user_id, page_size, page_index, test_type)
  File "G:\gitworkspace\TcloudServer\library\api\transfer.py", line 129, in _
    result = func(*args, **kwargs)
  File "G:\gitworkspace\TcloudServer\apps\autotest\business\monkey.py", line 686, in query_json_by_user_id
    order_by(desc(MonkeyPackage.id)).limit(int(page_size)).offset(int(page_index - 1) * int(page_size)).all()
  File "D:\Programs\python37\lib\site-packages\sqlalchemy\orm\query.py", line 3211, in all
    return list(self)
  File "D:\Programs\python37\lib\site-packages\sqlalchemy\orm\query.py", line 3367, in __iter__
    return self._execute_and_instances(context)
  File "D:\Programs\python37\lib\site-packages\sqlalchemy\orm\query.py", line 3392, in _execute_and_instances
    result = conn.execute(querycontext.statement, self._params)
  File "D:\Programs\python37\lib\site-packages\sqlalchemy\engine\base.py", line 982, in execute
    return meth(self, multiparams, params)
  File "D:\Programs\python37\lib\site-packages\sqlalchemy\sql\elements.py", line 287, in _execute_on_connection
    return connection._execute_clauseelement(self, multiparams, params)
  File "D:\Programs\python37\lib\site-packages\sqlalchemy\engine\base.py", line 1101, in _execute_clauseelement
    distilled_params,
  File "D:\Programs\python37\lib\site-packages\sqlalchemy\engine\base.py", line 1250, in _execute_context
    e, statement, parameters, cursor, context
  File "D:\Programs\python37\lib\site-packages\sqlalchemy\engine\base.py", line 1476, in _handle_dbapi_exception
    util.raise_from_cause(sqlalchemy_exception, exc_info)
  File "D:\Programs\python37\lib\site-packages\sqlalchemy\util\compat.py", line 398, in raise_from_cause
    reraise(type(exception), exception, tb=exc_tb, cause=cause)
  File "D:\Programs\python37\lib\site-packages\sqlalchemy\util\compat.py", line 152, in reraise
    raise value.with_traceback(tb)
  File "D:\Programs\python37\lib\site-packages\sqlalchemy\engine\base.py", line 1246, in _execute_context
    cursor, statement, parameters, context
  File "D:\Programs\python37\lib\site-packages\sqlalchemy\engine\default.py", line 581, in do_execute
    cursor.execute(statement, parameters)
  File "D:\Programs\python37\lib\site-packages\MySQLdb\cursors.py", line 209, in execute
    res = self._query(query)
  File "D:\Programs\python37\lib\site-packages\MySQLdb\cursors.py", line 315, in _query
    db.query(q)
  File "D:\Programs\python37\lib\site-packages\MySQLdb\connections.py", line 231, in query
    _mysql.connection.query(self, query)
sqlalchemy.exc.OperationalError: (MySQLdb._exceptions.OperationalError) (1054, "Unknown column 'monkey_package.test_type' in 'field list'")
[SQL: SELECT monkey_package.id AS monkey_package_id, monkey_package.creation_time AS monkey_package_creation_time, monkey_package.modified_time AS monkey_package_modified_time, monkey_package.name AS monkey_package_name, monkey_package.package_name AS monkey_package_package_name, monkey_package.oss_url AS monkey_package_oss_url, monkey_package.picture AS monkey_package_picture, monkey_package.version AS monkey_package_version, monkey_package.default_activity AS monkey_package_default_activity, monkey_package.user_id AS monkey_package_user_id, monkey_package.status AS monkey_package_status, monkey_package.size AS monkey_package_size, monkey_package.test_type AS monkey_package_test_type, monkey_package.id AS id, monkey_package.name AS name, monkey_package.package_name AS package_name, monkey_package.oss_url AS oss_url, monkey_package.picture AS picture, monkey_package.version AS version, monkey_package.default_activity AS default_activity, monkey_package.user_id AS user_id, monkey_package.status AS status, monkey_package.size AS size, date_format(monkey_package.creation_time, %s) AS upload_time, monkey_package.test_type AS test_type 
FROM monkey_package 
WHERE monkey_package.status = %s AND monkey_package.test_type = %s AND monkey_package.user_id = %s ORDER BY monkey_package.id DESC 
 LIMIT %s, %s]
[parameters: ('%Y-%m-%d %H:%i:%s', 0, 1, '1152', 0, 10)]
(Background on this error at: http://sqlalche.me/e/e3q8)

[2019-11-22 13:31:46,778][21924][autotest][tMiddleware.py 71 ERROR]: 
request  : /v1/monkey/package  GET [handler: 0]
token    : eyJ0eXAiOiJKV1QiLCJhbGciOiJIUzI1NiJ9.eyJ1c2VyaWQiOjExNTIsInVzZXJuYW1lIjoiYWRtaW4iLCJuaWNrbmFtZSI6ImFkbWluIiwicGljdHVyZSI6IiIsInVzZXJ3ZWlnaHQiOjEsInJvbGUiOlt7ImlkIjoxLCJuYW1lIjoiYWRtaW4iLCJjb21tZW50IjoiXHU4ZDg1XHU3ZWE3XHU3YmExXHU3NDA2XHU1NDU4In0seyJpZCI6MywibmFtZSI6InRlc3QiLCJjb21tZW50IjoiXHU2ZDRiXHU4YmQ1In1dLCJwcm9qZWN0aWQiOlsyXSwiZXhwIjoxNTc1MDMzODgxfQ.QRpqtIUc1lcf7boYzrm8XadcMs-APbWJTyX98VMSxTY
projectid: 
query    : {'page_index': '1', 'page_size': '10', 'user_id': '1152'}

Traceback (most recent call last):
  File "D:\Programs\python37\lib\site-packages\sqlalchemy\engine\base.py", line 1246, in _execute_context
    cursor, statement, parameters, context
  File "D:\Programs\python37\lib\site-packages\sqlalchemy\engine\default.py", line 581, in do_execute
    cursor.execute(statement, parameters)
  File "D:\Programs\python37\lib\site-packages\MySQLdb\cursors.py", line 209, in execute
    res = self._query(query)
  File "D:\Programs\python37\lib\site-packages\MySQLdb\cursors.py", line 315, in _query
    db.query(q)
  File "D:\Programs\python37\lib\site-packages\MySQLdb\connections.py", line 231, in query
    _mysql.connection.query(self, query)
MySQLdb._exceptions.OperationalError: (1054, "Unknown column 'monkey_package.test_type' in 'field list'")

The above exception was the direct cause of the following exception:

Traceback (most recent call last):
  File "D:\Programs\python37\lib\site-packages\flask\app.py", line 1949, in full_dispatch_request
    rv = self.dispatch_request()
  File "D:\Programs\python37\lib\site-packages\flask\app.py", line 1935, in dispatch_request
    return self.view_functions[rule.endpoint](**req.view_args)
  File "G:\gitworkspace\TcloudServer\apps\autotest\views\monkey.py", line 479, in monkey_package_index_handler
    all, count = MonkeyPackageBusiness.get_monkey_packages_by_user_id(user_id, page_size, page_index, test_type)
  File "G:\gitworkspace\TcloudServer\apps\autotest\business\monkey.py", line 699, in get_monkey_packages_by_user_id
    all = cls.query_json_by_user_id(user_id, page_size, page_index, test_type)
  File "G:\gitworkspace\TcloudServer\library\api\transfer.py", line 129, in _
    result = func(*args, **kwargs)
  File "G:\gitworkspace\TcloudServer\apps\autotest\business\monkey.py", line 686, in query_json_by_user_id
    order_by(desc(MonkeyPackage.id)).limit(int(page_size)).offset(int(page_index - 1) * int(page_size)).all()
  File "D:\Programs\python37\lib\site-packages\sqlalchemy\orm\query.py", line 3211, in all
    return list(self)
  File "D:\Programs\python37\lib\site-packages\sqlalchemy\orm\query.py", line 3367, in __iter__
    return self._execute_and_instances(context)
  File "D:\Programs\python37\lib\site-packages\sqlalchemy\orm\query.py", line 3392, in _execute_and_instances
    result = conn.execute(querycontext.statement, self._params)
  File "D:\Programs\python37\lib\site-packages\sqlalchemy\engine\base.py", line 982, in execute
    return meth(self, multiparams, params)
  File "D:\Programs\python37\lib\site-packages\sqlalchemy\sql\elements.py", line 287, in _execute_on_connection
    return connection._execute_clauseelement(self, multiparams, params)
  File "D:\Programs\python37\lib\site-packages\sqlalchemy\engine\base.py", line 1101, in _execute_clauseelement
    distilled_params,
  File "D:\Programs\python37\lib\site-packages\sqlalchemy\engine\base.py", line 1250, in _execute_context
    e, statement, parameters, cursor, context
  File "D:\Programs\python37\lib\site-packages\sqlalchemy\engine\base.py", line 1476, in _handle_dbapi_exception
    util.raise_from_cause(sqlalchemy_exception, exc_info)
  File "D:\Programs\python37\lib\site-packages\sqlalchemy\util\compat.py", line 398, in raise_from_cause
    reraise(type(exception), exception, tb=exc_tb, cause=cause)
  File "D:\Programs\python37\lib\site-packages\sqlalchemy\util\compat.py", line 152, in reraise
    raise value.with_traceback(tb)
  File "D:\Programs\python37\lib\site-packages\sqlalchemy\engine\base.py", line 1246, in _execute_context
    cursor, statement, parameters, context
  File "D:\Programs\python37\lib\site-packages\sqlalchemy\engine\default.py", line 581, in do_execute
    cursor.execute(statement, parameters)
  File "D:\Programs\python37\lib\site-packages\MySQLdb\cursors.py", line 209, in execute
    res = self._query(query)
  File "D:\Programs\python37\lib\site-packages\MySQLdb\cursors.py", line 315, in _query
    db.query(q)
  File "D:\Programs\python37\lib\site-packages\MySQLdb\connections.py", line 231, in query
    _mysql.connection.query(self, query)
sqlalchemy.exc.OperationalError: (MySQLdb._exceptions.OperationalError) (1054, "Unknown column 'monkey_package.test_type' in 'field list'")
[SQL: SELECT monkey_package.id AS monkey_package_id, monkey_package.creation_time AS monkey_package_creation_time, monkey_package.modified_time AS monkey_package_modified_time, monkey_package.name AS monkey_package_name, monkey_package.package_name AS monkey_package_package_name, monkey_package.oss_url AS monkey_package_oss_url, monkey_package.picture AS monkey_package_picture, monkey_package.version AS monkey_package_version, monkey_package.default_activity AS monkey_package_default_activity, monkey_package.user_id AS monkey_package_user_id, monkey_package.status AS monkey_package_status, monkey_package.size AS monkey_package_size, monkey_package.test_type AS monkey_package_test_type, monkey_package.id AS id, monkey_package.name AS name, monkey_package.package_name AS package_name, monkey_package.oss_url AS oss_url, monkey_package.picture AS picture, monkey_package.version AS version, monkey_package.default_activity AS default_activity, monkey_package.user_id AS user_id, monkey_package.status AS status, monkey_package.size AS size, date_format(monkey_package.creation_time, %s) AS upload_time, monkey_package.test_type AS test_type 
FROM monkey_package 
WHERE monkey_package.status = %s AND monkey_package.test_type = %s AND monkey_package.user_id = %s ORDER BY monkey_package.id DESC 
 LIMIT %s, %s]
[parameters: ('%Y-%m-%d %H:%i:%s', 0, 1, '1152', 0, 10)]
(Background on this error at: http://sqlalche.me/e/e3q8)

[2019-11-22 13:31:46,782][21924][autotest][tMiddleware.py 71 ERROR]: 
request  : /v1/monkey/package  GET [handler: 0]
token    : eyJ0eXAiOiJKV1QiLCJhbGciOiJIUzI1NiJ9.eyJ1c2VyaWQiOjExNTIsInVzZXJuYW1lIjoiYWRtaW4iLCJuaWNrbmFtZSI6ImFkbWluIiwicGljdHVyZSI6IiIsInVzZXJ3ZWlnaHQiOjEsInJvbGUiOlt7ImlkIjoxLCJuYW1lIjoiYWRtaW4iLCJjb21tZW50IjoiXHU4ZDg1XHU3ZWE3XHU3YmExXHU3NDA2XHU1NDU4In0seyJpZCI6MywibmFtZSI6InRlc3QiLCJjb21tZW50IjoiXHU2ZDRiXHU4YmQ1In1dLCJwcm9qZWN0aWQiOlsyXSwiZXhwIjoxNTc1MDMzODgxfQ.QRpqtIUc1lcf7boYzrm8XadcMs-APbWJTyX98VMSxTY
projectid: 
query    : {'page_index': '1', 'page_size': '10'}

Traceback (most recent call last):
  File "D:\Programs\python37\lib\site-packages\sqlalchemy\engine\base.py", line 1246, in _execute_context
    cursor, statement, parameters, context
  File "D:\Programs\python37\lib\site-packages\sqlalchemy\engine\default.py", line 581, in do_execute
    cursor.execute(statement, parameters)
  File "D:\Programs\python37\lib\site-packages\MySQLdb\cursors.py", line 209, in execute
    res = self._query(query)
  File "D:\Programs\python37\lib\site-packages\MySQLdb\cursors.py", line 315, in _query
    db.query(q)
  File "D:\Programs\python37\lib\site-packages\MySQLdb\connections.py", line 231, in query
    _mysql.connection.query(self, query)
MySQLdb._exceptions.OperationalError: (1054, "Unknown column 'monkey_package.test_type' in 'field list'")

The above exception was the direct cause of the following exception:

Traceback (most recent call last):
  File "D:\Programs\python37\lib\site-packages\flask\app.py", line 1949, in full_dispatch_request
    rv = self.dispatch_request()
  File "D:\Programs\python37\lib\site-packages\flask\app.py", line 1935, in dispatch_request
    return self.view_functions[rule.endpoint](**req.view_args)
  File "G:\gitworkspace\TcloudServer\apps\autotest\views\monkey.py", line 479, in monkey_package_index_handler
    all, count = MonkeyPackageBusiness.get_monkey_packages_by_user_id(user_id, page_size, page_index, test_type)
  File "G:\gitworkspace\TcloudServer\apps\autotest\business\monkey.py", line 702, in get_monkey_packages_by_user_id
    all = cls.query_all_json(page_size, page_index, test_type)
  File "G:\gitworkspace\TcloudServer\library\api\transfer.py", line 129, in _
    result = func(*args, **kwargs)
  File "G:\gitworkspace\TcloudServer\apps\autotest\business\monkey.py", line 648, in query_all_json
    int(page_index - 1) * int(page_size)).all()
  File "D:\Programs\python37\lib\site-packages\sqlalchemy\orm\query.py", line 3211, in all
    return list(self)
  File "D:\Programs\python37\lib\site-packages\sqlalchemy\orm\query.py", line 3367, in __iter__
    return self._execute_and_instances(context)
  File "D:\Programs\python37\lib\site-packages\sqlalchemy\orm\query.py", line 3392, in _execute_and_instances
    result = conn.execute(querycontext.statement, self._params)
  File "D:\Programs\python37\lib\site-packages\sqlalchemy\engine\base.py", line 982, in execute
    return meth(self, multiparams, params)
  File "D:\Programs\python37\lib\site-packages\sqlalchemy\sql\elements.py", line 287, in _execute_on_connection
    return connection._execute_clauseelement(self, multiparams, params)
  File "D:\Programs\python37\lib\site-packages\sqlalchemy\engine\base.py", line 1101, in _execute_clauseelement
    distilled_params,
  File "D:\Programs\python37\lib\site-packages\sqlalchemy\engine\base.py", line 1250, in _execute_context
    e, statement, parameters, cursor, context
  File "D:\Programs\python37\lib\site-packages\sqlalchemy\engine\base.py", line 1476, in _handle_dbapi_exception
    util.raise_from_cause(sqlalchemy_exception, exc_info)
  File "D:\Programs\python37\lib\site-packages\sqlalchemy\util\compat.py", line 398, in raise_from_cause
    reraise(type(exception), exception, tb=exc_tb, cause=cause)
  File "D:\Programs\python37\lib\site-packages\sqlalchemy\util\compat.py", line 152, in reraise
    raise value.with_traceback(tb)
  File "D:\Programs\python37\lib\site-packages\sqlalchemy\engine\base.py", line 1246, in _execute_context
    cursor, statement, parameters, context
  File "D:\Programs\python37\lib\site-packages\sqlalchemy\engine\default.py", line 581, in do_execute
    cursor.execute(statement, parameters)
  File "D:\Programs\python37\lib\site-packages\MySQLdb\cursors.py", line 209, in execute
    res = self._query(query)
  File "D:\Programs\python37\lib\site-packages\MySQLdb\cursors.py", line 315, in _query
    db.query(q)
  File "D:\Programs\python37\lib\site-packages\MySQLdb\connections.py", line 231, in query
    _mysql.connection.query(self, query)
sqlalchemy.exc.OperationalError: (MySQLdb._exceptions.OperationalError) (1054, "Unknown column 'monkey_package.test_type' in 'field list'")
[SQL: SELECT monkey_package.id AS monkey_package_id, monkey_package.creation_time AS monkey_package_creation_time, monkey_package.modified_time AS monkey_package_modified_time, monkey_package.name AS monkey_package_name, monkey_package.package_name AS monkey_package_package_name, monkey_package.oss_url AS monkey_package_oss_url, monkey_package.picture AS monkey_package_picture, monkey_package.version AS monkey_package_version, monkey_package.default_activity AS monkey_package_default_activity, monkey_package.user_id AS monkey_package_user_id, monkey_package.status AS monkey_package_status, monkey_package.size AS monkey_package_size, monkey_package.test_type AS monkey_package_test_type, monkey_package.id AS id, monkey_package.name AS name, monkey_package.package_name AS package_name, monkey_package.oss_url AS oss_url, monkey_package.picture AS picture, monkey_package.version AS version, monkey_package.default_activity AS default_activity, monkey_package.user_id AS user_id, monkey_package.status AS status, monkey_package.size AS size, date_format(monkey_package.creation_time, %s) AS upload_time, monkey_package.test_type AS test_type 
FROM monkey_package 
WHERE monkey_package.status = %s AND monkey_package.test_type = %s ORDER BY monkey_package.id DESC 
 LIMIT %s, %s]
[parameters: ('%Y-%m-%d %H:%i:%s', 0, 1, 0, 10)]
(Background on this error at: http://sqlalche.me/e/e3q8)

[2019-11-22 14:08:12,204][21924][autotest][tMiddleware.py 71 ERROR]: 
request  : /v1/monkey/package  GET [handler: 0]
token    : eyJ0eXAiOiJKV1QiLCJhbGciOiJIUzI1NiJ9.eyJ1c2VyaWQiOjExNTIsInVzZXJuYW1lIjoiYWRtaW4iLCJuaWNrbmFtZSI6ImFkbWluIiwicGljdHVyZSI6IiIsInVzZXJ3ZWlnaHQiOjEsInJvbGUiOlt7ImlkIjoxLCJuYW1lIjoiYWRtaW4iLCJjb21tZW50IjoiXHU4ZDg1XHU3ZWE3XHU3YmExXHU3NDA2XHU1NDU4In0seyJpZCI6MywibmFtZSI6InRlc3QiLCJjb21tZW50IjoiXHU2ZDRiXHU4YmQ1In1dLCJwcm9qZWN0aWQiOlsyXSwiZXhwIjoxNTc1MDMzODgxfQ.QRpqtIUc1lcf7boYzrm8XadcMs-APbWJTyX98VMSxTY
projectid: 
query    : {'page_index': '1', 'page_size': '10', 'user_id': '1152'}

Traceback (most recent call last):
  File "D:\Programs\python37\lib\site-packages\sqlalchemy\engine\base.py", line 1246, in _execute_context
    cursor, statement, parameters, context
  File "D:\Programs\python37\lib\site-packages\sqlalchemy\engine\default.py", line 581, in do_execute
    cursor.execute(statement, parameters)
  File "D:\Programs\python37\lib\site-packages\MySQLdb\cursors.py", line 209, in execute
    res = self._query(query)
  File "D:\Programs\python37\lib\site-packages\MySQLdb\cursors.py", line 315, in _query
    db.query(q)
  File "D:\Programs\python37\lib\site-packages\MySQLdb\connections.py", line 231, in query
    _mysql.connection.query(self, query)
MySQLdb._exceptions.OperationalError: (1054, "Unknown column 'monkey_package.test_type' in 'field list'")

The above exception was the direct cause of the following exception:

Traceback (most recent call last):
  File "D:\Programs\python37\lib\site-packages\flask\app.py", line 1949, in full_dispatch_request
    rv = self.dispatch_request()
  File "D:\Programs\python37\lib\site-packages\flask\app.py", line 1935, in dispatch_request
    return self.view_functions[rule.endpoint](**req.view_args)
  File "G:\gitworkspace\TcloudServer\apps\autotest\views\monkey.py", line 479, in monkey_package_index_handler
    all, count = MonkeyPackageBusiness.get_monkey_packages_by_user_id(user_id, page_size, page_index, test_type)
  File "G:\gitworkspace\TcloudServer\apps\autotest\business\monkey.py", line 699, in get_monkey_packages_by_user_id
    all = cls.query_json_by_user_id(user_id, page_size, page_index, test_type)
  File "G:\gitworkspace\TcloudServer\library\api\transfer.py", line 129, in _
    result = func(*args, **kwargs)
  File "G:\gitworkspace\TcloudServer\apps\autotest\business\monkey.py", line 686, in query_json_by_user_id
    order_by(desc(MonkeyPackage.id)).limit(int(page_size)).offset(int(page_index - 1) * int(page_size)).all()
  File "D:\Programs\python37\lib\site-packages\sqlalchemy\orm\query.py", line 3211, in all
    return list(self)
  File "D:\Programs\python37\lib\site-packages\sqlalchemy\orm\query.py", line 3367, in __iter__
    return self._execute_and_instances(context)
  File "D:\Programs\python37\lib\site-packages\sqlalchemy\orm\query.py", line 3392, in _execute_and_instances
    result = conn.execute(querycontext.statement, self._params)
  File "D:\Programs\python37\lib\site-packages\sqlalchemy\engine\base.py", line 982, in execute
    return meth(self, multiparams, params)
  File "D:\Programs\python37\lib\site-packages\sqlalchemy\sql\elements.py", line 287, in _execute_on_connection
    return connection._execute_clauseelement(self, multiparams, params)
  File "D:\Programs\python37\lib\site-packages\sqlalchemy\engine\base.py", line 1101, in _execute_clauseelement
    distilled_params,
  File "D:\Programs\python37\lib\site-packages\sqlalchemy\engine\base.py", line 1250, in _execute_context
    e, statement, parameters, cursor, context
  File "D:\Programs\python37\lib\site-packages\sqlalchemy\engine\base.py", line 1476, in _handle_dbapi_exception
    util.raise_from_cause(sqlalchemy_exception, exc_info)
  File "D:\Programs\python37\lib\site-packages\sqlalchemy\util\compat.py", line 398, in raise_from_cause
    reraise(type(exception), exception, tb=exc_tb, cause=cause)
  File "D:\Programs\python37\lib\site-packages\sqlalchemy\util\compat.py", line 152, in reraise
    raise value.with_traceback(tb)
  File "D:\Programs\python37\lib\site-packages\sqlalchemy\engine\base.py", line 1246, in _execute_context
    cursor, statement, parameters, context
  File "D:\Programs\python37\lib\site-packages\sqlalchemy\engine\default.py", line 581, in do_execute
    cursor.execute(statement, parameters)
  File "D:\Programs\python37\lib\site-packages\MySQLdb\cursors.py", line 209, in execute
    res = self._query(query)
  File "D:\Programs\python37\lib\site-packages\MySQLdb\cursors.py", line 315, in _query
    db.query(q)
  File "D:\Programs\python37\lib\site-packages\MySQLdb\connections.py", line 231, in query
    _mysql.connection.query(self, query)
sqlalchemy.exc.OperationalError: (MySQLdb._exceptions.OperationalError) (1054, "Unknown column 'monkey_package.test_type' in 'field list'")
[SQL: SELECT monkey_package.id AS monkey_package_id, monkey_package.creation_time AS monkey_package_creation_time, monkey_package.modified_time AS monkey_package_modified_time, monkey_package.name AS monkey_package_name, monkey_package.package_name AS monkey_package_package_name, monkey_package.oss_url AS monkey_package_oss_url, monkey_package.picture AS monkey_package_picture, monkey_package.version AS monkey_package_version, monkey_package.default_activity AS monkey_package_default_activity, monkey_package.user_id AS monkey_package_user_id, monkey_package.status AS monkey_package_status, monkey_package.size AS monkey_package_size, monkey_package.test_type AS monkey_package_test_type, monkey_package.id AS id, monkey_package.name AS name, monkey_package.package_name AS package_name, monkey_package.oss_url AS oss_url, monkey_package.picture AS picture, monkey_package.version AS version, monkey_package.default_activity AS default_activity, monkey_package.user_id AS user_id, monkey_package.status AS status, monkey_package.size AS size, date_format(monkey_package.creation_time, %s) AS upload_time, monkey_package.test_type AS test_type 
FROM monkey_package 
WHERE monkey_package.status = %s AND monkey_package.test_type = %s AND monkey_package.user_id = %s ORDER BY monkey_package.id DESC 
 LIMIT %s, %s]
[parameters: ('%Y-%m-%d %H:%i:%s', 0, 1, '1152', 0, 10)]
(Background on this error at: http://sqlalche.me/e/e3q8)

[2019-11-22 14:08:12,237][21924][autotest][tMiddleware.py 71 ERROR]: 
request  : /v1/monkey/package  GET [handler: 0]
token    : eyJ0eXAiOiJKV1QiLCJhbGciOiJIUzI1NiJ9.eyJ1c2VyaWQiOjExNTIsInVzZXJuYW1lIjoiYWRtaW4iLCJuaWNrbmFtZSI6ImFkbWluIiwicGljdHVyZSI6IiIsInVzZXJ3ZWlnaHQiOjEsInJvbGUiOlt7ImlkIjoxLCJuYW1lIjoiYWRtaW4iLCJjb21tZW50IjoiXHU4ZDg1XHU3ZWE3XHU3YmExXHU3NDA2XHU1NDU4In0seyJpZCI6MywibmFtZSI6InRlc3QiLCJjb21tZW50IjoiXHU2ZDRiXHU4YmQ1In1dLCJwcm9qZWN0aWQiOlsyXSwiZXhwIjoxNTc1MDMzODgxfQ.QRpqtIUc1lcf7boYzrm8XadcMs-APbWJTyX98VMSxTY
projectid: 
query    : {'page_index': '1', 'page_size': '10'}

Traceback (most recent call last):
  File "D:\Programs\python37\lib\site-packages\sqlalchemy\engine\base.py", line 1246, in _execute_context
    cursor, statement, parameters, context
  File "D:\Programs\python37\lib\site-packages\sqlalchemy\engine\default.py", line 581, in do_execute
    cursor.execute(statement, parameters)
  File "D:\Programs\python37\lib\site-packages\MySQLdb\cursors.py", line 209, in execute
    res = self._query(query)
  File "D:\Programs\python37\lib\site-packages\MySQLdb\cursors.py", line 315, in _query
    db.query(q)
  File "D:\Programs\python37\lib\site-packages\MySQLdb\connections.py", line 231, in query
    _mysql.connection.query(self, query)
MySQLdb._exceptions.OperationalError: (1054, "Unknown column 'monkey_package.test_type' in 'field list'")

The above exception was the direct cause of the following exception:

Traceback (most recent call last):
  File "D:\Programs\python37\lib\site-packages\flask\app.py", line 1949, in full_dispatch_request
    rv = self.dispatch_request()
  File "D:\Programs\python37\lib\site-packages\flask\app.py", line 1935, in dispatch_request
    return self.view_functions[rule.endpoint](**req.view_args)
  File "G:\gitworkspace\TcloudServer\apps\autotest\views\monkey.py", line 479, in monkey_package_index_handler
    all, count = MonkeyPackageBusiness.get_monkey_packages_by_user_id(user_id, page_size, page_index, test_type)
  File "G:\gitworkspace\TcloudServer\apps\autotest\business\monkey.py", line 702, in get_monkey_packages_by_user_id
    all = cls.query_all_json(page_size, page_index, test_type)
  File "G:\gitworkspace\TcloudServer\library\api\transfer.py", line 129, in _
    result = func(*args, **kwargs)
  File "G:\gitworkspace\TcloudServer\apps\autotest\business\monkey.py", line 648, in query_all_json
    int(page_index - 1) * int(page_size)).all()
  File "D:\Programs\python37\lib\site-packages\sqlalchemy\orm\query.py", line 3211, in all
    return list(self)
  File "D:\Programs\python37\lib\site-packages\sqlalchemy\orm\query.py", line 3367, in __iter__
    return self._execute_and_instances(context)
  File "D:\Programs\python37\lib\site-packages\sqlalchemy\orm\query.py", line 3392, in _execute_and_instances
    result = conn.execute(querycontext.statement, self._params)
  File "D:\Programs\python37\lib\site-packages\sqlalchemy\engine\base.py", line 982, in execute
    return meth(self, multiparams, params)
  File "D:\Programs\python37\lib\site-packages\sqlalchemy\sql\elements.py", line 287, in _execute_on_connection
    return connection._execute_clauseelement(self, multiparams, params)
  File "D:\Programs\python37\lib\site-packages\sqlalchemy\engine\base.py", line 1101, in _execute_clauseelement
    distilled_params,
  File "D:\Programs\python37\lib\site-packages\sqlalchemy\engine\base.py", line 1250, in _execute_context
    e, statement, parameters, cursor, context
  File "D:\Programs\python37\lib\site-packages\sqlalchemy\engine\base.py", line 1476, in _handle_dbapi_exception
    util.raise_from_cause(sqlalchemy_exception, exc_info)
  File "D:\Programs\python37\lib\site-packages\sqlalchemy\util\compat.py", line 398, in raise_from_cause
    reraise(type(exception), exception, tb=exc_tb, cause=cause)
  File "D:\Programs\python37\lib\site-packages\sqlalchemy\util\compat.py", line 152, in reraise
    raise value.with_traceback(tb)
  File "D:\Programs\python37\lib\site-packages\sqlalchemy\engine\base.py", line 1246, in _execute_context
    cursor, statement, parameters, context
  File "D:\Programs\python37\lib\site-packages\sqlalchemy\engine\default.py", line 581, in do_execute
    cursor.execute(statement, parameters)
  File "D:\Programs\python37\lib\site-packages\MySQLdb\cursors.py", line 209, in execute
    res = self._query(query)
  File "D:\Programs\python37\lib\site-packages\MySQLdb\cursors.py", line 315, in _query
    db.query(q)
  File "D:\Programs\python37\lib\site-packages\MySQLdb\connections.py", line 231, in query
    _mysql.connection.query(self, query)
sqlalchemy.exc.OperationalError: (MySQLdb._exceptions.OperationalError) (1054, "Unknown column 'monkey_package.test_type' in 'field list'")
[SQL: SELECT monkey_package.id AS monkey_package_id, monkey_package.creation_time AS monkey_package_creation_time, monkey_package.modified_time AS monkey_package_modified_time, monkey_package.name AS monkey_package_name, monkey_package.package_name AS monkey_package_package_name, monkey_package.oss_url AS monkey_package_oss_url, monkey_package.picture AS monkey_package_picture, monkey_package.version AS monkey_package_version, monkey_package.default_activity AS monkey_package_default_activity, monkey_package.user_id AS monkey_package_user_id, monkey_package.status AS monkey_package_status, monkey_package.size AS monkey_package_size, monkey_package.test_type AS monkey_package_test_type, monkey_package.id AS id, monkey_package.name AS name, monkey_package.package_name AS package_name, monkey_package.oss_url AS oss_url, monkey_package.picture AS picture, monkey_package.version AS version, monkey_package.default_activity AS default_activity, monkey_package.user_id AS user_id, monkey_package.status AS status, monkey_package.size AS size, date_format(monkey_package.creation_time, %s) AS upload_time, monkey_package.test_type AS test_type 
FROM monkey_package 
WHERE monkey_package.status = %s AND monkey_package.test_type = %s ORDER BY monkey_package.id DESC 
 LIMIT %s, %s]
[parameters: ('%Y-%m-%d %H:%i:%s', 0, 1, 0, 10)]
(Background on this error at: http://sqlalche.me/e/e3q8)

[2019-11-22 14:16:27,105][21924][autotest][tMiddleware.py 71 ERROR]: 
request  : /v1/monkey/package  GET [handler: 0]
token    : eyJ0eXAiOiJKV1QiLCJhbGciOiJIUzI1NiJ9.eyJ1c2VyaWQiOjExNTIsInVzZXJuYW1lIjoiYWRtaW4iLCJuaWNrbmFtZSI6ImFkbWluIiwicGljdHVyZSI6IiIsInVzZXJ3ZWlnaHQiOjEsInJvbGUiOlt7ImlkIjoxLCJuYW1lIjoiYWRtaW4iLCJjb21tZW50IjoiXHU4ZDg1XHU3ZWE3XHU3YmExXHU3NDA2XHU1NDU4In0seyJpZCI6MywibmFtZSI6InRlc3QiLCJjb21tZW50IjoiXHU2ZDRiXHU4YmQ1In1dLCJwcm9qZWN0aWQiOlsyXSwiZXhwIjoxNTc1MDMzODgxfQ.QRpqtIUc1lcf7boYzrm8XadcMs-APbWJTyX98VMSxTY
projectid: 
query    : {'page_index': '1', 'page_size': '10'}

Traceback (most recent call last):
  File "D:\Programs\python37\lib\site-packages\sqlalchemy\engine\base.py", line 1246, in _execute_context
    cursor, statement, parameters, context
  File "D:\Programs\python37\lib\site-packages\sqlalchemy\engine\default.py", line 581, in do_execute
    cursor.execute(statement, parameters)
  File "D:\Programs\python37\lib\site-packages\MySQLdb\cursors.py", line 209, in execute
    res = self._query(query)
  File "D:\Programs\python37\lib\site-packages\MySQLdb\cursors.py", line 315, in _query
    db.query(q)
  File "D:\Programs\python37\lib\site-packages\MySQLdb\connections.py", line 231, in query
    _mysql.connection.query(self, query)
MySQLdb._exceptions.OperationalError: (1054, "Unknown column 'monkey_package.test_type' in 'field list'")

The above exception was the direct cause of the following exception:

Traceback (most recent call last):
  File "D:\Programs\python37\lib\site-packages\flask\app.py", line 1949, in full_dispatch_request
    rv = self.dispatch_request()
  File "D:\Programs\python37\lib\site-packages\flask\app.py", line 1935, in dispatch_request
    return self.view_functions[rule.endpoint](**req.view_args)
  File "G:\gitworkspace\TcloudServer\apps\autotest\views\monkey.py", line 479, in monkey_package_index_handler
    all, count = MonkeyPackageBusiness.get_monkey_packages_by_user_id(user_id, page_size, page_index, test_type)
  File "G:\gitworkspace\TcloudServer\apps\autotest\business\monkey.py", line 702, in get_monkey_packages_by_user_id
    all = cls.query_all_json(page_size, page_index, test_type)
  File "G:\gitworkspace\TcloudServer\library\api\transfer.py", line 129, in _
    result = func(*args, **kwargs)
  File "G:\gitworkspace\TcloudServer\apps\autotest\business\monkey.py", line 648, in query_all_json
    int(page_index - 1) * int(page_size)).all()
  File "D:\Programs\python37\lib\site-packages\sqlalchemy\orm\query.py", line 3211, in all
    return list(self)
  File "D:\Programs\python37\lib\site-packages\sqlalchemy\orm\query.py", line 3367, in __iter__
    return self._execute_and_instances(context)
  File "D:\Programs\python37\lib\site-packages\sqlalchemy\orm\query.py", line 3392, in _execute_and_instances
    result = conn.execute(querycontext.statement, self._params)
  File "D:\Programs\python37\lib\site-packages\sqlalchemy\engine\base.py", line 982, in execute
    return meth(self, multiparams, params)
  File "D:\Programs\python37\lib\site-packages\sqlalchemy\sql\elements.py", line 287, in _execute_on_connection
    return connection._execute_clauseelement(self, multiparams, params)
  File "D:\Programs\python37\lib\site-packages\sqlalchemy\engine\base.py", line 1101, in _execute_clauseelement
    distilled_params,
  File "D:\Programs\python37\lib\site-packages\sqlalchemy\engine\base.py", line 1250, in _execute_context
    e, statement, parameters, cursor, context
  File "D:\Programs\python37\lib\site-packages\sqlalchemy\engine\base.py", line 1476, in _handle_dbapi_exception
    util.raise_from_cause(sqlalchemy_exception, exc_info)
  File "D:\Programs\python37\lib\site-packages\sqlalchemy\util\compat.py", line 398, in raise_from_cause
    reraise(type(exception), exception, tb=exc_tb, cause=cause)
  File "D:\Programs\python37\lib\site-packages\sqlalchemy\util\compat.py", line 152, in reraise
    raise value.with_traceback(tb)
  File "D:\Programs\python37\lib\site-packages\sqlalchemy\engine\base.py", line 1246, in _execute_context
    cursor, statement, parameters, context
  File "D:\Programs\python37\lib\site-packages\sqlalchemy\engine\default.py", line 581, in do_execute
    cursor.execute(statement, parameters)
  File "D:\Programs\python37\lib\site-packages\MySQLdb\cursors.py", line 209, in execute
    res = self._query(query)
  File "D:\Programs\python37\lib\site-packages\MySQLdb\cursors.py", line 315, in _query
    db.query(q)
  File "D:\Programs\python37\lib\site-packages\MySQLdb\connections.py", line 231, in query
    _mysql.connection.query(self, query)
sqlalchemy.exc.OperationalError: (MySQLdb._exceptions.OperationalError) (1054, "Unknown column 'monkey_package.test_type' in 'field list'")
[SQL: SELECT monkey_package.id AS monkey_package_id, monkey_package.creation_time AS monkey_package_creation_time, monkey_package.modified_time AS monkey_package_modified_time, monkey_package.name AS monkey_package_name, monkey_package.package_name AS monkey_package_package_name, monkey_package.oss_url AS monkey_package_oss_url, monkey_package.picture AS monkey_package_picture, monkey_package.version AS monkey_package_version, monkey_package.default_activity AS monkey_package_default_activity, monkey_package.user_id AS monkey_package_user_id, monkey_package.status AS monkey_package_status, monkey_package.size AS monkey_package_size, monkey_package.test_type AS monkey_package_test_type, monkey_package.id AS id, monkey_package.name AS name, monkey_package.package_name AS package_name, monkey_package.oss_url AS oss_url, monkey_package.picture AS picture, monkey_package.version AS version, monkey_package.default_activity AS default_activity, monkey_package.user_id AS user_id, monkey_package.status AS status, monkey_package.size AS size, date_format(monkey_package.creation_time, %s) AS upload_time, monkey_package.test_type AS test_type 
FROM monkey_package 
WHERE monkey_package.status = %s AND monkey_package.test_type = %s ORDER BY monkey_package.id DESC 
 LIMIT %s, %s]
[parameters: ('%Y-%m-%d %H:%i:%s', 0, 1, 0, 10)]
(Background on this error at: http://sqlalche.me/e/e3q8)

[2019-11-22 14:16:27,705][21924][autotest][tMiddleware.py 71 ERROR]: 
request  : /v1/monkey/package  GET [handler: 0]
token    : eyJ0eXAiOiJKV1QiLCJhbGciOiJIUzI1NiJ9.eyJ1c2VyaWQiOjExNTIsInVzZXJuYW1lIjoiYWRtaW4iLCJuaWNrbmFtZSI6ImFkbWluIiwicGljdHVyZSI6IiIsInVzZXJ3ZWlnaHQiOjEsInJvbGUiOlt7ImlkIjoxLCJuYW1lIjoiYWRtaW4iLCJjb21tZW50IjoiXHU4ZDg1XHU3ZWE3XHU3YmExXHU3NDA2XHU1NDU4In0seyJpZCI6MywibmFtZSI6InRlc3QiLCJjb21tZW50IjoiXHU2ZDRiXHU4YmQ1In1dLCJwcm9qZWN0aWQiOlsyXSwiZXhwIjoxNTc1MDMzODgxfQ.QRpqtIUc1lcf7boYzrm8XadcMs-APbWJTyX98VMSxTY
projectid: 
query    : {'page_index': '1', 'page_size': '10', 'user_id': '1152'}

Traceback (most recent call last):
  File "D:\Programs\python37\lib\site-packages\sqlalchemy\engine\base.py", line 1246, in _execute_context
    cursor, statement, parameters, context
  File "D:\Programs\python37\lib\site-packages\sqlalchemy\engine\default.py", line 581, in do_execute
    cursor.execute(statement, parameters)
  File "D:\Programs\python37\lib\site-packages\MySQLdb\cursors.py", line 209, in execute
    res = self._query(query)
  File "D:\Programs\python37\lib\site-packages\MySQLdb\cursors.py", line 315, in _query
    db.query(q)
  File "D:\Programs\python37\lib\site-packages\MySQLdb\connections.py", line 231, in query
    _mysql.connection.query(self, query)
MySQLdb._exceptions.OperationalError: (1054, "Unknown column 'monkey_package.test_type' in 'field list'")

The above exception was the direct cause of the following exception:

Traceback (most recent call last):
  File "D:\Programs\python37\lib\site-packages\flask\app.py", line 1949, in full_dispatch_request
    rv = self.dispatch_request()
  File "D:\Programs\python37\lib\site-packages\flask\app.py", line 1935, in dispatch_request
    return self.view_functions[rule.endpoint](**req.view_args)
  File "G:\gitworkspace\TcloudServer\apps\autotest\views\monkey.py", line 479, in monkey_package_index_handler
    all, count = MonkeyPackageBusiness.get_monkey_packages_by_user_id(user_id, page_size, page_index, test_type)
  File "G:\gitworkspace\TcloudServer\apps\autotest\business\monkey.py", line 699, in get_monkey_packages_by_user_id
    all = cls.query_json_by_user_id(user_id, page_size, page_index, test_type)
  File "G:\gitworkspace\TcloudServer\library\api\transfer.py", line 129, in _
    result = func(*args, **kwargs)
  File "G:\gitworkspace\TcloudServer\apps\autotest\business\monkey.py", line 686, in query_json_by_user_id
    order_by(desc(MonkeyPackage.id)).limit(int(page_size)).offset(int(page_index - 1) * int(page_size)).all()
  File "D:\Programs\python37\lib\site-packages\sqlalchemy\orm\query.py", line 3211, in all
    return list(self)
  File "D:\Programs\python37\lib\site-packages\sqlalchemy\orm\query.py", line 3367, in __iter__
    return self._execute_and_instances(context)
  File "D:\Programs\python37\lib\site-packages\sqlalchemy\orm\query.py", line 3392, in _execute_and_instances
    result = conn.execute(querycontext.statement, self._params)
  File "D:\Programs\python37\lib\site-packages\sqlalchemy\engine\base.py", line 982, in execute
    return meth(self, multiparams, params)
  File "D:\Programs\python37\lib\site-packages\sqlalchemy\sql\elements.py", line 287, in _execute_on_connection
    return connection._execute_clauseelement(self, multiparams, params)
  File "D:\Programs\python37\lib\site-packages\sqlalchemy\engine\base.py", line 1101, in _execute_clauseelement
    distilled_params,
  File "D:\Programs\python37\lib\site-packages\sqlalchemy\engine\base.py", line 1250, in _execute_context
    e, statement, parameters, cursor, context
  File "D:\Programs\python37\lib\site-packages\sqlalchemy\engine\base.py", line 1476, in _handle_dbapi_exception
    util.raise_from_cause(sqlalchemy_exception, exc_info)
  File "D:\Programs\python37\lib\site-packages\sqlalchemy\util\compat.py", line 398, in raise_from_cause
    reraise(type(exception), exception, tb=exc_tb, cause=cause)
  File "D:\Programs\python37\lib\site-packages\sqlalchemy\util\compat.py", line 152, in reraise
    raise value.with_traceback(tb)
  File "D:\Programs\python37\lib\site-packages\sqlalchemy\engine\base.py", line 1246, in _execute_context
    cursor, statement, parameters, context
  File "D:\Programs\python37\lib\site-packages\sqlalchemy\engine\default.py", line 581, in do_execute
    cursor.execute(statement, parameters)
  File "D:\Programs\python37\lib\site-packages\MySQLdb\cursors.py", line 209, in execute
    res = self._query(query)
  File "D:\Programs\python37\lib\site-packages\MySQLdb\cursors.py", line 315, in _query
    db.query(q)
  File "D:\Programs\python37\lib\site-packages\MySQLdb\connections.py", line 231, in query
    _mysql.connection.query(self, query)
sqlalchemy.exc.OperationalError: (MySQLdb._exceptions.OperationalError) (1054, "Unknown column 'monkey_package.test_type' in 'field list'")
[SQL: SELECT monkey_package.id AS monkey_package_id, monkey_package.creation_time AS monkey_package_creation_time, monkey_package.modified_time AS monkey_package_modified_time, monkey_package.name AS monkey_package_name, monkey_package.package_name AS monkey_package_package_name, monkey_package.oss_url AS monkey_package_oss_url, monkey_package.picture AS monkey_package_picture, monkey_package.version AS monkey_package_version, monkey_package.default_activity AS monkey_package_default_activity, monkey_package.user_id AS monkey_package_user_id, monkey_package.status AS monkey_package_status, monkey_package.size AS monkey_package_size, monkey_package.test_type AS monkey_package_test_type, monkey_package.id AS id, monkey_package.name AS name, monkey_package.package_name AS package_name, monkey_package.oss_url AS oss_url, monkey_package.picture AS picture, monkey_package.version AS version, monkey_package.default_activity AS default_activity, monkey_package.user_id AS user_id, monkey_package.status AS status, monkey_package.size AS size, date_format(monkey_package.creation_time, %s) AS upload_time, monkey_package.test_type AS test_type 
FROM monkey_package 
WHERE monkey_package.status = %s AND monkey_package.test_type = %s AND monkey_package.user_id = %s ORDER BY monkey_package.id DESC 
 LIMIT %s, %s]
[parameters: ('%Y-%m-%d %H:%i:%s', 0, 1, '1152', 0, 10)]
(Background on this error at: http://sqlalche.me/e/e3q8)

[2019-11-22 14:34:59,380][21924][autotest][tMiddleware.py 71 ERROR]: 
request  : /v1/monkey/package  GET [handler: 0]
token    : eyJ0eXAiOiJKV1QiLCJhbGciOiJIUzI1NiJ9.eyJ1c2VyaWQiOjExNTIsInVzZXJuYW1lIjoiYWRtaW4iLCJuaWNrbmFtZSI6ImFkbWluIiwicGljdHVyZSI6IiIsInVzZXJ3ZWlnaHQiOjEsInJvbGUiOlt7ImlkIjoxLCJuYW1lIjoiYWRtaW4iLCJjb21tZW50IjoiXHU4ZDg1XHU3ZWE3XHU3YmExXHU3NDA2XHU1NDU4In0seyJpZCI6MywibmFtZSI6InRlc3QiLCJjb21tZW50IjoiXHU2ZDRiXHU4YmQ1In1dLCJwcm9qZWN0aWQiOlsyXSwiZXhwIjoxNTc1MDMzODgxfQ.QRpqtIUc1lcf7boYzrm8XadcMs-APbWJTyX98VMSxTY
projectid: 
query    : {'page_index': '1', 'page_size': '10', 'user_id': '1152'}

Traceback (most recent call last):
  File "D:\Programs\python37\lib\site-packages\sqlalchemy\engine\base.py", line 1246, in _execute_context
    cursor, statement, parameters, context
  File "D:\Programs\python37\lib\site-packages\sqlalchemy\engine\default.py", line 581, in do_execute
    cursor.execute(statement, parameters)
  File "D:\Programs\python37\lib\site-packages\MySQLdb\cursors.py", line 209, in execute
    res = self._query(query)
  File "D:\Programs\python37\lib\site-packages\MySQLdb\cursors.py", line 315, in _query
    db.query(q)
  File "D:\Programs\python37\lib\site-packages\MySQLdb\connections.py", line 231, in query
    _mysql.connection.query(self, query)
MySQLdb._exceptions.OperationalError: (1054, "Unknown column 'monkey_package.test_type' in 'field list'")

The above exception was the direct cause of the following exception:

Traceback (most recent call last):
  File "D:\Programs\python37\lib\site-packages\flask\app.py", line 1949, in full_dispatch_request
    rv = self.dispatch_request()
  File "D:\Programs\python37\lib\site-packages\flask\app.py", line 1935, in dispatch_request
    return self.view_functions[rule.endpoint](**req.view_args)
  File "G:\gitworkspace\TcloudServer\apps\autotest\views\monkey.py", line 479, in monkey_package_index_handler
    all, count = MonkeyPackageBusiness.get_monkey_packages_by_user_id(user_id, page_size, page_index, test_type)
  File "G:\gitworkspace\TcloudServer\apps\autotest\business\monkey.py", line 699, in get_monkey_packages_by_user_id
    all = cls.query_json_by_user_id(user_id, page_size, page_index, test_type)
  File "G:\gitworkspace\TcloudServer\library\api\transfer.py", line 129, in _
    result = func(*args, **kwargs)
  File "G:\gitworkspace\TcloudServer\apps\autotest\business\monkey.py", line 686, in query_json_by_user_id
    order_by(desc(MonkeyPackage.id)).limit(int(page_size)).offset(int(page_index - 1) * int(page_size)).all()
  File "D:\Programs\python37\lib\site-packages\sqlalchemy\orm\query.py", line 3211, in all
    return list(self)
  File "D:\Programs\python37\lib\site-packages\sqlalchemy\orm\query.py", line 3367, in __iter__
    return self._execute_and_instances(context)
  File "D:\Programs\python37\lib\site-packages\sqlalchemy\orm\query.py", line 3392, in _execute_and_instances
    result = conn.execute(querycontext.statement, self._params)
  File "D:\Programs\python37\lib\site-packages\sqlalchemy\engine\base.py", line 982, in execute
    return meth(self, multiparams, params)
  File "D:\Programs\python37\lib\site-packages\sqlalchemy\sql\elements.py", line 287, in _execute_on_connection
    return connection._execute_clauseelement(self, multiparams, params)
  File "D:\Programs\python37\lib\site-packages\sqlalchemy\engine\base.py", line 1101, in _execute_clauseelement
    distilled_params,
  File "D:\Programs\python37\lib\site-packages\sqlalchemy\engine\base.py", line 1250, in _execute_context
    e, statement, parameters, cursor, context
  File "D:\Programs\python37\lib\site-packages\sqlalchemy\engine\base.py", line 1476, in _handle_dbapi_exception
    util.raise_from_cause(sqlalchemy_exception, exc_info)
  File "D:\Programs\python37\lib\site-packages\sqlalchemy\util\compat.py", line 398, in raise_from_cause
    reraise(type(exception), exception, tb=exc_tb, cause=cause)
  File "D:\Programs\python37\lib\site-packages\sqlalchemy\util\compat.py", line 152, in reraise
    raise value.with_traceback(tb)
  File "D:\Programs\python37\lib\site-packages\sqlalchemy\engine\base.py", line 1246, in _execute_context
    cursor, statement, parameters, context
  File "D:\Programs\python37\lib\site-packages\sqlalchemy\engine\default.py", line 581, in do_execute
    cursor.execute(statement, parameters)
  File "D:\Programs\python37\lib\site-packages\MySQLdb\cursors.py", line 209, in execute
    res = self._query(query)
  File "D:\Programs\python37\lib\site-packages\MySQLdb\cursors.py", line 315, in _query
    db.query(q)
  File "D:\Programs\python37\lib\site-packages\MySQLdb\connections.py", line 231, in query
    _mysql.connection.query(self, query)
sqlalchemy.exc.OperationalError: (MySQLdb._exceptions.OperationalError) (1054, "Unknown column 'monkey_package.test_type' in 'field list'")
[SQL: SELECT monkey_package.id AS monkey_package_id, monkey_package.creation_time AS monkey_package_creation_time, monkey_package.modified_time AS monkey_package_modified_time, monkey_package.name AS monkey_package_name, monkey_package.package_name AS monkey_package_package_name, monkey_package.oss_url AS monkey_package_oss_url, monkey_package.picture AS monkey_package_picture, monkey_package.version AS monkey_package_version, monkey_package.default_activity AS monkey_package_default_activity, monkey_package.user_id AS monkey_package_user_id, monkey_package.status AS monkey_package_status, monkey_package.size AS monkey_package_size, monkey_package.test_type AS monkey_package_test_type, monkey_package.id AS id, monkey_package.name AS name, monkey_package.package_name AS package_name, monkey_package.oss_url AS oss_url, monkey_package.picture AS picture, monkey_package.version AS version, monkey_package.default_activity AS default_activity, monkey_package.user_id AS user_id, monkey_package.status AS status, monkey_package.size AS size, date_format(monkey_package.creation_time, %s) AS upload_time, monkey_package.test_type AS test_type 
FROM monkey_package 
WHERE monkey_package.status = %s AND monkey_package.test_type = %s AND monkey_package.user_id = %s ORDER BY monkey_package.id DESC 
 LIMIT %s, %s]
[parameters: ('%Y-%m-%d %H:%i:%s', 0, 1, '1152', 0, 10)]
(Background on this error at: http://sqlalche.me/e/e3q8)

[2019-11-22 14:34:59,388][21924][autotest][tMiddleware.py 71 ERROR]: 
request  : /v1/monkey/package  GET [handler: 0]
token    : eyJ0eXAiOiJKV1QiLCJhbGciOiJIUzI1NiJ9.eyJ1c2VyaWQiOjExNTIsInVzZXJuYW1lIjoiYWRtaW4iLCJuaWNrbmFtZSI6ImFkbWluIiwicGljdHVyZSI6IiIsInVzZXJ3ZWlnaHQiOjEsInJvbGUiOlt7ImlkIjoxLCJuYW1lIjoiYWRtaW4iLCJjb21tZW50IjoiXHU4ZDg1XHU3ZWE3XHU3YmExXHU3NDA2XHU1NDU4In0seyJpZCI6MywibmFtZSI6InRlc3QiLCJjb21tZW50IjoiXHU2ZDRiXHU4YmQ1In1dLCJwcm9qZWN0aWQiOlsyXSwiZXhwIjoxNTc1MDMzODgxfQ.QRpqtIUc1lcf7boYzrm8XadcMs-APbWJTyX98VMSxTY
projectid: 
query    : {'page_index': '1', 'page_size': '10'}

Traceback (most recent call last):
  File "D:\Programs\python37\lib\site-packages\sqlalchemy\engine\base.py", line 1246, in _execute_context
    cursor, statement, parameters, context
  File "D:\Programs\python37\lib\site-packages\sqlalchemy\engine\default.py", line 581, in do_execute
    cursor.execute(statement, parameters)
  File "D:\Programs\python37\lib\site-packages\MySQLdb\cursors.py", line 209, in execute
    res = self._query(query)
  File "D:\Programs\python37\lib\site-packages\MySQLdb\cursors.py", line 315, in _query
    db.query(q)
  File "D:\Programs\python37\lib\site-packages\MySQLdb\connections.py", line 231, in query
    _mysql.connection.query(self, query)
MySQLdb._exceptions.OperationalError: (1054, "Unknown column 'monkey_package.test_type' in 'field list'")

The above exception was the direct cause of the following exception:

Traceback (most recent call last):
  File "D:\Programs\python37\lib\site-packages\flask\app.py", line 1949, in full_dispatch_request
    rv = self.dispatch_request()
  File "D:\Programs\python37\lib\site-packages\flask\app.py", line 1935, in dispatch_request
    return self.view_functions[rule.endpoint](**req.view_args)
  File "G:\gitworkspace\TcloudServer\apps\autotest\views\monkey.py", line 479, in monkey_package_index_handler
    all, count = MonkeyPackageBusiness.get_monkey_packages_by_user_id(user_id, page_size, page_index, test_type)
  File "G:\gitworkspace\TcloudServer\apps\autotest\business\monkey.py", line 702, in get_monkey_packages_by_user_id
    all = cls.query_all_json(page_size, page_index, test_type)
  File "G:\gitworkspace\TcloudServer\library\api\transfer.py", line 129, in _
    result = func(*args, **kwargs)
  File "G:\gitworkspace\TcloudServer\apps\autotest\business\monkey.py", line 648, in query_all_json
    int(page_index - 1) * int(page_size)).all()
  File "D:\Programs\python37\lib\site-packages\sqlalchemy\orm\query.py", line 3211, in all
    return list(self)
  File "D:\Programs\python37\lib\site-packages\sqlalchemy\orm\query.py", line 3367, in __iter__
    return self._execute_and_instances(context)
  File "D:\Programs\python37\lib\site-packages\sqlalchemy\orm\query.py", line 3392, in _execute_and_instances
    result = conn.execute(querycontext.statement, self._params)
  File "D:\Programs\python37\lib\site-packages\sqlalchemy\engine\base.py", line 982, in execute
    return meth(self, multiparams, params)
  File "D:\Programs\python37\lib\site-packages\sqlalchemy\sql\elements.py", line 287, in _execute_on_connection
    return connection._execute_clauseelement(self, multiparams, params)
  File "D:\Programs\python37\lib\site-packages\sqlalchemy\engine\base.py", line 1101, in _execute_clauseelement
    distilled_params,
  File "D:\Programs\python37\lib\site-packages\sqlalchemy\engine\base.py", line 1250, in _execute_context
    e, statement, parameters, cursor, context
  File "D:\Programs\python37\lib\site-packages\sqlalchemy\engine\base.py", line 1476, in _handle_dbapi_exception
    util.raise_from_cause(sqlalchemy_exception, exc_info)
  File "D:\Programs\python37\lib\site-packages\sqlalchemy\util\compat.py", line 398, in raise_from_cause
    reraise(type(exception), exception, tb=exc_tb, cause=cause)
  File "D:\Programs\python37\lib\site-packages\sqlalchemy\util\compat.py", line 152, in reraise
    raise value.with_traceback(tb)
  File "D:\Programs\python37\lib\site-packages\sqlalchemy\engine\base.py", line 1246, in _execute_context
    cursor, statement, parameters, context
  File "D:\Programs\python37\lib\site-packages\sqlalchemy\engine\default.py", line 581, in do_execute
    cursor.execute(statement, parameters)
  File "D:\Programs\python37\lib\site-packages\MySQLdb\cursors.py", line 209, in execute
    res = self._query(query)
  File "D:\Programs\python37\lib\site-packages\MySQLdb\cursors.py", line 315, in _query
    db.query(q)
  File "D:\Programs\python37\lib\site-packages\MySQLdb\connections.py", line 231, in query
    _mysql.connection.query(self, query)
sqlalchemy.exc.OperationalError: (MySQLdb._exceptions.OperationalError) (1054, "Unknown column 'monkey_package.test_type' in 'field list'")
[SQL: SELECT monkey_package.id AS monkey_package_id, monkey_package.creation_time AS monkey_package_creation_time, monkey_package.modified_time AS monkey_package_modified_time, monkey_package.name AS monkey_package_name, monkey_package.package_name AS monkey_package_package_name, monkey_package.oss_url AS monkey_package_oss_url, monkey_package.picture AS monkey_package_picture, monkey_package.version AS monkey_package_version, monkey_package.default_activity AS monkey_package_default_activity, monkey_package.user_id AS monkey_package_user_id, monkey_package.status AS monkey_package_status, monkey_package.size AS monkey_package_size, monkey_package.test_type AS monkey_package_test_type, monkey_package.id AS id, monkey_package.name AS name, monkey_package.package_name AS package_name, monkey_package.oss_url AS oss_url, monkey_package.picture AS picture, monkey_package.version AS version, monkey_package.default_activity AS default_activity, monkey_package.user_id AS user_id, monkey_package.status AS status, monkey_package.size AS size, date_format(monkey_package.creation_time, %s) AS upload_time, monkey_package.test_type AS test_type 
FROM monkey_package 
WHERE monkey_package.status = %s AND monkey_package.test_type = %s ORDER BY monkey_package.id DESC 
 LIMIT %s, %s]
[parameters: ('%Y-%m-%d %H:%i:%s', 0, 1, 0, 10)]
(Background on this error at: http://sqlalche.me/e/e3q8)

[2019-11-22 14:42:26,585][35428][autotest][tMiddleware.py 71 ERROR]: 
request  : /v1/monkey/package  GET [handler: 0]
token    : eyJ0eXAiOiJKV1QiLCJhbGciOiJIUzI1NiJ9.eyJ1c2VyaWQiOjExNTIsInVzZXJuYW1lIjoiYWRtaW4iLCJuaWNrbmFtZSI6ImFkbWluIiwicGljdHVyZSI6IiIsInVzZXJ3ZWlnaHQiOjEsInJvbGUiOlt7ImlkIjoxLCJuYW1lIjoiYWRtaW4iLCJjb21tZW50IjoiXHU4ZDg1XHU3ZWE3XHU3YmExXHU3NDA2XHU1NDU4In0seyJpZCI6MywibmFtZSI6InRlc3QiLCJjb21tZW50IjoiXHU2ZDRiXHU4YmQ1In1dLCJwcm9qZWN0aWQiOlsyXSwiZXhwIjoxNTc1MDMzODgxfQ.QRpqtIUc1lcf7boYzrm8XadcMs-APbWJTyX98VMSxTY
projectid: 
query    : {'page_index': '1', 'page_size': '10', 'user_id': '1152'}

Traceback (most recent call last):
  File "D:\Programs\python37\lib\site-packages\sqlalchemy\engine\base.py", line 1246, in _execute_context
    cursor, statement, parameters, context
  File "D:\Programs\python37\lib\site-packages\sqlalchemy\engine\default.py", line 581, in do_execute
    cursor.execute(statement, parameters)
  File "D:\Programs\python37\lib\site-packages\MySQLdb\cursors.py", line 209, in execute
    res = self._query(query)
  File "D:\Programs\python37\lib\site-packages\MySQLdb\cursors.py", line 315, in _query
    db.query(q)
  File "D:\Programs\python37\lib\site-packages\MySQLdb\connections.py", line 231, in query
    _mysql.connection.query(self, query)
MySQLdb._exceptions.OperationalError: (1054, "Unknown column 'monkey_package.test_type' in 'field list'")

The above exception was the direct cause of the following exception:

Traceback (most recent call last):
  File "D:\Programs\python37\lib\site-packages\flask\app.py", line 1949, in full_dispatch_request
    rv = self.dispatch_request()
  File "D:\Programs\python37\lib\site-packages\flask\app.py", line 1935, in dispatch_request
    return self.view_functions[rule.endpoint](**req.view_args)
  File "G:\gitworkspace\TcloudServer\apps\autotest\views\monkey.py", line 479, in monkey_package_index_handler
    all, count = MonkeyPackageBusiness.get_monkey_packages_by_user_id(user_id, page_size, page_index, test_type)
  File "G:\gitworkspace\TcloudServer\apps\autotest\business\monkey.py", line 699, in get_monkey_packages_by_user_id
    all = cls.query_json_by_user_id(user_id, page_size, page_index, test_type)
  File "G:\gitworkspace\TcloudServer\library\api\transfer.py", line 129, in _
    result = func(*args, **kwargs)
  File "G:\gitworkspace\TcloudServer\apps\autotest\business\monkey.py", line 686, in query_json_by_user_id
    order_by(desc(MonkeyPackage.id)).limit(int(page_size)).offset(int(page_index - 1) * int(page_size)).all()
  File "D:\Programs\python37\lib\site-packages\sqlalchemy\orm\query.py", line 3211, in all
    return list(self)
  File "D:\Programs\python37\lib\site-packages\sqlalchemy\orm\query.py", line 3367, in __iter__
    return self._execute_and_instances(context)
  File "D:\Programs\python37\lib\site-packages\sqlalchemy\orm\query.py", line 3392, in _execute_and_instances
    result = conn.execute(querycontext.statement, self._params)
  File "D:\Programs\python37\lib\site-packages\sqlalchemy\engine\base.py", line 982, in execute
    return meth(self, multiparams, params)
  File "D:\Programs\python37\lib\site-packages\sqlalchemy\sql\elements.py", line 287, in _execute_on_connection
    return connection._execute_clauseelement(self, multiparams, params)
  File "D:\Programs\python37\lib\site-packages\sqlalchemy\engine\base.py", line 1101, in _execute_clauseelement
    distilled_params,
  File "D:\Programs\python37\lib\site-packages\sqlalchemy\engine\base.py", line 1250, in _execute_context
    e, statement, parameters, cursor, context
  File "D:\Programs\python37\lib\site-packages\sqlalchemy\engine\base.py", line 1476, in _handle_dbapi_exception
    util.raise_from_cause(sqlalchemy_exception, exc_info)
  File "D:\Programs\python37\lib\site-packages\sqlalchemy\util\compat.py", line 398, in raise_from_cause
    reraise(type(exception), exception, tb=exc_tb, cause=cause)
  File "D:\Programs\python37\lib\site-packages\sqlalchemy\util\compat.py", line 152, in reraise
    raise value.with_traceback(tb)
  File "D:\Programs\python37\lib\site-packages\sqlalchemy\engine\base.py", line 1246, in _execute_context
    cursor, statement, parameters, context
  File "D:\Programs\python37\lib\site-packages\sqlalchemy\engine\default.py", line 581, in do_execute
    cursor.execute(statement, parameters)
  File "D:\Programs\python37\lib\site-packages\MySQLdb\cursors.py", line 209, in execute
    res = self._query(query)
  File "D:\Programs\python37\lib\site-packages\MySQLdb\cursors.py", line 315, in _query
    db.query(q)
  File "D:\Programs\python37\lib\site-packages\MySQLdb\connections.py", line 231, in query
    _mysql.connection.query(self, query)
sqlalchemy.exc.OperationalError: (MySQLdb._exceptions.OperationalError) (1054, "Unknown column 'monkey_package.test_type' in 'field list'")
[SQL: SELECT monkey_package.id AS monkey_package_id, monkey_package.creation_time AS monkey_package_creation_time, monkey_package.modified_time AS monkey_package_modified_time, monkey_package.name AS monkey_package_name, monkey_package.package_name AS monkey_package_package_name, monkey_package.oss_url AS monkey_package_oss_url, monkey_package.picture AS monkey_package_picture, monkey_package.version AS monkey_package_version, monkey_package.default_activity AS monkey_package_default_activity, monkey_package.user_id AS monkey_package_user_id, monkey_package.status AS monkey_package_status, monkey_package.size AS monkey_package_size, monkey_package.test_type AS monkey_package_test_type, monkey_package.id AS id, monkey_package.name AS name, monkey_package.package_name AS package_name, monkey_package.oss_url AS oss_url, monkey_package.picture AS picture, monkey_package.version AS version, monkey_package.default_activity AS default_activity, monkey_package.user_id AS user_id, monkey_package.status AS status, monkey_package.size AS size, date_format(monkey_package.creation_time, %s) AS upload_time, monkey_package.test_type AS test_type 
FROM monkey_package 
WHERE monkey_package.status = %s AND monkey_package.test_type = %s AND monkey_package.user_id = %s ORDER BY monkey_package.id DESC 
 LIMIT %s, %s]
[parameters: ('%Y-%m-%d %H:%i:%s', 0, 1, '1152', 0, 10)]
(Background on this error at: http://sqlalche.me/e/e3q8)

[2019-11-22 14:42:26,629][35428][autotest][tMiddleware.py 71 ERROR]: 
request  : /v1/monkey/package  GET [handler: 0]
token    : eyJ0eXAiOiJKV1QiLCJhbGciOiJIUzI1NiJ9.eyJ1c2VyaWQiOjExNTIsInVzZXJuYW1lIjoiYWRtaW4iLCJuaWNrbmFtZSI6ImFkbWluIiwicGljdHVyZSI6IiIsInVzZXJ3ZWlnaHQiOjEsInJvbGUiOlt7ImlkIjoxLCJuYW1lIjoiYWRtaW4iLCJjb21tZW50IjoiXHU4ZDg1XHU3ZWE3XHU3YmExXHU3NDA2XHU1NDU4In0seyJpZCI6MywibmFtZSI6InRlc3QiLCJjb21tZW50IjoiXHU2ZDRiXHU4YmQ1In1dLCJwcm9qZWN0aWQiOlsyXSwiZXhwIjoxNTc1MDMzODgxfQ.QRpqtIUc1lcf7boYzrm8XadcMs-APbWJTyX98VMSxTY
projectid: 
query    : {'page_index': '1', 'page_size': '10'}

Traceback (most recent call last):
  File "D:\Programs\python37\lib\site-packages\sqlalchemy\engine\base.py", line 1246, in _execute_context
    cursor, statement, parameters, context
  File "D:\Programs\python37\lib\site-packages\sqlalchemy\engine\default.py", line 581, in do_execute
    cursor.execute(statement, parameters)
  File "D:\Programs\python37\lib\site-packages\MySQLdb\cursors.py", line 209, in execute
    res = self._query(query)
  File "D:\Programs\python37\lib\site-packages\MySQLdb\cursors.py", line 315, in _query
    db.query(q)
  File "D:\Programs\python37\lib\site-packages\MySQLdb\connections.py", line 231, in query
    _mysql.connection.query(self, query)
MySQLdb._exceptions.OperationalError: (1054, "Unknown column 'monkey_package.test_type' in 'field list'")

The above exception was the direct cause of the following exception:

Traceback (most recent call last):
  File "D:\Programs\python37\lib\site-packages\flask\app.py", line 1949, in full_dispatch_request
    rv = self.dispatch_request()
  File "D:\Programs\python37\lib\site-packages\flask\app.py", line 1935, in dispatch_request
    return self.view_functions[rule.endpoint](**req.view_args)
  File "G:\gitworkspace\TcloudServer\apps\autotest\views\monkey.py", line 479, in monkey_package_index_handler
    all, count = MonkeyPackageBusiness.get_monkey_packages_by_user_id(user_id, page_size, page_index, test_type)
  File "G:\gitworkspace\TcloudServer\apps\autotest\business\monkey.py", line 702, in get_monkey_packages_by_user_id
    all = cls.query_all_json(page_size, page_index, test_type)
  File "G:\gitworkspace\TcloudServer\library\api\transfer.py", line 129, in _
    result = func(*args, **kwargs)
  File "G:\gitworkspace\TcloudServer\apps\autotest\business\monkey.py", line 648, in query_all_json
    int(page_index - 1) * int(page_size)).all()
  File "D:\Programs\python37\lib\site-packages\sqlalchemy\orm\query.py", line 3211, in all
    return list(self)
  File "D:\Programs\python37\lib\site-packages\sqlalchemy\orm\query.py", line 3367, in __iter__
    return self._execute_and_instances(context)
  File "D:\Programs\python37\lib\site-packages\sqlalchemy\orm\query.py", line 3392, in _execute_and_instances
    result = conn.execute(querycontext.statement, self._params)
  File "D:\Programs\python37\lib\site-packages\sqlalchemy\engine\base.py", line 982, in execute
    return meth(self, multiparams, params)
  File "D:\Programs\python37\lib\site-packages\sqlalchemy\sql\elements.py", line 287, in _execute_on_connection
    return connection._execute_clauseelement(self, multiparams, params)
  File "D:\Programs\python37\lib\site-packages\sqlalchemy\engine\base.py", line 1101, in _execute_clauseelement
    distilled_params,
  File "D:\Programs\python37\lib\site-packages\sqlalchemy\engine\base.py", line 1250, in _execute_context
    e, statement, parameters, cursor, context
  File "D:\Programs\python37\lib\site-packages\sqlalchemy\engine\base.py", line 1476, in _handle_dbapi_exception
    util.raise_from_cause(sqlalchemy_exception, exc_info)
  File "D:\Programs\python37\lib\site-packages\sqlalchemy\util\compat.py", line 398, in raise_from_cause
    reraise(type(exception), exception, tb=exc_tb, cause=cause)
  File "D:\Programs\python37\lib\site-packages\sqlalchemy\util\compat.py", line 152, in reraise
    raise value.with_traceback(tb)
  File "D:\Programs\python37\lib\site-packages\sqlalchemy\engine\base.py", line 1246, in _execute_context
    cursor, statement, parameters, context
  File "D:\Programs\python37\lib\site-packages\sqlalchemy\engine\default.py", line 581, in do_execute
    cursor.execute(statement, parameters)
  File "D:\Programs\python37\lib\site-packages\MySQLdb\cursors.py", line 209, in execute
    res = self._query(query)
  File "D:\Programs\python37\lib\site-packages\MySQLdb\cursors.py", line 315, in _query
    db.query(q)
  File "D:\Programs\python37\lib\site-packages\MySQLdb\connections.py", line 231, in query
    _mysql.connection.query(self, query)
sqlalchemy.exc.OperationalError: (MySQLdb._exceptions.OperationalError) (1054, "Unknown column 'monkey_package.test_type' in 'field list'")
[SQL: SELECT monkey_package.id AS monkey_package_id, monkey_package.creation_time AS monkey_package_creation_time, monkey_package.modified_time AS monkey_package_modified_time, monkey_package.name AS monkey_package_name, monkey_package.package_name AS monkey_package_package_name, monkey_package.oss_url AS monkey_package_oss_url, monkey_package.picture AS monkey_package_picture, monkey_package.version AS monkey_package_version, monkey_package.default_activity AS monkey_package_default_activity, monkey_package.user_id AS monkey_package_user_id, monkey_package.status AS monkey_package_status, monkey_package.size AS monkey_package_size, monkey_package.test_type AS monkey_package_test_type, monkey_package.id AS id, monkey_package.name AS name, monkey_package.package_name AS package_name, monkey_package.oss_url AS oss_url, monkey_package.picture AS picture, monkey_package.version AS version, monkey_package.default_activity AS default_activity, monkey_package.user_id AS user_id, monkey_package.status AS status, monkey_package.size AS size, date_format(monkey_package.creation_time, %s) AS upload_time, monkey_package.test_type AS test_type 
FROM monkey_package 
WHERE monkey_package.status = %s AND monkey_package.test_type = %s ORDER BY monkey_package.id DESC 
 LIMIT %s, %s]
[parameters: ('%Y-%m-%d %H:%i:%s', 0, 1, 0, 10)]
(Background on this error at: http://sqlalche.me/e/e3q8)

[2019-11-22 14:50:35,568][37328][autotest][tMiddleware.py 71 ERROR]: 
request  : /v1/monkey/package  GET [handler: 0]
token    : eyJ0eXAiOiJKV1QiLCJhbGciOiJIUzI1NiJ9.eyJ1c2VyaWQiOjExNTIsInVzZXJuYW1lIjoiYWRtaW4iLCJuaWNrbmFtZSI6ImFkbWluIiwicGljdHVyZSI6IiIsInVzZXJ3ZWlnaHQiOjEsInJvbGUiOlt7ImlkIjoxLCJuYW1lIjoiYWRtaW4iLCJjb21tZW50IjoiXHU4ZDg1XHU3ZWE3XHU3YmExXHU3NDA2XHU1NDU4In0seyJpZCI6MywibmFtZSI6InRlc3QiLCJjb21tZW50IjoiXHU2ZDRiXHU4YmQ1In1dLCJwcm9qZWN0aWQiOlsyXSwiZXhwIjoxNTc1MDMzODgxfQ.QRpqtIUc1lcf7boYzrm8XadcMs-APbWJTyX98VMSxTY
projectid: 
query    : {'page_index': '1', 'page_size': '10', 'user_id': '1152'}

Traceback (most recent call last):
  File "D:\Programs\python37\lib\site-packages\sqlalchemy\engine\base.py", line 1246, in _execute_context
    cursor, statement, parameters, context
  File "D:\Programs\python37\lib\site-packages\sqlalchemy\engine\default.py", line 581, in do_execute
    cursor.execute(statement, parameters)
  File "D:\Programs\python37\lib\site-packages\MySQLdb\cursors.py", line 209, in execute
    res = self._query(query)
  File "D:\Programs\python37\lib\site-packages\MySQLdb\cursors.py", line 315, in _query
    db.query(q)
  File "D:\Programs\python37\lib\site-packages\MySQLdb\connections.py", line 231, in query
    _mysql.connection.query(self, query)
MySQLdb._exceptions.OperationalError: (1054, "Unknown column 'monkey_package.test_type' in 'field list'")

The above exception was the direct cause of the following exception:

Traceback (most recent call last):
  File "D:\Programs\python37\lib\site-packages\flask\app.py", line 1949, in full_dispatch_request
    rv = self.dispatch_request()
  File "D:\Programs\python37\lib\site-packages\flask\app.py", line 1935, in dispatch_request
    return self.view_functions[rule.endpoint](**req.view_args)
  File "G:\gitworkspace\TcloudServer\apps\autotest\views\monkey.py", line 479, in monkey_package_index_handler
    all, count = MonkeyPackageBusiness.get_monkey_packages_by_user_id(user_id, page_size, page_index, test_type)
  File "G:\gitworkspace\TcloudServer\apps\autotest\business\monkey.py", line 699, in get_monkey_packages_by_user_id
    all = cls.query_json_by_user_id(user_id, page_size, page_index, test_type)
  File "G:\gitworkspace\TcloudServer\library\api\transfer.py", line 129, in _
    result = func(*args, **kwargs)
  File "G:\gitworkspace\TcloudServer\apps\autotest\business\monkey.py", line 686, in query_json_by_user_id
    order_by(desc(MonkeyPackage.id)).limit(int(page_size)).offset(int(page_index - 1) * int(page_size)).all()
  File "D:\Programs\python37\lib\site-packages\sqlalchemy\orm\query.py", line 3211, in all
    return list(self)
  File "D:\Programs\python37\lib\site-packages\sqlalchemy\orm\query.py", line 3367, in __iter__
    return self._execute_and_instances(context)
  File "D:\Programs\python37\lib\site-packages\sqlalchemy\orm\query.py", line 3392, in _execute_and_instances
    result = conn.execute(querycontext.statement, self._params)
  File "D:\Programs\python37\lib\site-packages\sqlalchemy\engine\base.py", line 982, in execute
    return meth(self, multiparams, params)
  File "D:\Programs\python37\lib\site-packages\sqlalchemy\sql\elements.py", line 287, in _execute_on_connection
    return connection._execute_clauseelement(self, multiparams, params)
  File "D:\Programs\python37\lib\site-packages\sqlalchemy\engine\base.py", line 1101, in _execute_clauseelement
    distilled_params,
  File "D:\Programs\python37\lib\site-packages\sqlalchemy\engine\base.py", line 1250, in _execute_context
    e, statement, parameters, cursor, context
  File "D:\Programs\python37\lib\site-packages\sqlalchemy\engine\base.py", line 1476, in _handle_dbapi_exception
    util.raise_from_cause(sqlalchemy_exception, exc_info)
  File "D:\Programs\python37\lib\site-packages\sqlalchemy\util\compat.py", line 398, in raise_from_cause
    reraise(type(exception), exception, tb=exc_tb, cause=cause)
  File "D:\Programs\python37\lib\site-packages\sqlalchemy\util\compat.py", line 152, in reraise
    raise value.with_traceback(tb)
  File "D:\Programs\python37\lib\site-packages\sqlalchemy\engine\base.py", line 1246, in _execute_context
    cursor, statement, parameters, context
  File "D:\Programs\python37\lib\site-packages\sqlalchemy\engine\default.py", line 581, in do_execute
    cursor.execute(statement, parameters)
  File "D:\Programs\python37\lib\site-packages\MySQLdb\cursors.py", line 209, in execute
    res = self._query(query)
  File "D:\Programs\python37\lib\site-packages\MySQLdb\cursors.py", line 315, in _query
    db.query(q)
  File "D:\Programs\python37\lib\site-packages\MySQLdb\connections.py", line 231, in query
    _mysql.connection.query(self, query)
sqlalchemy.exc.OperationalError: (MySQLdb._exceptions.OperationalError) (1054, "Unknown column 'monkey_package.test_type' in 'field list'")
[SQL: SELECT monkey_package.id AS monkey_package_id, monkey_package.creation_time AS monkey_package_creation_time, monkey_package.modified_time AS monkey_package_modified_time, monkey_package.name AS monkey_package_name, monkey_package.package_name AS monkey_package_package_name, monkey_package.oss_url AS monkey_package_oss_url, monkey_package.picture AS monkey_package_picture, monkey_package.version AS monkey_package_version, monkey_package.default_activity AS monkey_package_default_activity, monkey_package.user_id AS monkey_package_user_id, monkey_package.status AS monkey_package_status, monkey_package.size AS monkey_package_size, monkey_package.test_type AS monkey_package_test_type, monkey_package.id AS id, monkey_package.name AS name, monkey_package.package_name AS package_name, monkey_package.oss_url AS oss_url, monkey_package.picture AS picture, monkey_package.version AS version, monkey_package.default_activity AS default_activity, monkey_package.user_id AS user_id, monkey_package.status AS status, monkey_package.size AS size, date_format(monkey_package.creation_time, %s) AS upload_time, monkey_package.test_type AS test_type 
FROM monkey_package 
WHERE monkey_package.status = %s AND monkey_package.test_type = %s AND monkey_package.user_id = %s ORDER BY monkey_package.id DESC 
 LIMIT %s, %s]
[parameters: ('%Y-%m-%d %H:%i:%s', 0, 1, '1152', 0, 10)]
(Background on this error at: http://sqlalche.me/e/e3q8)

[2019-11-22 14:50:35,603][37328][autotest][tMiddleware.py 71 ERROR]: 
request  : /v1/monkey/package  GET [handler: 0]
token    : eyJ0eXAiOiJKV1QiLCJhbGciOiJIUzI1NiJ9.eyJ1c2VyaWQiOjExNTIsInVzZXJuYW1lIjoiYWRtaW4iLCJuaWNrbmFtZSI6ImFkbWluIiwicGljdHVyZSI6IiIsInVzZXJ3ZWlnaHQiOjEsInJvbGUiOlt7ImlkIjoxLCJuYW1lIjoiYWRtaW4iLCJjb21tZW50IjoiXHU4ZDg1XHU3ZWE3XHU3YmExXHU3NDA2XHU1NDU4In0seyJpZCI6MywibmFtZSI6InRlc3QiLCJjb21tZW50IjoiXHU2ZDRiXHU4YmQ1In1dLCJwcm9qZWN0aWQiOlsyXSwiZXhwIjoxNTc1MDMzODgxfQ.QRpqtIUc1lcf7boYzrm8XadcMs-APbWJTyX98VMSxTY
projectid: 
query    : {'page_index': '1', 'page_size': '10'}

Traceback (most recent call last):
  File "D:\Programs\python37\lib\site-packages\sqlalchemy\engine\base.py", line 1246, in _execute_context
    cursor, statement, parameters, context
  File "D:\Programs\python37\lib\site-packages\sqlalchemy\engine\default.py", line 581, in do_execute
    cursor.execute(statement, parameters)
  File "D:\Programs\python37\lib\site-packages\MySQLdb\cursors.py", line 209, in execute
    res = self._query(query)
  File "D:\Programs\python37\lib\site-packages\MySQLdb\cursors.py", line 315, in _query
    db.query(q)
  File "D:\Programs\python37\lib\site-packages\MySQLdb\connections.py", line 231, in query
    _mysql.connection.query(self, query)
MySQLdb._exceptions.OperationalError: (1054, "Unknown column 'monkey_package.test_type' in 'field list'")

The above exception was the direct cause of the following exception:

Traceback (most recent call last):
  File "D:\Programs\python37\lib\site-packages\flask\app.py", line 1949, in full_dispatch_request
    rv = self.dispatch_request()
  File "D:\Programs\python37\lib\site-packages\flask\app.py", line 1935, in dispatch_request
    return self.view_functions[rule.endpoint](**req.view_args)
  File "G:\gitworkspace\TcloudServer\apps\autotest\views\monkey.py", line 479, in monkey_package_index_handler
    all, count = MonkeyPackageBusiness.get_monkey_packages_by_user_id(user_id, page_size, page_index, test_type)
  File "G:\gitworkspace\TcloudServer\apps\autotest\business\monkey.py", line 702, in get_monkey_packages_by_user_id
    all = cls.query_all_json(page_size, page_index, test_type)
  File "G:\gitworkspace\TcloudServer\library\api\transfer.py", line 129, in _
    result = func(*args, **kwargs)
  File "G:\gitworkspace\TcloudServer\apps\autotest\business\monkey.py", line 648, in query_all_json
    int(page_index - 1) * int(page_size)).all()
  File "D:\Programs\python37\lib\site-packages\sqlalchemy\orm\query.py", line 3211, in all
    return list(self)
  File "D:\Programs\python37\lib\site-packages\sqlalchemy\orm\query.py", line 3367, in __iter__
    return self._execute_and_instances(context)
  File "D:\Programs\python37\lib\site-packages\sqlalchemy\orm\query.py", line 3392, in _execute_and_instances
    result = conn.execute(querycontext.statement, self._params)
  File "D:\Programs\python37\lib\site-packages\sqlalchemy\engine\base.py", line 982, in execute
    return meth(self, multiparams, params)
  File "D:\Programs\python37\lib\site-packages\sqlalchemy\sql\elements.py", line 287, in _execute_on_connection
    return connection._execute_clauseelement(self, multiparams, params)
  File "D:\Programs\python37\lib\site-packages\sqlalchemy\engine\base.py", line 1101, in _execute_clauseelement
    distilled_params,
  File "D:\Programs\python37\lib\site-packages\sqlalchemy\engine\base.py", line 1250, in _execute_context
    e, statement, parameters, cursor, context
  File "D:\Programs\python37\lib\site-packages\sqlalchemy\engine\base.py", line 1476, in _handle_dbapi_exception
    util.raise_from_cause(sqlalchemy_exception, exc_info)
  File "D:\Programs\python37\lib\site-packages\sqlalchemy\util\compat.py", line 398, in raise_from_cause
    reraise(type(exception), exception, tb=exc_tb, cause=cause)
  File "D:\Programs\python37\lib\site-packages\sqlalchemy\util\compat.py", line 152, in reraise
    raise value.with_traceback(tb)
  File "D:\Programs\python37\lib\site-packages\sqlalchemy\engine\base.py", line 1246, in _execute_context
    cursor, statement, parameters, context
  File "D:\Programs\python37\lib\site-packages\sqlalchemy\engine\default.py", line 581, in do_execute
    cursor.execute(statement, parameters)
  File "D:\Programs\python37\lib\site-packages\MySQLdb\cursors.py", line 209, in execute
    res = self._query(query)
  File "D:\Programs\python37\lib\site-packages\MySQLdb\cursors.py", line 315, in _query
    db.query(q)
  File "D:\Programs\python37\lib\site-packages\MySQLdb\connections.py", line 231, in query
    _mysql.connection.query(self, query)
sqlalchemy.exc.OperationalError: (MySQLdb._exceptions.OperationalError) (1054, "Unknown column 'monkey_package.test_type' in 'field list'")
[SQL: SELECT monkey_package.id AS monkey_package_id, monkey_package.creation_time AS monkey_package_creation_time, monkey_package.modified_time AS monkey_package_modified_time, monkey_package.name AS monkey_package_name, monkey_package.package_name AS monkey_package_package_name, monkey_package.oss_url AS monkey_package_oss_url, monkey_package.picture AS monkey_package_picture, monkey_package.version AS monkey_package_version, monkey_package.default_activity AS monkey_package_default_activity, monkey_package.user_id AS monkey_package_user_id, monkey_package.status AS monkey_package_status, monkey_package.size AS monkey_package_size, monkey_package.test_type AS monkey_package_test_type, monkey_package.id AS id, monkey_package.name AS name, monkey_package.package_name AS package_name, monkey_package.oss_url AS oss_url, monkey_package.picture AS picture, monkey_package.version AS version, monkey_package.default_activity AS default_activity, monkey_package.user_id AS user_id, monkey_package.status AS status, monkey_package.size AS size, date_format(monkey_package.creation_time, %s) AS upload_time, monkey_package.test_type AS test_type 
FROM monkey_package 
WHERE monkey_package.status = %s AND monkey_package.test_type = %s ORDER BY monkey_package.id DESC 
 LIMIT %s, %s]
[parameters: ('%Y-%m-%d %H:%i:%s', 0, 1, 0, 10)]
(Background on this error at: http://sqlalche.me/e/e3q8)

[2019-11-22 15:05:25,830][37328][autotest][tMiddleware.py 71 ERROR]: 
request  : /v1/monkey/package  GET [handler: 0]
token    : eyJ0eXAiOiJKV1QiLCJhbGciOiJIUzI1NiJ9.eyJ1c2VyaWQiOjExNTIsInVzZXJuYW1lIjoiYWRtaW4iLCJuaWNrbmFtZSI6ImFkbWluIiwicGljdHVyZSI6IiIsInVzZXJ3ZWlnaHQiOjEsInJvbGUiOlt7ImlkIjoxLCJuYW1lIjoiYWRtaW4iLCJjb21tZW50IjoiXHU4ZDg1XHU3ZWE3XHU3YmExXHU3NDA2XHU1NDU4In0seyJpZCI6MywibmFtZSI6InRlc3QiLCJjb21tZW50IjoiXHU2ZDRiXHU4YmQ1In1dLCJwcm9qZWN0aWQiOlsyXSwiZXhwIjoxNTc1MDMzODgxfQ.QRpqtIUc1lcf7boYzrm8XadcMs-APbWJTyX98VMSxTY
projectid: 
query    : {'page_index': '1', 'page_size': '10', 'user_id': '1152'}

Traceback (most recent call last):
  File "D:\Programs\python37\lib\site-packages\sqlalchemy\engine\base.py", line 1246, in _execute_context
    cursor, statement, parameters, context
  File "D:\Programs\python37\lib\site-packages\sqlalchemy\engine\default.py", line 581, in do_execute
    cursor.execute(statement, parameters)
  File "D:\Programs\python37\lib\site-packages\MySQLdb\cursors.py", line 209, in execute
    res = self._query(query)
  File "D:\Programs\python37\lib\site-packages\MySQLdb\cursors.py", line 315, in _query
    db.query(q)
  File "D:\Programs\python37\lib\site-packages\MySQLdb\connections.py", line 231, in query
    _mysql.connection.query(self, query)
MySQLdb._exceptions.OperationalError: (1054, "Unknown column 'monkey_package.test_type' in 'field list'")

The above exception was the direct cause of the following exception:

Traceback (most recent call last):
  File "D:\Programs\python37\lib\site-packages\flask\app.py", line 1949, in full_dispatch_request
    rv = self.dispatch_request()
  File "D:\Programs\python37\lib\site-packages\flask\app.py", line 1935, in dispatch_request
    return self.view_functions[rule.endpoint](**req.view_args)
  File "G:\gitworkspace\TcloudServer\apps\autotest\views\monkey.py", line 479, in monkey_package_index_handler
    all, count = MonkeyPackageBusiness.get_monkey_packages_by_user_id(user_id, page_size, page_index, test_type)
  File "G:\gitworkspace\TcloudServer\apps\autotest\business\monkey.py", line 699, in get_monkey_packages_by_user_id
    all = cls.query_json_by_user_id(user_id, page_size, page_index, test_type)
  File "G:\gitworkspace\TcloudServer\library\api\transfer.py", line 129, in _
    result = func(*args, **kwargs)
  File "G:\gitworkspace\TcloudServer\apps\autotest\business\monkey.py", line 686, in query_json_by_user_id
    order_by(desc(MonkeyPackage.id)).limit(int(page_size)).offset(int(page_index - 1) * int(page_size)).all()
  File "D:\Programs\python37\lib\site-packages\sqlalchemy\orm\query.py", line 3211, in all
    return list(self)
  File "D:\Programs\python37\lib\site-packages\sqlalchemy\orm\query.py", line 3367, in __iter__
    return self._execute_and_instances(context)
  File "D:\Programs\python37\lib\site-packages\sqlalchemy\orm\query.py", line 3392, in _execute_and_instances
    result = conn.execute(querycontext.statement, self._params)
  File "D:\Programs\python37\lib\site-packages\sqlalchemy\engine\base.py", line 982, in execute
    return meth(self, multiparams, params)
  File "D:\Programs\python37\lib\site-packages\sqlalchemy\sql\elements.py", line 287, in _execute_on_connection
    return connection._execute_clauseelement(self, multiparams, params)
  File "D:\Programs\python37\lib\site-packages\sqlalchemy\engine\base.py", line 1101, in _execute_clauseelement
    distilled_params,
  File "D:\Programs\python37\lib\site-packages\sqlalchemy\engine\base.py", line 1250, in _execute_context
    e, statement, parameters, cursor, context
  File "D:\Programs\python37\lib\site-packages\sqlalchemy\engine\base.py", line 1476, in _handle_dbapi_exception
    util.raise_from_cause(sqlalchemy_exception, exc_info)
  File "D:\Programs\python37\lib\site-packages\sqlalchemy\util\compat.py", line 398, in raise_from_cause
    reraise(type(exception), exception, tb=exc_tb, cause=cause)
  File "D:\Programs\python37\lib\site-packages\sqlalchemy\util\compat.py", line 152, in reraise
    raise value.with_traceback(tb)
  File "D:\Programs\python37\lib\site-packages\sqlalchemy\engine\base.py", line 1246, in _execute_context
    cursor, statement, parameters, context
  File "D:\Programs\python37\lib\site-packages\sqlalchemy\engine\default.py", line 581, in do_execute
    cursor.execute(statement, parameters)
  File "D:\Programs\python37\lib\site-packages\MySQLdb\cursors.py", line 209, in execute
    res = self._query(query)
  File "D:\Programs\python37\lib\site-packages\MySQLdb\cursors.py", line 315, in _query
    db.query(q)
  File "D:\Programs\python37\lib\site-packages\MySQLdb\connections.py", line 231, in query
    _mysql.connection.query(self, query)
sqlalchemy.exc.OperationalError: (MySQLdb._exceptions.OperationalError) (1054, "Unknown column 'monkey_package.test_type' in 'field list'")
[SQL: SELECT monkey_package.id AS monkey_package_id, monkey_package.creation_time AS monkey_package_creation_time, monkey_package.modified_time AS monkey_package_modified_time, monkey_package.name AS monkey_package_name, monkey_package.package_name AS monkey_package_package_name, monkey_package.oss_url AS monkey_package_oss_url, monkey_package.picture AS monkey_package_picture, monkey_package.version AS monkey_package_version, monkey_package.default_activity AS monkey_package_default_activity, monkey_package.user_id AS monkey_package_user_id, monkey_package.status AS monkey_package_status, monkey_package.size AS monkey_package_size, monkey_package.test_type AS monkey_package_test_type, monkey_package.id AS id, monkey_package.name AS name, monkey_package.package_name AS package_name, monkey_package.oss_url AS oss_url, monkey_package.picture AS picture, monkey_package.version AS version, monkey_package.default_activity AS default_activity, monkey_package.user_id AS user_id, monkey_package.status AS status, monkey_package.size AS size, date_format(monkey_package.creation_time, %s) AS upload_time, monkey_package.test_type AS test_type 
FROM monkey_package 
WHERE monkey_package.status = %s AND monkey_package.test_type = %s AND monkey_package.user_id = %s ORDER BY monkey_package.id DESC 
 LIMIT %s, %s]
[parameters: ('%Y-%m-%d %H:%i:%s', 0, 1, '1152', 0, 10)]
(Background on this error at: http://sqlalche.me/e/e3q8)

[2019-11-22 15:05:25,845][37328][autotest][tMiddleware.py 71 ERROR]: 
request  : /v1/monkey/package  GET [handler: 0]
token    : eyJ0eXAiOiJKV1QiLCJhbGciOiJIUzI1NiJ9.eyJ1c2VyaWQiOjExNTIsInVzZXJuYW1lIjoiYWRtaW4iLCJuaWNrbmFtZSI6ImFkbWluIiwicGljdHVyZSI6IiIsInVzZXJ3ZWlnaHQiOjEsInJvbGUiOlt7ImlkIjoxLCJuYW1lIjoiYWRtaW4iLCJjb21tZW50IjoiXHU4ZDg1XHU3ZWE3XHU3YmExXHU3NDA2XHU1NDU4In0seyJpZCI6MywibmFtZSI6InRlc3QiLCJjb21tZW50IjoiXHU2ZDRiXHU4YmQ1In1dLCJwcm9qZWN0aWQiOlsyXSwiZXhwIjoxNTc1MDMzODgxfQ.QRpqtIUc1lcf7boYzrm8XadcMs-APbWJTyX98VMSxTY
projectid: 
query    : {'page_index': '1', 'page_size': '10'}

Traceback (most recent call last):
  File "D:\Programs\python37\lib\site-packages\sqlalchemy\engine\base.py", line 1246, in _execute_context
    cursor, statement, parameters, context
  File "D:\Programs\python37\lib\site-packages\sqlalchemy\engine\default.py", line 581, in do_execute
    cursor.execute(statement, parameters)
  File "D:\Programs\python37\lib\site-packages\MySQLdb\cursors.py", line 209, in execute
    res = self._query(query)
  File "D:\Programs\python37\lib\site-packages\MySQLdb\cursors.py", line 315, in _query
    db.query(q)
  File "D:\Programs\python37\lib\site-packages\MySQLdb\connections.py", line 231, in query
    _mysql.connection.query(self, query)
MySQLdb._exceptions.OperationalError: (1054, "Unknown column 'monkey_package.test_type' in 'field list'")

The above exception was the direct cause of the following exception:

Traceback (most recent call last):
  File "D:\Programs\python37\lib\site-packages\flask\app.py", line 1949, in full_dispatch_request
    rv = self.dispatch_request()
  File "D:\Programs\python37\lib\site-packages\flask\app.py", line 1935, in dispatch_request
    return self.view_functions[rule.endpoint](**req.view_args)
  File "G:\gitworkspace\TcloudServer\apps\autotest\views\monkey.py", line 479, in monkey_package_index_handler
    all, count = MonkeyPackageBusiness.get_monkey_packages_by_user_id(user_id, page_size, page_index, test_type)
  File "G:\gitworkspace\TcloudServer\apps\autotest\business\monkey.py", line 702, in get_monkey_packages_by_user_id
    all = cls.query_all_json(page_size, page_index, test_type)
  File "G:\gitworkspace\TcloudServer\library\api\transfer.py", line 129, in _
    result = func(*args, **kwargs)
  File "G:\gitworkspace\TcloudServer\apps\autotest\business\monkey.py", line 648, in query_all_json
    int(page_index - 1) * int(page_size)).all()
  File "D:\Programs\python37\lib\site-packages\sqlalchemy\orm\query.py", line 3211, in all
    return list(self)
  File "D:\Programs\python37\lib\site-packages\sqlalchemy\orm\query.py", line 3367, in __iter__
    return self._execute_and_instances(context)
  File "D:\Programs\python37\lib\site-packages\sqlalchemy\orm\query.py", line 3392, in _execute_and_instances
    result = conn.execute(querycontext.statement, self._params)
  File "D:\Programs\python37\lib\site-packages\sqlalchemy\engine\base.py", line 982, in execute
    return meth(self, multiparams, params)
  File "D:\Programs\python37\lib\site-packages\sqlalchemy\sql\elements.py", line 287, in _execute_on_connection
    return connection._execute_clauseelement(self, multiparams, params)
  File "D:\Programs\python37\lib\site-packages\sqlalchemy\engine\base.py", line 1101, in _execute_clauseelement
    distilled_params,
  File "D:\Programs\python37\lib\site-packages\sqlalchemy\engine\base.py", line 1250, in _execute_context
    e, statement, parameters, cursor, context
  File "D:\Programs\python37\lib\site-packages\sqlalchemy\engine\base.py", line 1476, in _handle_dbapi_exception
    util.raise_from_cause(sqlalchemy_exception, exc_info)
  File "D:\Programs\python37\lib\site-packages\sqlalchemy\util\compat.py", line 398, in raise_from_cause
    reraise(type(exception), exception, tb=exc_tb, cause=cause)
  File "D:\Programs\python37\lib\site-packages\sqlalchemy\util\compat.py", line 152, in reraise
    raise value.with_traceback(tb)
  File "D:\Programs\python37\lib\site-packages\sqlalchemy\engine\base.py", line 1246, in _execute_context
    cursor, statement, parameters, context
  File "D:\Programs\python37\lib\site-packages\sqlalchemy\engine\default.py", line 581, in do_execute
    cursor.execute(statement, parameters)
  File "D:\Programs\python37\lib\site-packages\MySQLdb\cursors.py", line 209, in execute
    res = self._query(query)
  File "D:\Programs\python37\lib\site-packages\MySQLdb\cursors.py", line 315, in _query
    db.query(q)
  File "D:\Programs\python37\lib\site-packages\MySQLdb\connections.py", line 231, in query
    _mysql.connection.query(self, query)
sqlalchemy.exc.OperationalError: (MySQLdb._exceptions.OperationalError) (1054, "Unknown column 'monkey_package.test_type' in 'field list'")
[SQL: SELECT monkey_package.id AS monkey_package_id, monkey_package.creation_time AS monkey_package_creation_time, monkey_package.modified_time AS monkey_package_modified_time, monkey_package.name AS monkey_package_name, monkey_package.package_name AS monkey_package_package_name, monkey_package.oss_url AS monkey_package_oss_url, monkey_package.picture AS monkey_package_picture, monkey_package.version AS monkey_package_version, monkey_package.default_activity AS monkey_package_default_activity, monkey_package.user_id AS monkey_package_user_id, monkey_package.status AS monkey_package_status, monkey_package.size AS monkey_package_size, monkey_package.test_type AS monkey_package_test_type, monkey_package.id AS id, monkey_package.name AS name, monkey_package.package_name AS package_name, monkey_package.oss_url AS oss_url, monkey_package.picture AS picture, monkey_package.version AS version, monkey_package.default_activity AS default_activity, monkey_package.user_id AS user_id, monkey_package.status AS status, monkey_package.size AS size, date_format(monkey_package.creation_time, %s) AS upload_time, monkey_package.test_type AS test_type 
FROM monkey_package 
WHERE monkey_package.status = %s AND monkey_package.test_type = %s ORDER BY monkey_package.id DESC 
 LIMIT %s, %s]
[parameters: ('%Y-%m-%d %H:%i:%s', 0, 1, 0, 10)]
(Background on this error at: http://sqlalche.me/e/e3q8)

[2019-11-22 15:09:35,986][37328][autotest][tMiddleware.py 71 ERROR]: 
request  : /v1/monkey/package  GET [handler: 0]
token    : eyJ0eXAiOiJKV1QiLCJhbGciOiJIUzI1NiJ9.eyJ1c2VyaWQiOjExNTIsInVzZXJuYW1lIjoiYWRtaW4iLCJuaWNrbmFtZSI6ImFkbWluIiwicGljdHVyZSI6IiIsInVzZXJ3ZWlnaHQiOjEsInJvbGUiOlt7ImlkIjoxLCJuYW1lIjoiYWRtaW4iLCJjb21tZW50IjoiXHU4ZDg1XHU3ZWE3XHU3YmExXHU3NDA2XHU1NDU4In0seyJpZCI6MywibmFtZSI6InRlc3QiLCJjb21tZW50IjoiXHU2ZDRiXHU4YmQ1In1dLCJwcm9qZWN0aWQiOlsyXSwiZXhwIjoxNTc1MDMzODgxfQ.QRpqtIUc1lcf7boYzrm8XadcMs-APbWJTyX98VMSxTY
projectid: 
query    : {'page_index': '1', 'page_size': '10', 'user_id': '1152'}

Traceback (most recent call last):
  File "D:\Programs\python37\lib\site-packages\sqlalchemy\engine\base.py", line 1246, in _execute_context
    cursor, statement, parameters, context
  File "D:\Programs\python37\lib\site-packages\sqlalchemy\engine\default.py", line 581, in do_execute
    cursor.execute(statement, parameters)
  File "D:\Programs\python37\lib\site-packages\MySQLdb\cursors.py", line 209, in execute
    res = self._query(query)
  File "D:\Programs\python37\lib\site-packages\MySQLdb\cursors.py", line 315, in _query
    db.query(q)
  File "D:\Programs\python37\lib\site-packages\MySQLdb\connections.py", line 231, in query
    _mysql.connection.query(self, query)
MySQLdb._exceptions.OperationalError: (1054, "Unknown column 'monkey_package.test_type' in 'field list'")

The above exception was the direct cause of the following exception:

Traceback (most recent call last):
  File "D:\Programs\python37\lib\site-packages\flask\app.py", line 1949, in full_dispatch_request
    rv = self.dispatch_request()
  File "D:\Programs\python37\lib\site-packages\flask\app.py", line 1935, in dispatch_request
    return self.view_functions[rule.endpoint](**req.view_args)
  File "G:\gitworkspace\TcloudServer\apps\autotest\views\monkey.py", line 479, in monkey_package_index_handler
    all, count = MonkeyPackageBusiness.get_monkey_packages_by_user_id(user_id, page_size, page_index, test_type)
  File "G:\gitworkspace\TcloudServer\apps\autotest\business\monkey.py", line 699, in get_monkey_packages_by_user_id
    all = cls.query_json_by_user_id(user_id, page_size, page_index, test_type)
  File "G:\gitworkspace\TcloudServer\library\api\transfer.py", line 129, in _
    result = func(*args, **kwargs)
  File "G:\gitworkspace\TcloudServer\apps\autotest\business\monkey.py", line 686, in query_json_by_user_id
    order_by(desc(MonkeyPackage.id)).limit(int(page_size)).offset(int(page_index - 1) * int(page_size)).all()
  File "D:\Programs\python37\lib\site-packages\sqlalchemy\orm\query.py", line 3211, in all
    return list(self)
  File "D:\Programs\python37\lib\site-packages\sqlalchemy\orm\query.py", line 3367, in __iter__
    return self._execute_and_instances(context)
  File "D:\Programs\python37\lib\site-packages\sqlalchemy\orm\query.py", line 3392, in _execute_and_instances
    result = conn.execute(querycontext.statement, self._params)
  File "D:\Programs\python37\lib\site-packages\sqlalchemy\engine\base.py", line 982, in execute
    return meth(self, multiparams, params)
  File "D:\Programs\python37\lib\site-packages\sqlalchemy\sql\elements.py", line 287, in _execute_on_connection
    return connection._execute_clauseelement(self, multiparams, params)
  File "D:\Programs\python37\lib\site-packages\sqlalchemy\engine\base.py", line 1101, in _execute_clauseelement
    distilled_params,
  File "D:\Programs\python37\lib\site-packages\sqlalchemy\engine\base.py", line 1250, in _execute_context
    e, statement, parameters, cursor, context
  File "D:\Programs\python37\lib\site-packages\sqlalchemy\engine\base.py", line 1476, in _handle_dbapi_exception
    util.raise_from_cause(sqlalchemy_exception, exc_info)
  File "D:\Programs\python37\lib\site-packages\sqlalchemy\util\compat.py", line 398, in raise_from_cause
    reraise(type(exception), exception, tb=exc_tb, cause=cause)
  File "D:\Programs\python37\lib\site-packages\sqlalchemy\util\compat.py", line 152, in reraise
    raise value.with_traceback(tb)
  File "D:\Programs\python37\lib\site-packages\sqlalchemy\engine\base.py", line 1246, in _execute_context
    cursor, statement, parameters, context
  File "D:\Programs\python37\lib\site-packages\sqlalchemy\engine\default.py", line 581, in do_execute
    cursor.execute(statement, parameters)
  File "D:\Programs\python37\lib\site-packages\MySQLdb\cursors.py", line 209, in execute
    res = self._query(query)
  File "D:\Programs\python37\lib\site-packages\MySQLdb\cursors.py", line 315, in _query
    db.query(q)
  File "D:\Programs\python37\lib\site-packages\MySQLdb\connections.py", line 231, in query
    _mysql.connection.query(self, query)
sqlalchemy.exc.OperationalError: (MySQLdb._exceptions.OperationalError) (1054, "Unknown column 'monkey_package.test_type' in 'field list'")
[SQL: SELECT monkey_package.id AS monkey_package_id, monkey_package.creation_time AS monkey_package_creation_time, monkey_package.modified_time AS monkey_package_modified_time, monkey_package.name AS monkey_package_name, monkey_package.package_name AS monkey_package_package_name, monkey_package.oss_url AS monkey_package_oss_url, monkey_package.picture AS monkey_package_picture, monkey_package.version AS monkey_package_version, monkey_package.default_activity AS monkey_package_default_activity, monkey_package.user_id AS monkey_package_user_id, monkey_package.status AS monkey_package_status, monkey_package.size AS monkey_package_size, monkey_package.test_type AS monkey_package_test_type, monkey_package.id AS id, monkey_package.name AS name, monkey_package.package_name AS package_name, monkey_package.oss_url AS oss_url, monkey_package.picture AS picture, monkey_package.version AS version, monkey_package.default_activity AS default_activity, monkey_package.user_id AS user_id, monkey_package.status AS status, monkey_package.size AS size, date_format(monkey_package.creation_time, %s) AS upload_time, monkey_package.test_type AS test_type 
FROM monkey_package 
WHERE monkey_package.status = %s AND monkey_package.test_type = %s AND monkey_package.user_id = %s ORDER BY monkey_package.id DESC 
 LIMIT %s, %s]
[parameters: ('%Y-%m-%d %H:%i:%s', 0, 1, '1152', 0, 10)]
(Background on this error at: http://sqlalche.me/e/e3q8)

[2019-11-22 15:09:36,163][37328][autotest][tMiddleware.py 71 ERROR]: 
request  : /v1/monkey/package  GET [handler: 0]
token    : eyJ0eXAiOiJKV1QiLCJhbGciOiJIUzI1NiJ9.eyJ1c2VyaWQiOjExNTIsInVzZXJuYW1lIjoiYWRtaW4iLCJuaWNrbmFtZSI6ImFkbWluIiwicGljdHVyZSI6IiIsInVzZXJ3ZWlnaHQiOjEsInJvbGUiOlt7ImlkIjoxLCJuYW1lIjoiYWRtaW4iLCJjb21tZW50IjoiXHU4ZDg1XHU3ZWE3XHU3YmExXHU3NDA2XHU1NDU4In0seyJpZCI6MywibmFtZSI6InRlc3QiLCJjb21tZW50IjoiXHU2ZDRiXHU4YmQ1In1dLCJwcm9qZWN0aWQiOlsyXSwiZXhwIjoxNTc1MDMzODgxfQ.QRpqtIUc1lcf7boYzrm8XadcMs-APbWJTyX98VMSxTY
projectid: 
query    : {'page_index': '1', 'page_size': '10'}

Traceback (most recent call last):
  File "D:\Programs\python37\lib\site-packages\sqlalchemy\engine\base.py", line 1246, in _execute_context
    cursor, statement, parameters, context
  File "D:\Programs\python37\lib\site-packages\sqlalchemy\engine\default.py", line 581, in do_execute
    cursor.execute(statement, parameters)
  File "D:\Programs\python37\lib\site-packages\MySQLdb\cursors.py", line 209, in execute
    res = self._query(query)
  File "D:\Programs\python37\lib\site-packages\MySQLdb\cursors.py", line 315, in _query
    db.query(q)
  File "D:\Programs\python37\lib\site-packages\MySQLdb\connections.py", line 231, in query
    _mysql.connection.query(self, query)
MySQLdb._exceptions.OperationalError: (1054, "Unknown column 'monkey_package.test_type' in 'field list'")

The above exception was the direct cause of the following exception:

Traceback (most recent call last):
  File "D:\Programs\python37\lib\site-packages\flask\app.py", line 1949, in full_dispatch_request
    rv = self.dispatch_request()
  File "D:\Programs\python37\lib\site-packages\flask\app.py", line 1935, in dispatch_request
    return self.view_functions[rule.endpoint](**req.view_args)
  File "G:\gitworkspace\TcloudServer\apps\autotest\views\monkey.py", line 479, in monkey_package_index_handler
    all, count = MonkeyPackageBusiness.get_monkey_packages_by_user_id(user_id, page_size, page_index, test_type)
  File "G:\gitworkspace\TcloudServer\apps\autotest\business\monkey.py", line 702, in get_monkey_packages_by_user_id
    all = cls.query_all_json(page_size, page_index, test_type)
  File "G:\gitworkspace\TcloudServer\library\api\transfer.py", line 129, in _
    result = func(*args, **kwargs)
  File "G:\gitworkspace\TcloudServer\apps\autotest\business\monkey.py", line 648, in query_all_json
    int(page_index - 1) * int(page_size)).all()
  File "D:\Programs\python37\lib\site-packages\sqlalchemy\orm\query.py", line 3211, in all
    return list(self)
  File "D:\Programs\python37\lib\site-packages\sqlalchemy\orm\query.py", line 3367, in __iter__
    return self._execute_and_instances(context)
  File "D:\Programs\python37\lib\site-packages\sqlalchemy\orm\query.py", line 3392, in _execute_and_instances
    result = conn.execute(querycontext.statement, self._params)
  File "D:\Programs\python37\lib\site-packages\sqlalchemy\engine\base.py", line 982, in execute
    return meth(self, multiparams, params)
  File "D:\Programs\python37\lib\site-packages\sqlalchemy\sql\elements.py", line 287, in _execute_on_connection
    return connection._execute_clauseelement(self, multiparams, params)
  File "D:\Programs\python37\lib\site-packages\sqlalchemy\engine\base.py", line 1101, in _execute_clauseelement
    distilled_params,
  File "D:\Programs\python37\lib\site-packages\sqlalchemy\engine\base.py", line 1250, in _execute_context
    e, statement, parameters, cursor, context
  File "D:\Programs\python37\lib\site-packages\sqlalchemy\engine\base.py", line 1476, in _handle_dbapi_exception
    util.raise_from_cause(sqlalchemy_exception, exc_info)
  File "D:\Programs\python37\lib\site-packages\sqlalchemy\util\compat.py", line 398, in raise_from_cause
    reraise(type(exception), exception, tb=exc_tb, cause=cause)
  File "D:\Programs\python37\lib\site-packages\sqlalchemy\util\compat.py", line 152, in reraise
    raise value.with_traceback(tb)
  File "D:\Programs\python37\lib\site-packages\sqlalchemy\engine\base.py", line 1246, in _execute_context
    cursor, statement, parameters, context
  File "D:\Programs\python37\lib\site-packages\sqlalchemy\engine\default.py", line 581, in do_execute
    cursor.execute(statement, parameters)
  File "D:\Programs\python37\lib\site-packages\MySQLdb\cursors.py", line 209, in execute
    res = self._query(query)
  File "D:\Programs\python37\lib\site-packages\MySQLdb\cursors.py", line 315, in _query
    db.query(q)
  File "D:\Programs\python37\lib\site-packages\MySQLdb\connections.py", line 231, in query
    _mysql.connection.query(self, query)
sqlalchemy.exc.OperationalError: (MySQLdb._exceptions.OperationalError) (1054, "Unknown column 'monkey_package.test_type' in 'field list'")
[SQL: SELECT monkey_package.id AS monkey_package_id, monkey_package.creation_time AS monkey_package_creation_time, monkey_package.modified_time AS monkey_package_modified_time, monkey_package.name AS monkey_package_name, monkey_package.package_name AS monkey_package_package_name, monkey_package.oss_url AS monkey_package_oss_url, monkey_package.picture AS monkey_package_picture, monkey_package.version AS monkey_package_version, monkey_package.default_activity AS monkey_package_default_activity, monkey_package.user_id AS monkey_package_user_id, monkey_package.status AS monkey_package_status, monkey_package.size AS monkey_package_size, monkey_package.test_type AS monkey_package_test_type, monkey_package.id AS id, monkey_package.name AS name, monkey_package.package_name AS package_name, monkey_package.oss_url AS oss_url, monkey_package.picture AS picture, monkey_package.version AS version, monkey_package.default_activity AS default_activity, monkey_package.user_id AS user_id, monkey_package.status AS status, monkey_package.size AS size, date_format(monkey_package.creation_time, %s) AS upload_time, monkey_package.test_type AS test_type 
FROM monkey_package 
WHERE monkey_package.status = %s AND monkey_package.test_type = %s ORDER BY monkey_package.id DESC 
 LIMIT %s, %s]
[parameters: ('%Y-%m-%d %H:%i:%s', 0, 1, 0, 10)]
(Background on this error at: http://sqlalche.me/e/e3q8)

[2019-11-22 15:16:24,039][37328][autotest][tMiddleware.py 71 ERROR]: 
request  : /v1/monkey/package  GET [handler: 0]
token    : eyJ0eXAiOiJKV1QiLCJhbGciOiJIUzI1NiJ9.eyJ1c2VyaWQiOjExNTIsInVzZXJuYW1lIjoiYWRtaW4iLCJuaWNrbmFtZSI6ImFkbWluIiwicGljdHVyZSI6IiIsInVzZXJ3ZWlnaHQiOjEsInJvbGUiOlt7ImlkIjoxLCJuYW1lIjoiYWRtaW4iLCJjb21tZW50IjoiXHU4ZDg1XHU3ZWE3XHU3YmExXHU3NDA2XHU1NDU4In0seyJpZCI6MywibmFtZSI6InRlc3QiLCJjb21tZW50IjoiXHU2ZDRiXHU4YmQ1In1dLCJwcm9qZWN0aWQiOlsyXSwiZXhwIjoxNTc1MDMzODgxfQ.QRpqtIUc1lcf7boYzrm8XadcMs-APbWJTyX98VMSxTY
projectid: 
query    : {'page_index': '1', 'page_size': '10'}

Traceback (most recent call last):
  File "D:\Programs\python37\lib\site-packages\sqlalchemy\engine\base.py", line 1246, in _execute_context
    cursor, statement, parameters, context
  File "D:\Programs\python37\lib\site-packages\sqlalchemy\engine\default.py", line 581, in do_execute
    cursor.execute(statement, parameters)
  File "D:\Programs\python37\lib\site-packages\MySQLdb\cursors.py", line 209, in execute
    res = self._query(query)
  File "D:\Programs\python37\lib\site-packages\MySQLdb\cursors.py", line 315, in _query
    db.query(q)
  File "D:\Programs\python37\lib\site-packages\MySQLdb\connections.py", line 231, in query
    _mysql.connection.query(self, query)
MySQLdb._exceptions.OperationalError: (1054, "Unknown column 'monkey_package.test_type' in 'field list'")

The above exception was the direct cause of the following exception:

Traceback (most recent call last):
  File "D:\Programs\python37\lib\site-packages\flask\app.py", line 1949, in full_dispatch_request
    rv = self.dispatch_request()
  File "D:\Programs\python37\lib\site-packages\flask\app.py", line 1935, in dispatch_request
    return self.view_functions[rule.endpoint](**req.view_args)
  File "G:\gitworkspace\TcloudServer\apps\autotest\views\monkey.py", line 479, in monkey_package_index_handler
    all, count = MonkeyPackageBusiness.get_monkey_packages_by_user_id(user_id, page_size, page_index, test_type)
  File "G:\gitworkspace\TcloudServer\apps\autotest\business\monkey.py", line 702, in get_monkey_packages_by_user_id
    all = cls.query_all_json(page_size, page_index, test_type)
  File "G:\gitworkspace\TcloudServer\library\api\transfer.py", line 129, in _
    result = func(*args, **kwargs)
  File "G:\gitworkspace\TcloudServer\apps\autotest\business\monkey.py", line 648, in query_all_json
    int(page_index - 1) * int(page_size)).all()
  File "D:\Programs\python37\lib\site-packages\sqlalchemy\orm\query.py", line 3211, in all
    return list(self)
  File "D:\Programs\python37\lib\site-packages\sqlalchemy\orm\query.py", line 3367, in __iter__
    return self._execute_and_instances(context)
  File "D:\Programs\python37\lib\site-packages\sqlalchemy\orm\query.py", line 3392, in _execute_and_instances
    result = conn.execute(querycontext.statement, self._params)
  File "D:\Programs\python37\lib\site-packages\sqlalchemy\engine\base.py", line 982, in execute
    return meth(self, multiparams, params)
  File "D:\Programs\python37\lib\site-packages\sqlalchemy\sql\elements.py", line 287, in _execute_on_connection
    return connection._execute_clauseelement(self, multiparams, params)
  File "D:\Programs\python37\lib\site-packages\sqlalchemy\engine\base.py", line 1101, in _execute_clauseelement
    distilled_params,
  File "D:\Programs\python37\lib\site-packages\sqlalchemy\engine\base.py", line 1250, in _execute_context
    e, statement, parameters, cursor, context
  File "D:\Programs\python37\lib\site-packages\sqlalchemy\engine\base.py", line 1476, in _handle_dbapi_exception
    util.raise_from_cause(sqlalchemy_exception, exc_info)
  File "D:\Programs\python37\lib\site-packages\sqlalchemy\util\compat.py", line 398, in raise_from_cause
    reraise(type(exception), exception, tb=exc_tb, cause=cause)
  File "D:\Programs\python37\lib\site-packages\sqlalchemy\util\compat.py", line 152, in reraise
    raise value.with_traceback(tb)
  File "D:\Programs\python37\lib\site-packages\sqlalchemy\engine\base.py", line 1246, in _execute_context
    cursor, statement, parameters, context
  File "D:\Programs\python37\lib\site-packages\sqlalchemy\engine\default.py", line 581, in do_execute
    cursor.execute(statement, parameters)
  File "D:\Programs\python37\lib\site-packages\MySQLdb\cursors.py", line 209, in execute
    res = self._query(query)
  File "D:\Programs\python37\lib\site-packages\MySQLdb\cursors.py", line 315, in _query
    db.query(q)
  File "D:\Programs\python37\lib\site-packages\MySQLdb\connections.py", line 231, in query
    _mysql.connection.query(self, query)
sqlalchemy.exc.OperationalError: (MySQLdb._exceptions.OperationalError) (1054, "Unknown column 'monkey_package.test_type' in 'field list'")
[SQL: SELECT monkey_package.id AS monkey_package_id, monkey_package.creation_time AS monkey_package_creation_time, monkey_package.modified_time AS monkey_package_modified_time, monkey_package.name AS monkey_package_name, monkey_package.package_name AS monkey_package_package_name, monkey_package.oss_url AS monkey_package_oss_url, monkey_package.picture AS monkey_package_picture, monkey_package.version AS monkey_package_version, monkey_package.default_activity AS monkey_package_default_activity, monkey_package.user_id AS monkey_package_user_id, monkey_package.status AS monkey_package_status, monkey_package.size AS monkey_package_size, monkey_package.test_type AS monkey_package_test_type, monkey_package.id AS id, monkey_package.name AS name, monkey_package.package_name AS package_name, monkey_package.oss_url AS oss_url, monkey_package.picture AS picture, monkey_package.version AS version, monkey_package.default_activity AS default_activity, monkey_package.user_id AS user_id, monkey_package.status AS status, monkey_package.size AS size, date_format(monkey_package.creation_time, %s) AS upload_time, monkey_package.test_type AS test_type 
FROM monkey_package 
WHERE monkey_package.status = %s AND monkey_package.test_type = %s ORDER BY monkey_package.id DESC 
 LIMIT %s, %s]
[parameters: ('%Y-%m-%d %H:%i:%s', 0, 1, 0, 10)]
(Background on this error at: http://sqlalche.me/e/e3q8)

[2019-11-22 15:16:24,044][37328][autotest][tMiddleware.py 71 ERROR]: 
request  : /v1/monkey/package  GET [handler: 0]
token    : eyJ0eXAiOiJKV1QiLCJhbGciOiJIUzI1NiJ9.eyJ1c2VyaWQiOjExNTIsInVzZXJuYW1lIjoiYWRtaW4iLCJuaWNrbmFtZSI6ImFkbWluIiwicGljdHVyZSI6IiIsInVzZXJ3ZWlnaHQiOjEsInJvbGUiOlt7ImlkIjoxLCJuYW1lIjoiYWRtaW4iLCJjb21tZW50IjoiXHU4ZDg1XHU3ZWE3XHU3YmExXHU3NDA2XHU1NDU4In0seyJpZCI6MywibmFtZSI6InRlc3QiLCJjb21tZW50IjoiXHU2ZDRiXHU4YmQ1In1dLCJwcm9qZWN0aWQiOlsyXSwiZXhwIjoxNTc1MDMzODgxfQ.QRpqtIUc1lcf7boYzrm8XadcMs-APbWJTyX98VMSxTY
projectid: 
query    : {'page_index': '1', 'page_size': '10', 'user_id': '1152'}

Traceback (most recent call last):
  File "D:\Programs\python37\lib\site-packages\sqlalchemy\engine\base.py", line 1246, in _execute_context
    cursor, statement, parameters, context
  File "D:\Programs\python37\lib\site-packages\sqlalchemy\engine\default.py", line 581, in do_execute
    cursor.execute(statement, parameters)
  File "D:\Programs\python37\lib\site-packages\MySQLdb\cursors.py", line 209, in execute
    res = self._query(query)
  File "D:\Programs\python37\lib\site-packages\MySQLdb\cursors.py", line 315, in _query
    db.query(q)
  File "D:\Programs\python37\lib\site-packages\MySQLdb\connections.py", line 231, in query
    _mysql.connection.query(self, query)
MySQLdb._exceptions.OperationalError: (1054, "Unknown column 'monkey_package.test_type' in 'field list'")

The above exception was the direct cause of the following exception:

Traceback (most recent call last):
  File "D:\Programs\python37\lib\site-packages\flask\app.py", line 1949, in full_dispatch_request
    rv = self.dispatch_request()
  File "D:\Programs\python37\lib\site-packages\flask\app.py", line 1935, in dispatch_request
    return self.view_functions[rule.endpoint](**req.view_args)
  File "G:\gitworkspace\TcloudServer\apps\autotest\views\monkey.py", line 479, in monkey_package_index_handler
    all, count = MonkeyPackageBusiness.get_monkey_packages_by_user_id(user_id, page_size, page_index, test_type)
  File "G:\gitworkspace\TcloudServer\apps\autotest\business\monkey.py", line 699, in get_monkey_packages_by_user_id
    all = cls.query_json_by_user_id(user_id, page_size, page_index, test_type)
  File "G:\gitworkspace\TcloudServer\library\api\transfer.py", line 129, in _
    result = func(*args, **kwargs)
  File "G:\gitworkspace\TcloudServer\apps\autotest\business\monkey.py", line 686, in query_json_by_user_id
    order_by(desc(MonkeyPackage.id)).limit(int(page_size)).offset(int(page_index - 1) * int(page_size)).all()
  File "D:\Programs\python37\lib\site-packages\sqlalchemy\orm\query.py", line 3211, in all
    return list(self)
  File "D:\Programs\python37\lib\site-packages\sqlalchemy\orm\query.py", line 3367, in __iter__
    return self._execute_and_instances(context)
  File "D:\Programs\python37\lib\site-packages\sqlalchemy\orm\query.py", line 3392, in _execute_and_instances
    result = conn.execute(querycontext.statement, self._params)
  File "D:\Programs\python37\lib\site-packages\sqlalchemy\engine\base.py", line 982, in execute
    return meth(self, multiparams, params)
  File "D:\Programs\python37\lib\site-packages\sqlalchemy\sql\elements.py", line 287, in _execute_on_connection
    return connection._execute_clauseelement(self, multiparams, params)
  File "D:\Programs\python37\lib\site-packages\sqlalchemy\engine\base.py", line 1101, in _execute_clauseelement
    distilled_params,
  File "D:\Programs\python37\lib\site-packages\sqlalchemy\engine\base.py", line 1250, in _execute_context
    e, statement, parameters, cursor, context
  File "D:\Programs\python37\lib\site-packages\sqlalchemy\engine\base.py", line 1476, in _handle_dbapi_exception
    util.raise_from_cause(sqlalchemy_exception, exc_info)
  File "D:\Programs\python37\lib\site-packages\sqlalchemy\util\compat.py", line 398, in raise_from_cause
    reraise(type(exception), exception, tb=exc_tb, cause=cause)
  File "D:\Programs\python37\lib\site-packages\sqlalchemy\util\compat.py", line 152, in reraise
    raise value.with_traceback(tb)
  File "D:\Programs\python37\lib\site-packages\sqlalchemy\engine\base.py", line 1246, in _execute_context
    cursor, statement, parameters, context
  File "D:\Programs\python37\lib\site-packages\sqlalchemy\engine\default.py", line 581, in do_execute
    cursor.execute(statement, parameters)
  File "D:\Programs\python37\lib\site-packages\MySQLdb\cursors.py", line 209, in execute
    res = self._query(query)
  File "D:\Programs\python37\lib\site-packages\MySQLdb\cursors.py", line 315, in _query
    db.query(q)
  File "D:\Programs\python37\lib\site-packages\MySQLdb\connections.py", line 231, in query
    _mysql.connection.query(self, query)
sqlalchemy.exc.OperationalError: (MySQLdb._exceptions.OperationalError) (1054, "Unknown column 'monkey_package.test_type' in 'field list'")
[SQL: SELECT monkey_package.id AS monkey_package_id, monkey_package.creation_time AS monkey_package_creation_time, monkey_package.modified_time AS monkey_package_modified_time, monkey_package.name AS monkey_package_name, monkey_package.package_name AS monkey_package_package_name, monkey_package.oss_url AS monkey_package_oss_url, monkey_package.picture AS monkey_package_picture, monkey_package.version AS monkey_package_version, monkey_package.default_activity AS monkey_package_default_activity, monkey_package.user_id AS monkey_package_user_id, monkey_package.status AS monkey_package_status, monkey_package.size AS monkey_package_size, monkey_package.test_type AS monkey_package_test_type, monkey_package.id AS id, monkey_package.name AS name, monkey_package.package_name AS package_name, monkey_package.oss_url AS oss_url, monkey_package.picture AS picture, monkey_package.version AS version, monkey_package.default_activity AS default_activity, monkey_package.user_id AS user_id, monkey_package.status AS status, monkey_package.size AS size, date_format(monkey_package.creation_time, %s) AS upload_time, monkey_package.test_type AS test_type 
FROM monkey_package 
WHERE monkey_package.status = %s AND monkey_package.test_type = %s AND monkey_package.user_id = %s ORDER BY monkey_package.id DESC 
 LIMIT %s, %s]
[parameters: ('%Y-%m-%d %H:%i:%s', 0, 1, '1152', 0, 10)]
(Background on this error at: http://sqlalche.me/e/e3q8)

[2019-11-22 15:30:03,249][37328][autotest][tMiddleware.py 71 ERROR]: 
request  : /v1/monkey/package  GET [handler: 0]
token    : eyJ0eXAiOiJKV1QiLCJhbGciOiJIUzI1NiJ9.eyJ1c2VyaWQiOjExNTIsInVzZXJuYW1lIjoiYWRtaW4iLCJuaWNrbmFtZSI6ImFkbWluIiwicGljdHVyZSI6IiIsInVzZXJ3ZWlnaHQiOjEsInJvbGUiOlt7ImlkIjoxLCJuYW1lIjoiYWRtaW4iLCJjb21tZW50IjoiXHU4ZDg1XHU3ZWE3XHU3YmExXHU3NDA2XHU1NDU4In0seyJpZCI6MywibmFtZSI6InRlc3QiLCJjb21tZW50IjoiXHU2ZDRiXHU4YmQ1In1dLCJwcm9qZWN0aWQiOlsyXSwiZXhwIjoxNTc1MDMzODgxfQ.QRpqtIUc1lcf7boYzrm8XadcMs-APbWJTyX98VMSxTY
projectid: 
query    : {'page_index': '1', 'page_size': '10', 'user_id': '1152'}

Traceback (most recent call last):
  File "D:\Programs\python37\lib\site-packages\sqlalchemy\engine\base.py", line 1246, in _execute_context
    cursor, statement, parameters, context
  File "D:\Programs\python37\lib\site-packages\sqlalchemy\engine\default.py", line 581, in do_execute
    cursor.execute(statement, parameters)
  File "D:\Programs\python37\lib\site-packages\MySQLdb\cursors.py", line 209, in execute
    res = self._query(query)
  File "D:\Programs\python37\lib\site-packages\MySQLdb\cursors.py", line 315, in _query
    db.query(q)
  File "D:\Programs\python37\lib\site-packages\MySQLdb\connections.py", line 231, in query
    _mysql.connection.query(self, query)
MySQLdb._exceptions.OperationalError: (1054, "Unknown column 'monkey_package.test_type' in 'field list'")

The above exception was the direct cause of the following exception:

Traceback (most recent call last):
  File "D:\Programs\python37\lib\site-packages\flask\app.py", line 1949, in full_dispatch_request
    rv = self.dispatch_request()
  File "D:\Programs\python37\lib\site-packages\flask\app.py", line 1935, in dispatch_request
    return self.view_functions[rule.endpoint](**req.view_args)
  File "G:\gitworkspace\TcloudServer\apps\autotest\views\monkey.py", line 479, in monkey_package_index_handler
    all, count = MonkeyPackageBusiness.get_monkey_packages_by_user_id(user_id, page_size, page_index, test_type)
  File "G:\gitworkspace\TcloudServer\apps\autotest\business\monkey.py", line 699, in get_monkey_packages_by_user_id
    all = cls.query_json_by_user_id(user_id, page_size, page_index, test_type)
  File "G:\gitworkspace\TcloudServer\library\api\transfer.py", line 129, in _
    result = func(*args, **kwargs)
  File "G:\gitworkspace\TcloudServer\apps\autotest\business\monkey.py", line 686, in query_json_by_user_id
    order_by(desc(MonkeyPackage.id)).limit(int(page_size)).offset(int(page_index - 1) * int(page_size)).all()
  File "D:\Programs\python37\lib\site-packages\sqlalchemy\orm\query.py", line 3211, in all
    return list(self)
  File "D:\Programs\python37\lib\site-packages\sqlalchemy\orm\query.py", line 3367, in __iter__
    return self._execute_and_instances(context)
  File "D:\Programs\python37\lib\site-packages\sqlalchemy\orm\query.py", line 3392, in _execute_and_instances
    result = conn.execute(querycontext.statement, self._params)
  File "D:\Programs\python37\lib\site-packages\sqlalchemy\engine\base.py", line 982, in execute
    return meth(self, multiparams, params)
  File "D:\Programs\python37\lib\site-packages\sqlalchemy\sql\elements.py", line 287, in _execute_on_connection
    return connection._execute_clauseelement(self, multiparams, params)
  File "D:\Programs\python37\lib\site-packages\sqlalchemy\engine\base.py", line 1101, in _execute_clauseelement
    distilled_params,
  File "D:\Programs\python37\lib\site-packages\sqlalchemy\engine\base.py", line 1250, in _execute_context
    e, statement, parameters, cursor, context
  File "D:\Programs\python37\lib\site-packages\sqlalchemy\engine\base.py", line 1476, in _handle_dbapi_exception
    util.raise_from_cause(sqlalchemy_exception, exc_info)
  File "D:\Programs\python37\lib\site-packages\sqlalchemy\util\compat.py", line 398, in raise_from_cause
    reraise(type(exception), exception, tb=exc_tb, cause=cause)
  File "D:\Programs\python37\lib\site-packages\sqlalchemy\util\compat.py", line 152, in reraise
    raise value.with_traceback(tb)
  File "D:\Programs\python37\lib\site-packages\sqlalchemy\engine\base.py", line 1246, in _execute_context
    cursor, statement, parameters, context
  File "D:\Programs\python37\lib\site-packages\sqlalchemy\engine\default.py", line 581, in do_execute
    cursor.execute(statement, parameters)
  File "D:\Programs\python37\lib\site-packages\MySQLdb\cursors.py", line 209, in execute
    res = self._query(query)
  File "D:\Programs\python37\lib\site-packages\MySQLdb\cursors.py", line 315, in _query
    db.query(q)
  File "D:\Programs\python37\lib\site-packages\MySQLdb\connections.py", line 231, in query
    _mysql.connection.query(self, query)
sqlalchemy.exc.OperationalError: (MySQLdb._exceptions.OperationalError) (1054, "Unknown column 'monkey_package.test_type' in 'field list'")
[SQL: SELECT monkey_package.id AS monkey_package_id, monkey_package.creation_time AS monkey_package_creation_time, monkey_package.modified_time AS monkey_package_modified_time, monkey_package.name AS monkey_package_name, monkey_package.package_name AS monkey_package_package_name, monkey_package.oss_url AS monkey_package_oss_url, monkey_package.picture AS monkey_package_picture, monkey_package.version AS monkey_package_version, monkey_package.default_activity AS monkey_package_default_activity, monkey_package.user_id AS monkey_package_user_id, monkey_package.status AS monkey_package_status, monkey_package.size AS monkey_package_size, monkey_package.test_type AS monkey_package_test_type, monkey_package.id AS id, monkey_package.name AS name, monkey_package.package_name AS package_name, monkey_package.oss_url AS oss_url, monkey_package.picture AS picture, monkey_package.version AS version, monkey_package.default_activity AS default_activity, monkey_package.user_id AS user_id, monkey_package.status AS status, monkey_package.size AS size, date_format(monkey_package.creation_time, %s) AS upload_time, monkey_package.test_type AS test_type 
FROM monkey_package 
WHERE monkey_package.status = %s AND monkey_package.test_type = %s AND monkey_package.user_id = %s ORDER BY monkey_package.id DESC 
 LIMIT %s, %s]
[parameters: ('%Y-%m-%d %H:%i:%s', 0, 1, '1152', 0, 10)]
(Background on this error at: http://sqlalche.me/e/e3q8)

[2019-11-22 15:30:03,291][37328][autotest][tMiddleware.py 71 ERROR]: 
request  : /v1/monkey/package  GET [handler: 0]
token    : eyJ0eXAiOiJKV1QiLCJhbGciOiJIUzI1NiJ9.eyJ1c2VyaWQiOjExNTIsInVzZXJuYW1lIjoiYWRtaW4iLCJuaWNrbmFtZSI6ImFkbWluIiwicGljdHVyZSI6IiIsInVzZXJ3ZWlnaHQiOjEsInJvbGUiOlt7ImlkIjoxLCJuYW1lIjoiYWRtaW4iLCJjb21tZW50IjoiXHU4ZDg1XHU3ZWE3XHU3YmExXHU3NDA2XHU1NDU4In0seyJpZCI6MywibmFtZSI6InRlc3QiLCJjb21tZW50IjoiXHU2ZDRiXHU4YmQ1In1dLCJwcm9qZWN0aWQiOlsyXSwiZXhwIjoxNTc1MDMzODgxfQ.QRpqtIUc1lcf7boYzrm8XadcMs-APbWJTyX98VMSxTY
projectid: 
query    : {'page_index': '1', 'page_size': '10'}

Traceback (most recent call last):
  File "D:\Programs\python37\lib\site-packages\sqlalchemy\engine\base.py", line 1246, in _execute_context
    cursor, statement, parameters, context
  File "D:\Programs\python37\lib\site-packages\sqlalchemy\engine\default.py", line 581, in do_execute
    cursor.execute(statement, parameters)
  File "D:\Programs\python37\lib\site-packages\MySQLdb\cursors.py", line 209, in execute
    res = self._query(query)
  File "D:\Programs\python37\lib\site-packages\MySQLdb\cursors.py", line 315, in _query
    db.query(q)
  File "D:\Programs\python37\lib\site-packages\MySQLdb\connections.py", line 231, in query
    _mysql.connection.query(self, query)
MySQLdb._exceptions.OperationalError: (1054, "Unknown column 'monkey_package.test_type' in 'field list'")

The above exception was the direct cause of the following exception:

Traceback (most recent call last):
  File "D:\Programs\python37\lib\site-packages\flask\app.py", line 1949, in full_dispatch_request
    rv = self.dispatch_request()
  File "D:\Programs\python37\lib\site-packages\flask\app.py", line 1935, in dispatch_request
    return self.view_functions[rule.endpoint](**req.view_args)
  File "G:\gitworkspace\TcloudServer\apps\autotest\views\monkey.py", line 479, in monkey_package_index_handler
    all, count = MonkeyPackageBusiness.get_monkey_packages_by_user_id(user_id, page_size, page_index, test_type)
  File "G:\gitworkspace\TcloudServer\apps\autotest\business\monkey.py", line 702, in get_monkey_packages_by_user_id
    all = cls.query_all_json(page_size, page_index, test_type)
  File "G:\gitworkspace\TcloudServer\library\api\transfer.py", line 129, in _
    result = func(*args, **kwargs)
  File "G:\gitworkspace\TcloudServer\apps\autotest\business\monkey.py", line 648, in query_all_json
    int(page_index - 1) * int(page_size)).all()
  File "D:\Programs\python37\lib\site-packages\sqlalchemy\orm\query.py", line 3211, in all
    return list(self)
  File "D:\Programs\python37\lib\site-packages\sqlalchemy\orm\query.py", line 3367, in __iter__
    return self._execute_and_instances(context)
  File "D:\Programs\python37\lib\site-packages\sqlalchemy\orm\query.py", line 3392, in _execute_and_instances
    result = conn.execute(querycontext.statement, self._params)
  File "D:\Programs\python37\lib\site-packages\sqlalchemy\engine\base.py", line 982, in execute
    return meth(self, multiparams, params)
  File "D:\Programs\python37\lib\site-packages\sqlalchemy\sql\elements.py", line 287, in _execute_on_connection
    return connection._execute_clauseelement(self, multiparams, params)
  File "D:\Programs\python37\lib\site-packages\sqlalchemy\engine\base.py", line 1101, in _execute_clauseelement
    distilled_params,
  File "D:\Programs\python37\lib\site-packages\sqlalchemy\engine\base.py", line 1250, in _execute_context
    e, statement, parameters, cursor, context
  File "D:\Programs\python37\lib\site-packages\sqlalchemy\engine\base.py", line 1476, in _handle_dbapi_exception
    util.raise_from_cause(sqlalchemy_exception, exc_info)
  File "D:\Programs\python37\lib\site-packages\sqlalchemy\util\compat.py", line 398, in raise_from_cause
    reraise(type(exception), exception, tb=exc_tb, cause=cause)
  File "D:\Programs\python37\lib\site-packages\sqlalchemy\util\compat.py", line 152, in reraise
    raise value.with_traceback(tb)
  File "D:\Programs\python37\lib\site-packages\sqlalchemy\engine\base.py", line 1246, in _execute_context
    cursor, statement, parameters, context
  File "D:\Programs\python37\lib\site-packages\sqlalchemy\engine\default.py", line 581, in do_execute
    cursor.execute(statement, parameters)
  File "D:\Programs\python37\lib\site-packages\MySQLdb\cursors.py", line 209, in execute
    res = self._query(query)
  File "D:\Programs\python37\lib\site-packages\MySQLdb\cursors.py", line 315, in _query
    db.query(q)
  File "D:\Programs\python37\lib\site-packages\MySQLdb\connections.py", line 231, in query
    _mysql.connection.query(self, query)
sqlalchemy.exc.OperationalError: (MySQLdb._exceptions.OperationalError) (1054, "Unknown column 'monkey_package.test_type' in 'field list'")
[SQL: SELECT monkey_package.id AS monkey_package_id, monkey_package.creation_time AS monkey_package_creation_time, monkey_package.modified_time AS monkey_package_modified_time, monkey_package.name AS monkey_package_name, monkey_package.package_name AS monkey_package_package_name, monkey_package.oss_url AS monkey_package_oss_url, monkey_package.picture AS monkey_package_picture, monkey_package.version AS monkey_package_version, monkey_package.default_activity AS monkey_package_default_activity, monkey_package.user_id AS monkey_package_user_id, monkey_package.status AS monkey_package_status, monkey_package.size AS monkey_package_size, monkey_package.test_type AS monkey_package_test_type, monkey_package.id AS id, monkey_package.name AS name, monkey_package.package_name AS package_name, monkey_package.oss_url AS oss_url, monkey_package.picture AS picture, monkey_package.version AS version, monkey_package.default_activity AS default_activity, monkey_package.user_id AS user_id, monkey_package.status AS status, monkey_package.size AS size, date_format(monkey_package.creation_time, %s) AS upload_time, monkey_package.test_type AS test_type 
FROM monkey_package 
WHERE monkey_package.status = %s AND monkey_package.test_type = %s ORDER BY monkey_package.id DESC 
 LIMIT %s, %s]
[parameters: ('%Y-%m-%d %H:%i:%s', 0, 1, 0, 10)]
(Background on this error at: http://sqlalche.me/e/e3q8)

[2019-11-22 15:33:52,324][37328][autotest][tMiddleware.py 71 ERROR]: 
request  : /v1/monkey/package  GET [handler: 0]
token    : eyJ0eXAiOiJKV1QiLCJhbGciOiJIUzI1NiJ9.eyJ1c2VyaWQiOjExNTIsInVzZXJuYW1lIjoiYWRtaW4iLCJuaWNrbmFtZSI6ImFkbWluIiwicGljdHVyZSI6IiIsInVzZXJ3ZWlnaHQiOjEsInJvbGUiOlt7ImlkIjoxLCJuYW1lIjoiYWRtaW4iLCJjb21tZW50IjoiXHU4ZDg1XHU3ZWE3XHU3YmExXHU3NDA2XHU1NDU4In0seyJpZCI6MywibmFtZSI6InRlc3QiLCJjb21tZW50IjoiXHU2ZDRiXHU4YmQ1In1dLCJwcm9qZWN0aWQiOlsyXSwiZXhwIjoxNTc1MDMzODgxfQ.QRpqtIUc1lcf7boYzrm8XadcMs-APbWJTyX98VMSxTY
projectid: 
query    : {'page_index': '1', 'page_size': '10'}

Traceback (most recent call last):
  File "D:\Programs\python37\lib\site-packages\sqlalchemy\engine\base.py", line 1246, in _execute_context
    cursor, statement, parameters, context
  File "D:\Programs\python37\lib\site-packages\sqlalchemy\engine\default.py", line 581, in do_execute
    cursor.execute(statement, parameters)
  File "D:\Programs\python37\lib\site-packages\MySQLdb\cursors.py", line 209, in execute
    res = self._query(query)
  File "D:\Programs\python37\lib\site-packages\MySQLdb\cursors.py", line 315, in _query
    db.query(q)
  File "D:\Programs\python37\lib\site-packages\MySQLdb\connections.py", line 231, in query
    _mysql.connection.query(self, query)
MySQLdb._exceptions.OperationalError: (1054, "Unknown column 'monkey_package.test_type' in 'field list'")

The above exception was the direct cause of the following exception:

Traceback (most recent call last):
  File "D:\Programs\python37\lib\site-packages\flask\app.py", line 1949, in full_dispatch_request
    rv = self.dispatch_request()
  File "D:\Programs\python37\lib\site-packages\flask\app.py", line 1935, in dispatch_request
    return self.view_functions[rule.endpoint](**req.view_args)
  File "G:\gitworkspace\TcloudServer\apps\autotest\views\monkey.py", line 479, in monkey_package_index_handler
    all, count = MonkeyPackageBusiness.get_monkey_packages_by_user_id(user_id, page_size, page_index, test_type)
  File "G:\gitworkspace\TcloudServer\apps\autotest\business\monkey.py", line 702, in get_monkey_packages_by_user_id
    all = cls.query_all_json(page_size, page_index, test_type)
  File "G:\gitworkspace\TcloudServer\library\api\transfer.py", line 129, in _
    result = func(*args, **kwargs)
  File "G:\gitworkspace\TcloudServer\apps\autotest\business\monkey.py", line 648, in query_all_json
    int(page_index - 1) * int(page_size)).all()
  File "D:\Programs\python37\lib\site-packages\sqlalchemy\orm\query.py", line 3211, in all
    return list(self)
  File "D:\Programs\python37\lib\site-packages\sqlalchemy\orm\query.py", line 3367, in __iter__
    return self._execute_and_instances(context)
  File "D:\Programs\python37\lib\site-packages\sqlalchemy\orm\query.py", line 3392, in _execute_and_instances
    result = conn.execute(querycontext.statement, self._params)
  File "D:\Programs\python37\lib\site-packages\sqlalchemy\engine\base.py", line 982, in execute
    return meth(self, multiparams, params)
  File "D:\Programs\python37\lib\site-packages\sqlalchemy\sql\elements.py", line 287, in _execute_on_connection
    return connection._execute_clauseelement(self, multiparams, params)
  File "D:\Programs\python37\lib\site-packages\sqlalchemy\engine\base.py", line 1101, in _execute_clauseelement
    distilled_params,
  File "D:\Programs\python37\lib\site-packages\sqlalchemy\engine\base.py", line 1250, in _execute_context
    e, statement, parameters, cursor, context
  File "D:\Programs\python37\lib\site-packages\sqlalchemy\engine\base.py", line 1476, in _handle_dbapi_exception
    util.raise_from_cause(sqlalchemy_exception, exc_info)
  File "D:\Programs\python37\lib\site-packages\sqlalchemy\util\compat.py", line 398, in raise_from_cause
    reraise(type(exception), exception, tb=exc_tb, cause=cause)
  File "D:\Programs\python37\lib\site-packages\sqlalchemy\util\compat.py", line 152, in reraise
    raise value.with_traceback(tb)
  File "D:\Programs\python37\lib\site-packages\sqlalchemy\engine\base.py", line 1246, in _execute_context
    cursor, statement, parameters, context
  File "D:\Programs\python37\lib\site-packages\sqlalchemy\engine\default.py", line 581, in do_execute
    cursor.execute(statement, parameters)
  File "D:\Programs\python37\lib\site-packages\MySQLdb\cursors.py", line 209, in execute
    res = self._query(query)
  File "D:\Programs\python37\lib\site-packages\MySQLdb\cursors.py", line 315, in _query
    db.query(q)
  File "D:\Programs\python37\lib\site-packages\MySQLdb\connections.py", line 231, in query
    _mysql.connection.query(self, query)
sqlalchemy.exc.OperationalError: (MySQLdb._exceptions.OperationalError) (1054, "Unknown column 'monkey_package.test_type' in 'field list'")
[SQL: SELECT monkey_package.id AS monkey_package_id, monkey_package.creation_time AS monkey_package_creation_time, monkey_package.modified_time AS monkey_package_modified_time, monkey_package.name AS monkey_package_name, monkey_package.package_name AS monkey_package_package_name, monkey_package.oss_url AS monkey_package_oss_url, monkey_package.picture AS monkey_package_picture, monkey_package.version AS monkey_package_version, monkey_package.default_activity AS monkey_package_default_activity, monkey_package.user_id AS monkey_package_user_id, monkey_package.status AS monkey_package_status, monkey_package.size AS monkey_package_size, monkey_package.test_type AS monkey_package_test_type, monkey_package.id AS id, monkey_package.name AS name, monkey_package.package_name AS package_name, monkey_package.oss_url AS oss_url, monkey_package.picture AS picture, monkey_package.version AS version, monkey_package.default_activity AS default_activity, monkey_package.user_id AS user_id, monkey_package.status AS status, monkey_package.size AS size, date_format(monkey_package.creation_time, %s) AS upload_time, monkey_package.test_type AS test_type 
FROM monkey_package 
WHERE monkey_package.status = %s AND monkey_package.test_type = %s ORDER BY monkey_package.id DESC 
 LIMIT %s, %s]
[parameters: ('%Y-%m-%d %H:%i:%s', 0, 1, 0, 10)]
(Background on this error at: http://sqlalche.me/e/e3q8)

[2019-11-22 15:33:52,417][37328][autotest][tMiddleware.py 71 ERROR]: 
request  : /v1/monkey/package  GET [handler: 0]
token    : eyJ0eXAiOiJKV1QiLCJhbGciOiJIUzI1NiJ9.eyJ1c2VyaWQiOjExNTIsInVzZXJuYW1lIjoiYWRtaW4iLCJuaWNrbmFtZSI6ImFkbWluIiwicGljdHVyZSI6IiIsInVzZXJ3ZWlnaHQiOjEsInJvbGUiOlt7ImlkIjoxLCJuYW1lIjoiYWRtaW4iLCJjb21tZW50IjoiXHU4ZDg1XHU3ZWE3XHU3YmExXHU3NDA2XHU1NDU4In0seyJpZCI6MywibmFtZSI6InRlc3QiLCJjb21tZW50IjoiXHU2ZDRiXHU4YmQ1In1dLCJwcm9qZWN0aWQiOlsyXSwiZXhwIjoxNTc1MDMzODgxfQ.QRpqtIUc1lcf7boYzrm8XadcMs-APbWJTyX98VMSxTY
projectid: 
query    : {'page_index': '1', 'page_size': '10', 'user_id': '1152'}

Traceback (most recent call last):
  File "D:\Programs\python37\lib\site-packages\sqlalchemy\engine\base.py", line 1246, in _execute_context
    cursor, statement, parameters, context
  File "D:\Programs\python37\lib\site-packages\sqlalchemy\engine\default.py", line 581, in do_execute
    cursor.execute(statement, parameters)
  File "D:\Programs\python37\lib\site-packages\MySQLdb\cursors.py", line 209, in execute
    res = self._query(query)
  File "D:\Programs\python37\lib\site-packages\MySQLdb\cursors.py", line 315, in _query
    db.query(q)
  File "D:\Programs\python37\lib\site-packages\MySQLdb\connections.py", line 231, in query
    _mysql.connection.query(self, query)
MySQLdb._exceptions.OperationalError: (1054, "Unknown column 'monkey_package.test_type' in 'field list'")

The above exception was the direct cause of the following exception:

Traceback (most recent call last):
  File "D:\Programs\python37\lib\site-packages\flask\app.py", line 1949, in full_dispatch_request
    rv = self.dispatch_request()
  File "D:\Programs\python37\lib\site-packages\flask\app.py", line 1935, in dispatch_request
    return self.view_functions[rule.endpoint](**req.view_args)
  File "G:\gitworkspace\TcloudServer\apps\autotest\views\monkey.py", line 479, in monkey_package_index_handler
    all, count = MonkeyPackageBusiness.get_monkey_packages_by_user_id(user_id, page_size, page_index, test_type)
  File "G:\gitworkspace\TcloudServer\apps\autotest\business\monkey.py", line 699, in get_monkey_packages_by_user_id
    all = cls.query_json_by_user_id(user_id, page_size, page_index, test_type)
  File "G:\gitworkspace\TcloudServer\library\api\transfer.py", line 129, in _
    result = func(*args, **kwargs)
  File "G:\gitworkspace\TcloudServer\apps\autotest\business\monkey.py", line 686, in query_json_by_user_id
    order_by(desc(MonkeyPackage.id)).limit(int(page_size)).offset(int(page_index - 1) * int(page_size)).all()
  File "D:\Programs\python37\lib\site-packages\sqlalchemy\orm\query.py", line 3211, in all
    return list(self)
  File "D:\Programs\python37\lib\site-packages\sqlalchemy\orm\query.py", line 3367, in __iter__
    return self._execute_and_instances(context)
  File "D:\Programs\python37\lib\site-packages\sqlalchemy\orm\query.py", line 3392, in _execute_and_instances
    result = conn.execute(querycontext.statement, self._params)
  File "D:\Programs\python37\lib\site-packages\sqlalchemy\engine\base.py", line 982, in execute
    return meth(self, multiparams, params)
  File "D:\Programs\python37\lib\site-packages\sqlalchemy\sql\elements.py", line 287, in _execute_on_connection
    return connection._execute_clauseelement(self, multiparams, params)
  File "D:\Programs\python37\lib\site-packages\sqlalchemy\engine\base.py", line 1101, in _execute_clauseelement
    distilled_params,
  File "D:\Programs\python37\lib\site-packages\sqlalchemy\engine\base.py", line 1250, in _execute_context
    e, statement, parameters, cursor, context
  File "D:\Programs\python37\lib\site-packages\sqlalchemy\engine\base.py", line 1476, in _handle_dbapi_exception
    util.raise_from_cause(sqlalchemy_exception, exc_info)
  File "D:\Programs\python37\lib\site-packages\sqlalchemy\util\compat.py", line 398, in raise_from_cause
    reraise(type(exception), exception, tb=exc_tb, cause=cause)
  File "D:\Programs\python37\lib\site-packages\sqlalchemy\util\compat.py", line 152, in reraise
    raise value.with_traceback(tb)
  File "D:\Programs\python37\lib\site-packages\sqlalchemy\engine\base.py", line 1246, in _execute_context
    cursor, statement, parameters, context
  File "D:\Programs\python37\lib\site-packages\sqlalchemy\engine\default.py", line 581, in do_execute
    cursor.execute(statement, parameters)
  File "D:\Programs\python37\lib\site-packages\MySQLdb\cursors.py", line 209, in execute
    res = self._query(query)
  File "D:\Programs\python37\lib\site-packages\MySQLdb\cursors.py", line 315, in _query
    db.query(q)
  File "D:\Programs\python37\lib\site-packages\MySQLdb\connections.py", line 231, in query
    _mysql.connection.query(self, query)
sqlalchemy.exc.OperationalError: (MySQLdb._exceptions.OperationalError) (1054, "Unknown column 'monkey_package.test_type' in 'field list'")
[SQL: SELECT monkey_package.id AS monkey_package_id, monkey_package.creation_time AS monkey_package_creation_time, monkey_package.modified_time AS monkey_package_modified_time, monkey_package.name AS monkey_package_name, monkey_package.package_name AS monkey_package_package_name, monkey_package.oss_url AS monkey_package_oss_url, monkey_package.picture AS monkey_package_picture, monkey_package.version AS monkey_package_version, monkey_package.default_activity AS monkey_package_default_activity, monkey_package.user_id AS monkey_package_user_id, monkey_package.status AS monkey_package_status, monkey_package.size AS monkey_package_size, monkey_package.test_type AS monkey_package_test_type, monkey_package.id AS id, monkey_package.name AS name, monkey_package.package_name AS package_name, monkey_package.oss_url AS oss_url, monkey_package.picture AS picture, monkey_package.version AS version, monkey_package.default_activity AS default_activity, monkey_package.user_id AS user_id, monkey_package.status AS status, monkey_package.size AS size, date_format(monkey_package.creation_time, %s) AS upload_time, monkey_package.test_type AS test_type 
FROM monkey_package 
WHERE monkey_package.status = %s AND monkey_package.test_type = %s AND monkey_package.user_id = %s ORDER BY monkey_package.id DESC 
 LIMIT %s, %s]
[parameters: ('%Y-%m-%d %H:%i:%s', 0, 1, '1152', 0, 10)]
(Background on this error at: http://sqlalche.me/e/e3q8)

[2019-11-22 15:34:12,078][37328][autotest][tMiddleware.py 71 ERROR]: 
request  : /v1/monkey/package  GET [handler: 0]
token    : eyJ0eXAiOiJKV1QiLCJhbGciOiJIUzI1NiJ9.eyJ1c2VyaWQiOjExNTIsInVzZXJuYW1lIjoiYWRtaW4iLCJuaWNrbmFtZSI6ImFkbWluIiwicGljdHVyZSI6IiIsInVzZXJ3ZWlnaHQiOjEsInJvbGUiOlt7ImlkIjoxLCJuYW1lIjoiYWRtaW4iLCJjb21tZW50IjoiXHU4ZDg1XHU3ZWE3XHU3YmExXHU3NDA2XHU1NDU4In0seyJpZCI6MywibmFtZSI6InRlc3QiLCJjb21tZW50IjoiXHU2ZDRiXHU4YmQ1In1dLCJwcm9qZWN0aWQiOlsyXSwiZXhwIjoxNTc1MDQxNjQ3fQ.tAFuzTB-HuzpeE7KZvbgddc_JCL8RXP1d08tfhoOmnY
projectid: 
query    : {'page_index': '1', 'page_size': '10'}

Traceback (most recent call last):
  File "D:\Programs\python37\lib\site-packages\sqlalchemy\engine\base.py", line 1246, in _execute_context
    cursor, statement, parameters, context
  File "D:\Programs\python37\lib\site-packages\sqlalchemy\engine\default.py", line 581, in do_execute
    cursor.execute(statement, parameters)
  File "D:\Programs\python37\lib\site-packages\MySQLdb\cursors.py", line 209, in execute
    res = self._query(query)
  File "D:\Programs\python37\lib\site-packages\MySQLdb\cursors.py", line 315, in _query
    db.query(q)
  File "D:\Programs\python37\lib\site-packages\MySQLdb\connections.py", line 231, in query
    _mysql.connection.query(self, query)
MySQLdb._exceptions.OperationalError: (1054, "Unknown column 'monkey_package.test_type' in 'field list'")

The above exception was the direct cause of the following exception:

Traceback (most recent call last):
  File "D:\Programs\python37\lib\site-packages\flask\app.py", line 1949, in full_dispatch_request
    rv = self.dispatch_request()
  File "D:\Programs\python37\lib\site-packages\flask\app.py", line 1935, in dispatch_request
    return self.view_functions[rule.endpoint](**req.view_args)
  File "G:\gitworkspace\TcloudServer\apps\autotest\views\monkey.py", line 479, in monkey_package_index_handler
    all, count = MonkeyPackageBusiness.get_monkey_packages_by_user_id(user_id, page_size, page_index, test_type)
  File "G:\gitworkspace\TcloudServer\apps\autotest\business\monkey.py", line 702, in get_monkey_packages_by_user_id
    all = cls.query_all_json(page_size, page_index, test_type)
  File "G:\gitworkspace\TcloudServer\library\api\transfer.py", line 129, in _
    result = func(*args, **kwargs)
  File "G:\gitworkspace\TcloudServer\apps\autotest\business\monkey.py", line 648, in query_all_json
    int(page_index - 1) * int(page_size)).all()
  File "D:\Programs\python37\lib\site-packages\sqlalchemy\orm\query.py", line 3211, in all
    return list(self)
  File "D:\Programs\python37\lib\site-packages\sqlalchemy\orm\query.py", line 3367, in __iter__
    return self._execute_and_instances(context)
  File "D:\Programs\python37\lib\site-packages\sqlalchemy\orm\query.py", line 3392, in _execute_and_instances
    result = conn.execute(querycontext.statement, self._params)
  File "D:\Programs\python37\lib\site-packages\sqlalchemy\engine\base.py", line 982, in execute
    return meth(self, multiparams, params)
  File "D:\Programs\python37\lib\site-packages\sqlalchemy\sql\elements.py", line 287, in _execute_on_connection
    return connection._execute_clauseelement(self, multiparams, params)
  File "D:\Programs\python37\lib\site-packages\sqlalchemy\engine\base.py", line 1101, in _execute_clauseelement
    distilled_params,
  File "D:\Programs\python37\lib\site-packages\sqlalchemy\engine\base.py", line 1250, in _execute_context
    e, statement, parameters, cursor, context
  File "D:\Programs\python37\lib\site-packages\sqlalchemy\engine\base.py", line 1476, in _handle_dbapi_exception
    util.raise_from_cause(sqlalchemy_exception, exc_info)
  File "D:\Programs\python37\lib\site-packages\sqlalchemy\util\compat.py", line 398, in raise_from_cause
    reraise(type(exception), exception, tb=exc_tb, cause=cause)
  File "D:\Programs\python37\lib\site-packages\sqlalchemy\util\compat.py", line 152, in reraise
    raise value.with_traceback(tb)
  File "D:\Programs\python37\lib\site-packages\sqlalchemy\engine\base.py", line 1246, in _execute_context
    cursor, statement, parameters, context
  File "D:\Programs\python37\lib\site-packages\sqlalchemy\engine\default.py", line 581, in do_execute
    cursor.execute(statement, parameters)
  File "D:\Programs\python37\lib\site-packages\MySQLdb\cursors.py", line 209, in execute
    res = self._query(query)
  File "D:\Programs\python37\lib\site-packages\MySQLdb\cursors.py", line 315, in _query
    db.query(q)
  File "D:\Programs\python37\lib\site-packages\MySQLdb\connections.py", line 231, in query
    _mysql.connection.query(self, query)
sqlalchemy.exc.OperationalError: (MySQLdb._exceptions.OperationalError) (1054, "Unknown column 'monkey_package.test_type' in 'field list'")
[SQL: SELECT monkey_package.id AS monkey_package_id, monkey_package.creation_time AS monkey_package_creation_time, monkey_package.modified_time AS monkey_package_modified_time, monkey_package.name AS monkey_package_name, monkey_package.package_name AS monkey_package_package_name, monkey_package.oss_url AS monkey_package_oss_url, monkey_package.picture AS monkey_package_picture, monkey_package.version AS monkey_package_version, monkey_package.default_activity AS monkey_package_default_activity, monkey_package.user_id AS monkey_package_user_id, monkey_package.status AS monkey_package_status, monkey_package.size AS monkey_package_size, monkey_package.test_type AS monkey_package_test_type, monkey_package.id AS id, monkey_package.name AS name, monkey_package.package_name AS package_name, monkey_package.oss_url AS oss_url, monkey_package.picture AS picture, monkey_package.version AS version, monkey_package.default_activity AS default_activity, monkey_package.user_id AS user_id, monkey_package.status AS status, monkey_package.size AS size, date_format(monkey_package.creation_time, %s) AS upload_time, monkey_package.test_type AS test_type 
FROM monkey_package 
WHERE monkey_package.status = %s AND monkey_package.test_type = %s ORDER BY monkey_package.id DESC 
 LIMIT %s, %s]
[parameters: ('%Y-%m-%d %H:%i:%s', 0, 1, 0, 10)]
(Background on this error at: http://sqlalche.me/e/e3q8)

[2019-11-22 15:34:12,139][37328][autotest][tMiddleware.py 71 ERROR]: 
request  : /v1/monkey/package  GET [handler: 0]
token    : eyJ0eXAiOiJKV1QiLCJhbGciOiJIUzI1NiJ9.eyJ1c2VyaWQiOjExNTIsInVzZXJuYW1lIjoiYWRtaW4iLCJuaWNrbmFtZSI6ImFkbWluIiwicGljdHVyZSI6IiIsInVzZXJ3ZWlnaHQiOjEsInJvbGUiOlt7ImlkIjoxLCJuYW1lIjoiYWRtaW4iLCJjb21tZW50IjoiXHU4ZDg1XHU3ZWE3XHU3YmExXHU3NDA2XHU1NDU4In0seyJpZCI6MywibmFtZSI6InRlc3QiLCJjb21tZW50IjoiXHU2ZDRiXHU4YmQ1In1dLCJwcm9qZWN0aWQiOlsyXSwiZXhwIjoxNTc1MDQxNjQ3fQ.tAFuzTB-HuzpeE7KZvbgddc_JCL8RXP1d08tfhoOmnY
projectid: 
query    : {'page_index': '1', 'page_size': '10', 'user_id': '1152'}

Traceback (most recent call last):
  File "D:\Programs\python37\lib\site-packages\sqlalchemy\engine\base.py", line 1246, in _execute_context
    cursor, statement, parameters, context
  File "D:\Programs\python37\lib\site-packages\sqlalchemy\engine\default.py", line 581, in do_execute
    cursor.execute(statement, parameters)
  File "D:\Programs\python37\lib\site-packages\MySQLdb\cursors.py", line 209, in execute
    res = self._query(query)
  File "D:\Programs\python37\lib\site-packages\MySQLdb\cursors.py", line 315, in _query
    db.query(q)
  File "D:\Programs\python37\lib\site-packages\MySQLdb\connections.py", line 231, in query
    _mysql.connection.query(self, query)
MySQLdb._exceptions.OperationalError: (1054, "Unknown column 'monkey_package.test_type' in 'field list'")

The above exception was the direct cause of the following exception:

Traceback (most recent call last):
  File "D:\Programs\python37\lib\site-packages\flask\app.py", line 1949, in full_dispatch_request
    rv = self.dispatch_request()
  File "D:\Programs\python37\lib\site-packages\flask\app.py", line 1935, in dispatch_request
    return self.view_functions[rule.endpoint](**req.view_args)
  File "G:\gitworkspace\TcloudServer\apps\autotest\views\monkey.py", line 479, in monkey_package_index_handler
    all, count = MonkeyPackageBusiness.get_monkey_packages_by_user_id(user_id, page_size, page_index, test_type)
  File "G:\gitworkspace\TcloudServer\apps\autotest\business\monkey.py", line 699, in get_monkey_packages_by_user_id
    all = cls.query_json_by_user_id(user_id, page_size, page_index, test_type)
  File "G:\gitworkspace\TcloudServer\library\api\transfer.py", line 129, in _
    result = func(*args, **kwargs)
  File "G:\gitworkspace\TcloudServer\apps\autotest\business\monkey.py", line 686, in query_json_by_user_id
    order_by(desc(MonkeyPackage.id)).limit(int(page_size)).offset(int(page_index - 1) * int(page_size)).all()
  File "D:\Programs\python37\lib\site-packages\sqlalchemy\orm\query.py", line 3211, in all
    return list(self)
  File "D:\Programs\python37\lib\site-packages\sqlalchemy\orm\query.py", line 3367, in __iter__
    return self._execute_and_instances(context)
  File "D:\Programs\python37\lib\site-packages\sqlalchemy\orm\query.py", line 3392, in _execute_and_instances
    result = conn.execute(querycontext.statement, self._params)
  File "D:\Programs\python37\lib\site-packages\sqlalchemy\engine\base.py", line 982, in execute
    return meth(self, multiparams, params)
  File "D:\Programs\python37\lib\site-packages\sqlalchemy\sql\elements.py", line 287, in _execute_on_connection
    return connection._execute_clauseelement(self, multiparams, params)
  File "D:\Programs\python37\lib\site-packages\sqlalchemy\engine\base.py", line 1101, in _execute_clauseelement
    distilled_params,
  File "D:\Programs\python37\lib\site-packages\sqlalchemy\engine\base.py", line 1250, in _execute_context
    e, statement, parameters, cursor, context
  File "D:\Programs\python37\lib\site-packages\sqlalchemy\engine\base.py", line 1476, in _handle_dbapi_exception
    util.raise_from_cause(sqlalchemy_exception, exc_info)
  File "D:\Programs\python37\lib\site-packages\sqlalchemy\util\compat.py", line 398, in raise_from_cause
    reraise(type(exception), exception, tb=exc_tb, cause=cause)
  File "D:\Programs\python37\lib\site-packages\sqlalchemy\util\compat.py", line 152, in reraise
    raise value.with_traceback(tb)
  File "D:\Programs\python37\lib\site-packages\sqlalchemy\engine\base.py", line 1246, in _execute_context
    cursor, statement, parameters, context
  File "D:\Programs\python37\lib\site-packages\sqlalchemy\engine\default.py", line 581, in do_execute
    cursor.execute(statement, parameters)
  File "D:\Programs\python37\lib\site-packages\MySQLdb\cursors.py", line 209, in execute
    res = self._query(query)
  File "D:\Programs\python37\lib\site-packages\MySQLdb\cursors.py", line 315, in _query
    db.query(q)
  File "D:\Programs\python37\lib\site-packages\MySQLdb\connections.py", line 231, in query
    _mysql.connection.query(self, query)
sqlalchemy.exc.OperationalError: (MySQLdb._exceptions.OperationalError) (1054, "Unknown column 'monkey_package.test_type' in 'field list'")
[SQL: SELECT monkey_package.id AS monkey_package_id, monkey_package.creation_time AS monkey_package_creation_time, monkey_package.modified_time AS monkey_package_modified_time, monkey_package.name AS monkey_package_name, monkey_package.package_name AS monkey_package_package_name, monkey_package.oss_url AS monkey_package_oss_url, monkey_package.picture AS monkey_package_picture, monkey_package.version AS monkey_package_version, monkey_package.default_activity AS monkey_package_default_activity, monkey_package.user_id AS monkey_package_user_id, monkey_package.status AS monkey_package_status, monkey_package.size AS monkey_package_size, monkey_package.test_type AS monkey_package_test_type, monkey_package.id AS id, monkey_package.name AS name, monkey_package.package_name AS package_name, monkey_package.oss_url AS oss_url, monkey_package.picture AS picture, monkey_package.version AS version, monkey_package.default_activity AS default_activity, monkey_package.user_id AS user_id, monkey_package.status AS status, monkey_package.size AS size, date_format(monkey_package.creation_time, %s) AS upload_time, monkey_package.test_type AS test_type 
FROM monkey_package 
WHERE monkey_package.status = %s AND monkey_package.test_type = %s AND monkey_package.user_id = %s ORDER BY monkey_package.id DESC 
 LIMIT %s, %s]
[parameters: ('%Y-%m-%d %H:%i:%s', 0, 1, '1152', 0, 10)]
(Background on this error at: http://sqlalche.me/e/e3q8)

[2019-11-22 16:12:58,077][37328][autotest][tMiddleware.py 71 ERROR]: 
request  : /v1/monkey/package  GET [handler: 0]
token    : eyJ0eXAiOiJKV1QiLCJhbGciOiJIUzI1NiJ9.eyJ1c2VyaWQiOjExNTIsInVzZXJuYW1lIjoiYWRtaW4iLCJuaWNrbmFtZSI6ImFkbWluIiwicGljdHVyZSI6IiIsInVzZXJ3ZWlnaHQiOjEsInJvbGUiOlt7ImlkIjoxLCJuYW1lIjoiYWRtaW4iLCJjb21tZW50IjoiXHU4ZDg1XHU3ZWE3XHU3YmExXHU3NDA2XHU1NDU4In0seyJpZCI6MywibmFtZSI6InRlc3QiLCJjb21tZW50IjoiXHU2ZDRiXHU4YmQ1In1dLCJwcm9qZWN0aWQiOlsyXSwiZXhwIjoxNTc1MDQxNjQ3fQ.tAFuzTB-HuzpeE7KZvbgddc_JCL8RXP1d08tfhoOmnY
projectid: 
query    : {'page_index': '1', 'page_size': '10', 'user_id': '1152'}

Traceback (most recent call last):
  File "D:\Programs\python37\lib\site-packages\sqlalchemy\engine\base.py", line 1246, in _execute_context
    cursor, statement, parameters, context
  File "D:\Programs\python37\lib\site-packages\sqlalchemy\engine\default.py", line 581, in do_execute
    cursor.execute(statement, parameters)
  File "D:\Programs\python37\lib\site-packages\MySQLdb\cursors.py", line 209, in execute
    res = self._query(query)
  File "D:\Programs\python37\lib\site-packages\MySQLdb\cursors.py", line 315, in _query
    db.query(q)
  File "D:\Programs\python37\lib\site-packages\MySQLdb\connections.py", line 231, in query
    _mysql.connection.query(self, query)
MySQLdb._exceptions.OperationalError: (1054, "Unknown column 'monkey_package.test_type' in 'field list'")

The above exception was the direct cause of the following exception:

Traceback (most recent call last):
  File "D:\Programs\python37\lib\site-packages\flask\app.py", line 1949, in full_dispatch_request
    rv = self.dispatch_request()
  File "D:\Programs\python37\lib\site-packages\flask\app.py", line 1935, in dispatch_request
    return self.view_functions[rule.endpoint](**req.view_args)
  File "G:\gitworkspace\TcloudServer\apps\autotest\views\monkey.py", line 479, in monkey_package_index_handler
    all, count = MonkeyPackageBusiness.get_monkey_packages_by_user_id(user_id, page_size, page_index, test_type)
  File "G:\gitworkspace\TcloudServer\apps\autotest\business\monkey.py", line 699, in get_monkey_packages_by_user_id
    all = cls.query_json_by_user_id(user_id, page_size, page_index, test_type)
  File "G:\gitworkspace\TcloudServer\library\api\transfer.py", line 129, in _
    result = func(*args, **kwargs)
  File "G:\gitworkspace\TcloudServer\apps\autotest\business\monkey.py", line 686, in query_json_by_user_id
    order_by(desc(MonkeyPackage.id)).limit(int(page_size)).offset(int(page_index - 1) * int(page_size)).all()
  File "D:\Programs\python37\lib\site-packages\sqlalchemy\orm\query.py", line 3211, in all
    return list(self)
  File "D:\Programs\python37\lib\site-packages\sqlalchemy\orm\query.py", line 3367, in __iter__
    return self._execute_and_instances(context)
  File "D:\Programs\python37\lib\site-packages\sqlalchemy\orm\query.py", line 3392, in _execute_and_instances
    result = conn.execute(querycontext.statement, self._params)
  File "D:\Programs\python37\lib\site-packages\sqlalchemy\engine\base.py", line 982, in execute
    return meth(self, multiparams, params)
  File "D:\Programs\python37\lib\site-packages\sqlalchemy\sql\elements.py", line 287, in _execute_on_connection
    return connection._execute_clauseelement(self, multiparams, params)
  File "D:\Programs\python37\lib\site-packages\sqlalchemy\engine\base.py", line 1101, in _execute_clauseelement
    distilled_params,
  File "D:\Programs\python37\lib\site-packages\sqlalchemy\engine\base.py", line 1250, in _execute_context
    e, statement, parameters, cursor, context
  File "D:\Programs\python37\lib\site-packages\sqlalchemy\engine\base.py", line 1476, in _handle_dbapi_exception
    util.raise_from_cause(sqlalchemy_exception, exc_info)
  File "D:\Programs\python37\lib\site-packages\sqlalchemy\util\compat.py", line 398, in raise_from_cause
    reraise(type(exception), exception, tb=exc_tb, cause=cause)
  File "D:\Programs\python37\lib\site-packages\sqlalchemy\util\compat.py", line 152, in reraise
    raise value.with_traceback(tb)
  File "D:\Programs\python37\lib\site-packages\sqlalchemy\engine\base.py", line 1246, in _execute_context
    cursor, statement, parameters, context
  File "D:\Programs\python37\lib\site-packages\sqlalchemy\engine\default.py", line 581, in do_execute
    cursor.execute(statement, parameters)
  File "D:\Programs\python37\lib\site-packages\MySQLdb\cursors.py", line 209, in execute
    res = self._query(query)
  File "D:\Programs\python37\lib\site-packages\MySQLdb\cursors.py", line 315, in _query
    db.query(q)
  File "D:\Programs\python37\lib\site-packages\MySQLdb\connections.py", line 231, in query
    _mysql.connection.query(self, query)
sqlalchemy.exc.OperationalError: (MySQLdb._exceptions.OperationalError) (1054, "Unknown column 'monkey_package.test_type' in 'field list'")
[SQL: SELECT monkey_package.id AS monkey_package_id, monkey_package.creation_time AS monkey_package_creation_time, monkey_package.modified_time AS monkey_package_modified_time, monkey_package.name AS monkey_package_name, monkey_package.package_name AS monkey_package_package_name, monkey_package.oss_url AS monkey_package_oss_url, monkey_package.picture AS monkey_package_picture, monkey_package.version AS monkey_package_version, monkey_package.default_activity AS monkey_package_default_activity, monkey_package.user_id AS monkey_package_user_id, monkey_package.status AS monkey_package_status, monkey_package.size AS monkey_package_size, monkey_package.test_type AS monkey_package_test_type, monkey_package.id AS id, monkey_package.name AS name, monkey_package.package_name AS package_name, monkey_package.oss_url AS oss_url, monkey_package.picture AS picture, monkey_package.version AS version, monkey_package.default_activity AS default_activity, monkey_package.user_id AS user_id, monkey_package.status AS status, monkey_package.size AS size, date_format(monkey_package.creation_time, %s) AS upload_time, monkey_package.test_type AS test_type 
FROM monkey_package 
WHERE monkey_package.status = %s AND monkey_package.test_type = %s AND monkey_package.user_id = %s ORDER BY monkey_package.id DESC 
 LIMIT %s, %s]
[parameters: ('%Y-%m-%d %H:%i:%s', 0, 1, '1152', 0, 10)]
(Background on this error at: http://sqlalche.me/e/e3q8)

[2019-11-22 16:12:58,170][37328][autotest][tMiddleware.py 71 ERROR]: 
request  : /v1/monkey/package  GET [handler: 0]
token    : eyJ0eXAiOiJKV1QiLCJhbGciOiJIUzI1NiJ9.eyJ1c2VyaWQiOjExNTIsInVzZXJuYW1lIjoiYWRtaW4iLCJuaWNrbmFtZSI6ImFkbWluIiwicGljdHVyZSI6IiIsInVzZXJ3ZWlnaHQiOjEsInJvbGUiOlt7ImlkIjoxLCJuYW1lIjoiYWRtaW4iLCJjb21tZW50IjoiXHU4ZDg1XHU3ZWE3XHU3YmExXHU3NDA2XHU1NDU4In0seyJpZCI6MywibmFtZSI6InRlc3QiLCJjb21tZW50IjoiXHU2ZDRiXHU4YmQ1In1dLCJwcm9qZWN0aWQiOlsyXSwiZXhwIjoxNTc1MDQxNjQ3fQ.tAFuzTB-HuzpeE7KZvbgddc_JCL8RXP1d08tfhoOmnY
projectid: 
query    : {'page_index': '1', 'page_size': '10'}

Traceback (most recent call last):
  File "D:\Programs\python37\lib\site-packages\sqlalchemy\engine\base.py", line 1246, in _execute_context
    cursor, statement, parameters, context
  File "D:\Programs\python37\lib\site-packages\sqlalchemy\engine\default.py", line 581, in do_execute
    cursor.execute(statement, parameters)
  File "D:\Programs\python37\lib\site-packages\MySQLdb\cursors.py", line 209, in execute
    res = self._query(query)
  File "D:\Programs\python37\lib\site-packages\MySQLdb\cursors.py", line 315, in _query
    db.query(q)
  File "D:\Programs\python37\lib\site-packages\MySQLdb\connections.py", line 231, in query
    _mysql.connection.query(self, query)
MySQLdb._exceptions.OperationalError: (1054, "Unknown column 'monkey_package.test_type' in 'field list'")

The above exception was the direct cause of the following exception:

Traceback (most recent call last):
  File "D:\Programs\python37\lib\site-packages\flask\app.py", line 1949, in full_dispatch_request
    rv = self.dispatch_request()
  File "D:\Programs\python37\lib\site-packages\flask\app.py", line 1935, in dispatch_request
    return self.view_functions[rule.endpoint](**req.view_args)
  File "G:\gitworkspace\TcloudServer\apps\autotest\views\monkey.py", line 479, in monkey_package_index_handler
    all, count = MonkeyPackageBusiness.get_monkey_packages_by_user_id(user_id, page_size, page_index, test_type)
  File "G:\gitworkspace\TcloudServer\apps\autotest\business\monkey.py", line 702, in get_monkey_packages_by_user_id
    all = cls.query_all_json(page_size, page_index, test_type)
  File "G:\gitworkspace\TcloudServer\library\api\transfer.py", line 129, in _
    result = func(*args, **kwargs)
  File "G:\gitworkspace\TcloudServer\apps\autotest\business\monkey.py", line 648, in query_all_json
    int(page_index - 1) * int(page_size)).all()
  File "D:\Programs\python37\lib\site-packages\sqlalchemy\orm\query.py", line 3211, in all
    return list(self)
  File "D:\Programs\python37\lib\site-packages\sqlalchemy\orm\query.py", line 3367, in __iter__
    return self._execute_and_instances(context)
  File "D:\Programs\python37\lib\site-packages\sqlalchemy\orm\query.py", line 3392, in _execute_and_instances
    result = conn.execute(querycontext.statement, self._params)
  File "D:\Programs\python37\lib\site-packages\sqlalchemy\engine\base.py", line 982, in execute
    return meth(self, multiparams, params)
  File "D:\Programs\python37\lib\site-packages\sqlalchemy\sql\elements.py", line 287, in _execute_on_connection
    return connection._execute_clauseelement(self, multiparams, params)
  File "D:\Programs\python37\lib\site-packages\sqlalchemy\engine\base.py", line 1101, in _execute_clauseelement
    distilled_params,
  File "D:\Programs\python37\lib\site-packages\sqlalchemy\engine\base.py", line 1250, in _execute_context
    e, statement, parameters, cursor, context
  File "D:\Programs\python37\lib\site-packages\sqlalchemy\engine\base.py", line 1476, in _handle_dbapi_exception
    util.raise_from_cause(sqlalchemy_exception, exc_info)
  File "D:\Programs\python37\lib\site-packages\sqlalchemy\util\compat.py", line 398, in raise_from_cause
    reraise(type(exception), exception, tb=exc_tb, cause=cause)
  File "D:\Programs\python37\lib\site-packages\sqlalchemy\util\compat.py", line 152, in reraise
    raise value.with_traceback(tb)
  File "D:\Programs\python37\lib\site-packages\sqlalchemy\engine\base.py", line 1246, in _execute_context
    cursor, statement, parameters, context
  File "D:\Programs\python37\lib\site-packages\sqlalchemy\engine\default.py", line 581, in do_execute
    cursor.execute(statement, parameters)
  File "D:\Programs\python37\lib\site-packages\MySQLdb\cursors.py", line 209, in execute
    res = self._query(query)
  File "D:\Programs\python37\lib\site-packages\MySQLdb\cursors.py", line 315, in _query
    db.query(q)
  File "D:\Programs\python37\lib\site-packages\MySQLdb\connections.py", line 231, in query
    _mysql.connection.query(self, query)
sqlalchemy.exc.OperationalError: (MySQLdb._exceptions.OperationalError) (1054, "Unknown column 'monkey_package.test_type' in 'field list'")
[SQL: SELECT monkey_package.id AS monkey_package_id, monkey_package.creation_time AS monkey_package_creation_time, monkey_package.modified_time AS monkey_package_modified_time, monkey_package.name AS monkey_package_name, monkey_package.package_name AS monkey_package_package_name, monkey_package.oss_url AS monkey_package_oss_url, monkey_package.picture AS monkey_package_picture, monkey_package.version AS monkey_package_version, monkey_package.default_activity AS monkey_package_default_activity, monkey_package.user_id AS monkey_package_user_id, monkey_package.status AS monkey_package_status, monkey_package.size AS monkey_package_size, monkey_package.test_type AS monkey_package_test_type, monkey_package.id AS id, monkey_package.name AS name, monkey_package.package_name AS package_name, monkey_package.oss_url AS oss_url, monkey_package.picture AS picture, monkey_package.version AS version, monkey_package.default_activity AS default_activity, monkey_package.user_id AS user_id, monkey_package.status AS status, monkey_package.size AS size, date_format(monkey_package.creation_time, %s) AS upload_time, monkey_package.test_type AS test_type 
FROM monkey_package 
WHERE monkey_package.status = %s AND monkey_package.test_type = %s ORDER BY monkey_package.id DESC 
 LIMIT %s, %s]
[parameters: ('%Y-%m-%d %H:%i:%s', 0, 1, 0, 10)]
(Background on this error at: http://sqlalche.me/e/e3q8)

[2019-11-22 16:13:03,032][37328][autotest][tMiddleware.py 71 ERROR]: 
request  : /v1/monkey/package  GET [handler: 0]
token    : eyJ0eXAiOiJKV1QiLCJhbGciOiJIUzI1NiJ9.eyJ1c2VyaWQiOjExNTIsInVzZXJuYW1lIjoiYWRtaW4iLCJuaWNrbmFtZSI6ImFkbWluIiwicGljdHVyZSI6IiIsInVzZXJ3ZWlnaHQiOjEsInJvbGUiOlt7ImlkIjoxLCJuYW1lIjoiYWRtaW4iLCJjb21tZW50IjoiXHU4ZDg1XHU3ZWE3XHU3YmExXHU3NDA2XHU1NDU4In0seyJpZCI6MywibmFtZSI6InRlc3QiLCJjb21tZW50IjoiXHU2ZDRiXHU4YmQ1In1dLCJwcm9qZWN0aWQiOlsyXSwiZXhwIjoxNTc1MDQxNjQ3fQ.tAFuzTB-HuzpeE7KZvbgddc_JCL8RXP1d08tfhoOmnY
projectid: 
query    : {'page_index': '1', 'page_size': '10', 'user_id': '1152'}

Traceback (most recent call last):
  File "D:\Programs\python37\lib\site-packages\sqlalchemy\engine\base.py", line 1246, in _execute_context
    cursor, statement, parameters, context
  File "D:\Programs\python37\lib\site-packages\sqlalchemy\engine\default.py", line 581, in do_execute
    cursor.execute(statement, parameters)
  File "D:\Programs\python37\lib\site-packages\MySQLdb\cursors.py", line 209, in execute
    res = self._query(query)
  File "D:\Programs\python37\lib\site-packages\MySQLdb\cursors.py", line 315, in _query
    db.query(q)
  File "D:\Programs\python37\lib\site-packages\MySQLdb\connections.py", line 231, in query
    _mysql.connection.query(self, query)
MySQLdb._exceptions.OperationalError: (1054, "Unknown column 'monkey_package.test_type' in 'field list'")

The above exception was the direct cause of the following exception:

Traceback (most recent call last):
  File "D:\Programs\python37\lib\site-packages\flask\app.py", line 1949, in full_dispatch_request
    rv = self.dispatch_request()
  File "D:\Programs\python37\lib\site-packages\flask\app.py", line 1935, in dispatch_request
    return self.view_functions[rule.endpoint](**req.view_args)
  File "G:\gitworkspace\TcloudServer\apps\autotest\views\monkey.py", line 479, in monkey_package_index_handler
    all, count = MonkeyPackageBusiness.get_monkey_packages_by_user_id(user_id, page_size, page_index, test_type)
  File "G:\gitworkspace\TcloudServer\apps\autotest\business\monkey.py", line 699, in get_monkey_packages_by_user_id
    all = cls.query_json_by_user_id(user_id, page_size, page_index, test_type)
  File "G:\gitworkspace\TcloudServer\library\api\transfer.py", line 129, in _
    result = func(*args, **kwargs)
  File "G:\gitworkspace\TcloudServer\apps\autotest\business\monkey.py", line 686, in query_json_by_user_id
    order_by(desc(MonkeyPackage.id)).limit(int(page_size)).offset(int(page_index - 1) * int(page_size)).all()
  File "D:\Programs\python37\lib\site-packages\sqlalchemy\orm\query.py", line 3211, in all
    return list(self)
  File "D:\Programs\python37\lib\site-packages\sqlalchemy\orm\query.py", line 3367, in __iter__
    return self._execute_and_instances(context)
  File "D:\Programs\python37\lib\site-packages\sqlalchemy\orm\query.py", line 3392, in _execute_and_instances
    result = conn.execute(querycontext.statement, self._params)
  File "D:\Programs\python37\lib\site-packages\sqlalchemy\engine\base.py", line 982, in execute
    return meth(self, multiparams, params)
  File "D:\Programs\python37\lib\site-packages\sqlalchemy\sql\elements.py", line 287, in _execute_on_connection
    return connection._execute_clauseelement(self, multiparams, params)
  File "D:\Programs\python37\lib\site-packages\sqlalchemy\engine\base.py", line 1101, in _execute_clauseelement
    distilled_params,
  File "D:\Programs\python37\lib\site-packages\sqlalchemy\engine\base.py", line 1250, in _execute_context
    e, statement, parameters, cursor, context
  File "D:\Programs\python37\lib\site-packages\sqlalchemy\engine\base.py", line 1476, in _handle_dbapi_exception
    util.raise_from_cause(sqlalchemy_exception, exc_info)
  File "D:\Programs\python37\lib\site-packages\sqlalchemy\util\compat.py", line 398, in raise_from_cause
    reraise(type(exception), exception, tb=exc_tb, cause=cause)
  File "D:\Programs\python37\lib\site-packages\sqlalchemy\util\compat.py", line 152, in reraise
    raise value.with_traceback(tb)
  File "D:\Programs\python37\lib\site-packages\sqlalchemy\engine\base.py", line 1246, in _execute_context
    cursor, statement, parameters, context
  File "D:\Programs\python37\lib\site-packages\sqlalchemy\engine\default.py", line 581, in do_execute
    cursor.execute(statement, parameters)
  File "D:\Programs\python37\lib\site-packages\MySQLdb\cursors.py", line 209, in execute
    res = self._query(query)
  File "D:\Programs\python37\lib\site-packages\MySQLdb\cursors.py", line 315, in _query
    db.query(q)
  File "D:\Programs\python37\lib\site-packages\MySQLdb\connections.py", line 231, in query
    _mysql.connection.query(self, query)
sqlalchemy.exc.OperationalError: (MySQLdb._exceptions.OperationalError) (1054, "Unknown column 'monkey_package.test_type' in 'field list'")
[SQL: SELECT monkey_package.id AS monkey_package_id, monkey_package.creation_time AS monkey_package_creation_time, monkey_package.modified_time AS monkey_package_modified_time, monkey_package.name AS monkey_package_name, monkey_package.package_name AS monkey_package_package_name, monkey_package.oss_url AS monkey_package_oss_url, monkey_package.picture AS monkey_package_picture, monkey_package.version AS monkey_package_version, monkey_package.default_activity AS monkey_package_default_activity, monkey_package.user_id AS monkey_package_user_id, monkey_package.status AS monkey_package_status, monkey_package.size AS monkey_package_size, monkey_package.test_type AS monkey_package_test_type, monkey_package.id AS id, monkey_package.name AS name, monkey_package.package_name AS package_name, monkey_package.oss_url AS oss_url, monkey_package.picture AS picture, monkey_package.version AS version, monkey_package.default_activity AS default_activity, monkey_package.user_id AS user_id, monkey_package.status AS status, monkey_package.size AS size, date_format(monkey_package.creation_time, %s) AS upload_time, monkey_package.test_type AS test_type 
FROM monkey_package 
WHERE monkey_package.status = %s AND monkey_package.test_type = %s AND monkey_package.user_id = %s ORDER BY monkey_package.id DESC 
 LIMIT %s, %s]
[parameters: ('%Y-%m-%d %H:%i:%s', 0, 1, '1152', 0, 10)]
(Background on this error at: http://sqlalche.me/e/e3q8)

[2019-11-22 16:13:03,054][37328][autotest][tMiddleware.py 71 ERROR]: 
request  : /v1/monkey/package  GET [handler: 0]
token    : eyJ0eXAiOiJKV1QiLCJhbGciOiJIUzI1NiJ9.eyJ1c2VyaWQiOjExNTIsInVzZXJuYW1lIjoiYWRtaW4iLCJuaWNrbmFtZSI6ImFkbWluIiwicGljdHVyZSI6IiIsInVzZXJ3ZWlnaHQiOjEsInJvbGUiOlt7ImlkIjoxLCJuYW1lIjoiYWRtaW4iLCJjb21tZW50IjoiXHU4ZDg1XHU3ZWE3XHU3YmExXHU3NDA2XHU1NDU4In0seyJpZCI6MywibmFtZSI6InRlc3QiLCJjb21tZW50IjoiXHU2ZDRiXHU4YmQ1In1dLCJwcm9qZWN0aWQiOlsyXSwiZXhwIjoxNTc1MDQxNjQ3fQ.tAFuzTB-HuzpeE7KZvbgddc_JCL8RXP1d08tfhoOmnY
projectid: 
query    : {'page_index': '1', 'page_size': '10'}

Traceback (most recent call last):
  File "D:\Programs\python37\lib\site-packages\sqlalchemy\engine\base.py", line 1246, in _execute_context
    cursor, statement, parameters, context
  File "D:\Programs\python37\lib\site-packages\sqlalchemy\engine\default.py", line 581, in do_execute
    cursor.execute(statement, parameters)
  File "D:\Programs\python37\lib\site-packages\MySQLdb\cursors.py", line 209, in execute
    res = self._query(query)
  File "D:\Programs\python37\lib\site-packages\MySQLdb\cursors.py", line 315, in _query
    db.query(q)
  File "D:\Programs\python37\lib\site-packages\MySQLdb\connections.py", line 231, in query
    _mysql.connection.query(self, query)
MySQLdb._exceptions.OperationalError: (1054, "Unknown column 'monkey_package.test_type' in 'field list'")

The above exception was the direct cause of the following exception:

Traceback (most recent call last):
  File "D:\Programs\python37\lib\site-packages\flask\app.py", line 1949, in full_dispatch_request
    rv = self.dispatch_request()
  File "D:\Programs\python37\lib\site-packages\flask\app.py", line 1935, in dispatch_request
    return self.view_functions[rule.endpoint](**req.view_args)
  File "G:\gitworkspace\TcloudServer\apps\autotest\views\monkey.py", line 479, in monkey_package_index_handler
    all, count = MonkeyPackageBusiness.get_monkey_packages_by_user_id(user_id, page_size, page_index, test_type)
  File "G:\gitworkspace\TcloudServer\apps\autotest\business\monkey.py", line 702, in get_monkey_packages_by_user_id
    all = cls.query_all_json(page_size, page_index, test_type)
  File "G:\gitworkspace\TcloudServer\library\api\transfer.py", line 129, in _
    result = func(*args, **kwargs)
  File "G:\gitworkspace\TcloudServer\apps\autotest\business\monkey.py", line 648, in query_all_json
    int(page_index - 1) * int(page_size)).all()
  File "D:\Programs\python37\lib\site-packages\sqlalchemy\orm\query.py", line 3211, in all
    return list(self)
  File "D:\Programs\python37\lib\site-packages\sqlalchemy\orm\query.py", line 3367, in __iter__
    return self._execute_and_instances(context)
  File "D:\Programs\python37\lib\site-packages\sqlalchemy\orm\query.py", line 3392, in _execute_and_instances
    result = conn.execute(querycontext.statement, self._params)
  File "D:\Programs\python37\lib\site-packages\sqlalchemy\engine\base.py", line 982, in execute
    return meth(self, multiparams, params)
  File "D:\Programs\python37\lib\site-packages\sqlalchemy\sql\elements.py", line 287, in _execute_on_connection
    return connection._execute_clauseelement(self, multiparams, params)
  File "D:\Programs\python37\lib\site-packages\sqlalchemy\engine\base.py", line 1101, in _execute_clauseelement
    distilled_params,
  File "D:\Programs\python37\lib\site-packages\sqlalchemy\engine\base.py", line 1250, in _execute_context
    e, statement, parameters, cursor, context
  File "D:\Programs\python37\lib\site-packages\sqlalchemy\engine\base.py", line 1476, in _handle_dbapi_exception
    util.raise_from_cause(sqlalchemy_exception, exc_info)
  File "D:\Programs\python37\lib\site-packages\sqlalchemy\util\compat.py", line 398, in raise_from_cause
    reraise(type(exception), exception, tb=exc_tb, cause=cause)
  File "D:\Programs\python37\lib\site-packages\sqlalchemy\util\compat.py", line 152, in reraise
    raise value.with_traceback(tb)
  File "D:\Programs\python37\lib\site-packages\sqlalchemy\engine\base.py", line 1246, in _execute_context
    cursor, statement, parameters, context
  File "D:\Programs\python37\lib\site-packages\sqlalchemy\engine\default.py", line 581, in do_execute
    cursor.execute(statement, parameters)
  File "D:\Programs\python37\lib\site-packages\MySQLdb\cursors.py", line 209, in execute
    res = self._query(query)
  File "D:\Programs\python37\lib\site-packages\MySQLdb\cursors.py", line 315, in _query
    db.query(q)
  File "D:\Programs\python37\lib\site-packages\MySQLdb\connections.py", line 231, in query
    _mysql.connection.query(self, query)
sqlalchemy.exc.OperationalError: (MySQLdb._exceptions.OperationalError) (1054, "Unknown column 'monkey_package.test_type' in 'field list'")
[SQL: SELECT monkey_package.id AS monkey_package_id, monkey_package.creation_time AS monkey_package_creation_time, monkey_package.modified_time AS monkey_package_modified_time, monkey_package.name AS monkey_package_name, monkey_package.package_name AS monkey_package_package_name, monkey_package.oss_url AS monkey_package_oss_url, monkey_package.picture AS monkey_package_picture, monkey_package.version AS monkey_package_version, monkey_package.default_activity AS monkey_package_default_activity, monkey_package.user_id AS monkey_package_user_id, monkey_package.status AS monkey_package_status, monkey_package.size AS monkey_package_size, monkey_package.test_type AS monkey_package_test_type, monkey_package.id AS id, monkey_package.name AS name, monkey_package.package_name AS package_name, monkey_package.oss_url AS oss_url, monkey_package.picture AS picture, monkey_package.version AS version, monkey_package.default_activity AS default_activity, monkey_package.user_id AS user_id, monkey_package.status AS status, monkey_package.size AS size, date_format(monkey_package.creation_time, %s) AS upload_time, monkey_package.test_type AS test_type 
FROM monkey_package 
WHERE monkey_package.status = %s AND monkey_package.test_type = %s ORDER BY monkey_package.id DESC 
 LIMIT %s, %s]
[parameters: ('%Y-%m-%d %H:%i:%s', 0, 1, 0, 10)]
(Background on this error at: http://sqlalche.me/e/e3q8)

[2019-11-22 16:45:45,294][37328][autotest][tMiddleware.py 71 ERROR]: 
request  : /v1/monkey/package  GET [handler: 0]
token    : eyJ0eXAiOiJKV1QiLCJhbGciOiJIUzI1NiJ9.eyJ1c2VyaWQiOjExNTIsInVzZXJuYW1lIjoiYWRtaW4iLCJuaWNrbmFtZSI6ImFkbWluIiwicGljdHVyZSI6IiIsInVzZXJ3ZWlnaHQiOjEsInJvbGUiOlt7ImlkIjoxLCJuYW1lIjoiYWRtaW4iLCJjb21tZW50IjoiXHU4ZDg1XHU3ZWE3XHU3YmExXHU3NDA2XHU1NDU4In0seyJpZCI6MywibmFtZSI6InRlc3QiLCJjb21tZW50IjoiXHU2ZDRiXHU4YmQ1In1dLCJwcm9qZWN0aWQiOlsyXSwiZXhwIjoxNTc1MDQxNjQ3fQ.tAFuzTB-HuzpeE7KZvbgddc_JCL8RXP1d08tfhoOmnY
projectid: 
query    : {'page_index': '1', 'page_size': '10', 'user_id': '1152'}

Traceback (most recent call last):
  File "D:\Programs\python37\lib\site-packages\sqlalchemy\engine\base.py", line 1246, in _execute_context
    cursor, statement, parameters, context
  File "D:\Programs\python37\lib\site-packages\sqlalchemy\engine\default.py", line 581, in do_execute
    cursor.execute(statement, parameters)
  File "D:\Programs\python37\lib\site-packages\MySQLdb\cursors.py", line 209, in execute
    res = self._query(query)
  File "D:\Programs\python37\lib\site-packages\MySQLdb\cursors.py", line 315, in _query
    db.query(q)
  File "D:\Programs\python37\lib\site-packages\MySQLdb\connections.py", line 231, in query
    _mysql.connection.query(self, query)
MySQLdb._exceptions.OperationalError: (1054, "Unknown column 'monkey_package.test_type' in 'field list'")

The above exception was the direct cause of the following exception:

Traceback (most recent call last):
  File "D:\Programs\python37\lib\site-packages\flask\app.py", line 1949, in full_dispatch_request
    rv = self.dispatch_request()
  File "D:\Programs\python37\lib\site-packages\flask\app.py", line 1935, in dispatch_request
    return self.view_functions[rule.endpoint](**req.view_args)
  File "G:\gitworkspace\TcloudServer\apps\autotest\views\monkey.py", line 479, in monkey_package_index_handler
    all, count = MonkeyPackageBusiness.get_monkey_packages_by_user_id(user_id, page_size, page_index, test_type)
  File "G:\gitworkspace\TcloudServer\apps\autotest\business\monkey.py", line 699, in get_monkey_packages_by_user_id
    all = cls.query_json_by_user_id(user_id, page_size, page_index, test_type)
  File "G:\gitworkspace\TcloudServer\library\api\transfer.py", line 129, in _
    result = func(*args, **kwargs)
  File "G:\gitworkspace\TcloudServer\apps\autotest\business\monkey.py", line 686, in query_json_by_user_id
    order_by(desc(MonkeyPackage.id)).limit(int(page_size)).offset(int(page_index - 1) * int(page_size)).all()
  File "D:\Programs\python37\lib\site-packages\sqlalchemy\orm\query.py", line 3211, in all
    return list(self)
  File "D:\Programs\python37\lib\site-packages\sqlalchemy\orm\query.py", line 3367, in __iter__
    return self._execute_and_instances(context)
  File "D:\Programs\python37\lib\site-packages\sqlalchemy\orm\query.py", line 3392, in _execute_and_instances
    result = conn.execute(querycontext.statement, self._params)
  File "D:\Programs\python37\lib\site-packages\sqlalchemy\engine\base.py", line 982, in execute
    return meth(self, multiparams, params)
  File "D:\Programs\python37\lib\site-packages\sqlalchemy\sql\elements.py", line 287, in _execute_on_connection
    return connection._execute_clauseelement(self, multiparams, params)
  File "D:\Programs\python37\lib\site-packages\sqlalchemy\engine\base.py", line 1101, in _execute_clauseelement
    distilled_params,
  File "D:\Programs\python37\lib\site-packages\sqlalchemy\engine\base.py", line 1250, in _execute_context
    e, statement, parameters, cursor, context
  File "D:\Programs\python37\lib\site-packages\sqlalchemy\engine\base.py", line 1476, in _handle_dbapi_exception
    util.raise_from_cause(sqlalchemy_exception, exc_info)
  File "D:\Programs\python37\lib\site-packages\sqlalchemy\util\compat.py", line 398, in raise_from_cause
    reraise(type(exception), exception, tb=exc_tb, cause=cause)
  File "D:\Programs\python37\lib\site-packages\sqlalchemy\util\compat.py", line 152, in reraise
    raise value.with_traceback(tb)
  File "D:\Programs\python37\lib\site-packages\sqlalchemy\engine\base.py", line 1246, in _execute_context
    cursor, statement, parameters, context
  File "D:\Programs\python37\lib\site-packages\sqlalchemy\engine\default.py", line 581, in do_execute
    cursor.execute(statement, parameters)
  File "D:\Programs\python37\lib\site-packages\MySQLdb\cursors.py", line 209, in execute
    res = self._query(query)
  File "D:\Programs\python37\lib\site-packages\MySQLdb\cursors.py", line 315, in _query
    db.query(q)
  File "D:\Programs\python37\lib\site-packages\MySQLdb\connections.py", line 231, in query
    _mysql.connection.query(self, query)
sqlalchemy.exc.OperationalError: (MySQLdb._exceptions.OperationalError) (1054, "Unknown column 'monkey_package.test_type' in 'field list'")
[SQL: SELECT monkey_package.id AS monkey_package_id, monkey_package.creation_time AS monkey_package_creation_time, monkey_package.modified_time AS monkey_package_modified_time, monkey_package.name AS monkey_package_name, monkey_package.package_name AS monkey_package_package_name, monkey_package.oss_url AS monkey_package_oss_url, monkey_package.picture AS monkey_package_picture, monkey_package.version AS monkey_package_version, monkey_package.default_activity AS monkey_package_default_activity, monkey_package.user_id AS monkey_package_user_id, monkey_package.status AS monkey_package_status, monkey_package.size AS monkey_package_size, monkey_package.test_type AS monkey_package_test_type, monkey_package.id AS id, monkey_package.name AS name, monkey_package.package_name AS package_name, monkey_package.oss_url AS oss_url, monkey_package.picture AS picture, monkey_package.version AS version, monkey_package.default_activity AS default_activity, monkey_package.user_id AS user_id, monkey_package.status AS status, monkey_package.size AS size, date_format(monkey_package.creation_time, %s) AS upload_time, monkey_package.test_type AS test_type 
FROM monkey_package 
WHERE monkey_package.status = %s AND monkey_package.test_type = %s AND monkey_package.user_id = %s ORDER BY monkey_package.id DESC 
 LIMIT %s, %s]
[parameters: ('%Y-%m-%d %H:%i:%s', 0, 1, '1152', 0, 10)]
(Background on this error at: http://sqlalche.me/e/e3q8)

[2019-11-22 16:45:45,425][37328][autotest][tMiddleware.py 71 ERROR]: 
request  : /v1/monkey/package  GET [handler: 0]
token    : eyJ0eXAiOiJKV1QiLCJhbGciOiJIUzI1NiJ9.eyJ1c2VyaWQiOjExNTIsInVzZXJuYW1lIjoiYWRtaW4iLCJuaWNrbmFtZSI6ImFkbWluIiwicGljdHVyZSI6IiIsInVzZXJ3ZWlnaHQiOjEsInJvbGUiOlt7ImlkIjoxLCJuYW1lIjoiYWRtaW4iLCJjb21tZW50IjoiXHU4ZDg1XHU3ZWE3XHU3YmExXHU3NDA2XHU1NDU4In0seyJpZCI6MywibmFtZSI6InRlc3QiLCJjb21tZW50IjoiXHU2ZDRiXHU4YmQ1In1dLCJwcm9qZWN0aWQiOlsyXSwiZXhwIjoxNTc1MDQxNjQ3fQ.tAFuzTB-HuzpeE7KZvbgddc_JCL8RXP1d08tfhoOmnY
projectid: 
query    : {'page_index': '1', 'page_size': '10'}

Traceback (most recent call last):
  File "D:\Programs\python37\lib\site-packages\sqlalchemy\engine\base.py", line 1246, in _execute_context
    cursor, statement, parameters, context
  File "D:\Programs\python37\lib\site-packages\sqlalchemy\engine\default.py", line 581, in do_execute
    cursor.execute(statement, parameters)
  File "D:\Programs\python37\lib\site-packages\MySQLdb\cursors.py", line 209, in execute
    res = self._query(query)
  File "D:\Programs\python37\lib\site-packages\MySQLdb\cursors.py", line 315, in _query
    db.query(q)
  File "D:\Programs\python37\lib\site-packages\MySQLdb\connections.py", line 231, in query
    _mysql.connection.query(self, query)
MySQLdb._exceptions.OperationalError: (1054, "Unknown column 'monkey_package.test_type' in 'field list'")

The above exception was the direct cause of the following exception:

Traceback (most recent call last):
  File "D:\Programs\python37\lib\site-packages\flask\app.py", line 1949, in full_dispatch_request
    rv = self.dispatch_request()
  File "D:\Programs\python37\lib\site-packages\flask\app.py", line 1935, in dispatch_request
    return self.view_functions[rule.endpoint](**req.view_args)
  File "G:\gitworkspace\TcloudServer\apps\autotest\views\monkey.py", line 479, in monkey_package_index_handler
    all, count = MonkeyPackageBusiness.get_monkey_packages_by_user_id(user_id, page_size, page_index, test_type)
  File "G:\gitworkspace\TcloudServer\apps\autotest\business\monkey.py", line 702, in get_monkey_packages_by_user_id
    all = cls.query_all_json(page_size, page_index, test_type)
  File "G:\gitworkspace\TcloudServer\library\api\transfer.py", line 129, in _
    result = func(*args, **kwargs)
  File "G:\gitworkspace\TcloudServer\apps\autotest\business\monkey.py", line 648, in query_all_json
    int(page_index - 1) * int(page_size)).all()
  File "D:\Programs\python37\lib\site-packages\sqlalchemy\orm\query.py", line 3211, in all
    return list(self)
  File "D:\Programs\python37\lib\site-packages\sqlalchemy\orm\query.py", line 3367, in __iter__
    return self._execute_and_instances(context)
  File "D:\Programs\python37\lib\site-packages\sqlalchemy\orm\query.py", line 3392, in _execute_and_instances
    result = conn.execute(querycontext.statement, self._params)
  File "D:\Programs\python37\lib\site-packages\sqlalchemy\engine\base.py", line 982, in execute
    return meth(self, multiparams, params)
  File "D:\Programs\python37\lib\site-packages\sqlalchemy\sql\elements.py", line 287, in _execute_on_connection
    return connection._execute_clauseelement(self, multiparams, params)
  File "D:\Programs\python37\lib\site-packages\sqlalchemy\engine\base.py", line 1101, in _execute_clauseelement
    distilled_params,
  File "D:\Programs\python37\lib\site-packages\sqlalchemy\engine\base.py", line 1250, in _execute_context
    e, statement, parameters, cursor, context
  File "D:\Programs\python37\lib\site-packages\sqlalchemy\engine\base.py", line 1476, in _handle_dbapi_exception
    util.raise_from_cause(sqlalchemy_exception, exc_info)
  File "D:\Programs\python37\lib\site-packages\sqlalchemy\util\compat.py", line 398, in raise_from_cause
    reraise(type(exception), exception, tb=exc_tb, cause=cause)
  File "D:\Programs\python37\lib\site-packages\sqlalchemy\util\compat.py", line 152, in reraise
    raise value.with_traceback(tb)
  File "D:\Programs\python37\lib\site-packages\sqlalchemy\engine\base.py", line 1246, in _execute_context
    cursor, statement, parameters, context
  File "D:\Programs\python37\lib\site-packages\sqlalchemy\engine\default.py", line 581, in do_execute
    cursor.execute(statement, parameters)
  File "D:\Programs\python37\lib\site-packages\MySQLdb\cursors.py", line 209, in execute
    res = self._query(query)
  File "D:\Programs\python37\lib\site-packages\MySQLdb\cursors.py", line 315, in _query
    db.query(q)
  File "D:\Programs\python37\lib\site-packages\MySQLdb\connections.py", line 231, in query
    _mysql.connection.query(self, query)
sqlalchemy.exc.OperationalError: (MySQLdb._exceptions.OperationalError) (1054, "Unknown column 'monkey_package.test_type' in 'field list'")
[SQL: SELECT monkey_package.id AS monkey_package_id, monkey_package.creation_time AS monkey_package_creation_time, monkey_package.modified_time AS monkey_package_modified_time, monkey_package.name AS monkey_package_name, monkey_package.package_name AS monkey_package_package_name, monkey_package.oss_url AS monkey_package_oss_url, monkey_package.picture AS monkey_package_picture, monkey_package.version AS monkey_package_version, monkey_package.default_activity AS monkey_package_default_activity, monkey_package.user_id AS monkey_package_user_id, monkey_package.status AS monkey_package_status, monkey_package.size AS monkey_package_size, monkey_package.test_type AS monkey_package_test_type, monkey_package.id AS id, monkey_package.name AS name, monkey_package.package_name AS package_name, monkey_package.oss_url AS oss_url, monkey_package.picture AS picture, monkey_package.version AS version, monkey_package.default_activity AS default_activity, monkey_package.user_id AS user_id, monkey_package.status AS status, monkey_package.size AS size, date_format(monkey_package.creation_time, %s) AS upload_time, monkey_package.test_type AS test_type 
FROM monkey_package 
WHERE monkey_package.status = %s AND monkey_package.test_type = %s ORDER BY monkey_package.id DESC 
 LIMIT %s, %s]
[parameters: ('%Y-%m-%d %H:%i:%s', 0, 1, 0, 10)]
(Background on this error at: http://sqlalche.me/e/e3q8)

